Workbook

Sheet Leadership
B1: Level | C1: Element エレメント | D1: No | E1: Question 質問 | F1: Answered by 回答者 | G1: How to check 確認方法 | J1: Judgement Criteria 判断基準 | K1: Judgement 判断 | L1: Reason 判断理由
G2: Interview | H2: On-site observation | I2: Document check | J2: Note: Global target number of TMs who are interviewed is 10% and more in the site. Minimum number is 3 TMs in case 10% of all TMs is less than 3. 注記：インタビューする技能員の人数は、全従業員の10%以上をグローバル目標とする。なお10％が3人未満となる場合は、3人を目標とする。
B3: Ad-hoc | C3: Prioritization 優先付け | D3: 1 | E3: Have safety procedures been evaluated to ensure they are compliant with OH&S regulations? 安全手順は、安全衛生法令に準拠するよう、評価されていますか？ | F3: Site manager 事業所長 | G3: レ | J3: The respondent can explain how safety procedures have been evaluated to ensure they are compliant with OH&S regulations. 回答者は、安全手順が労働安全衛生規則に準拠するよう、どのように評価されているか説明できる。
C4: Decisions 意思決定 | D4: 2 | E4: Have you monitored the H&S and DP regulations* which may be applicable for your site and checked that these regulations have been taken place in your sites? (e.g. trainings, mobile equipment, chemicals, flammable materials) 事業所に適用される労働安全衛生・防災関連法令の要求事項を把握し、法要件を順守していますか？（例: 資格・教育、動力車、化学物質管理、可燃物管理） | F4: Site manager 事業所長 | H4: レ | I4: レ | J4: The H&S and DP regulations are listed up and actions in the site are determined. Besides, the site is compliant with these regulations. 労働安全衛生・防災関連法令の要件および事業所で取るべき対応が明確になっている。また、現場確認すると法要件が順守されていることを確認できる。
C5: Support 支援 | D5: 3 | E5: Does your site manager consider safety a priority and address safety at the morning assembly, roll-call, etc.? 事業所長は、安全を第一優先と考え、朝礼や点呼の際に安全に関する話をしていますか？ | F5: Teammate 技能員 | G5: レ | J5: All respondents can show examples that the site manager addresses at the morning assembly, roll call, etc. 回答者全員が、事業所長が点呼・朝礼などで話した安全に関する話の具体例をあげることができた。
B7: Reactive | C7: Support 支援 | D7: 4 | E7: What does site leadership (e.g. site manager and supervisor) do when a serious incident (lost-time-injury, fire accident, etc.) occurs? 重大インシデント（休業災害・出火事故等）発生時、管理監督者（事業所長、作業主任）はどのような対応をとりますか？ | F7: Teammate 技能員 | G7: レ | J7: All respondents stated that site leadership (e.g. site manager and supervisor) was involved in the root cause analysis process when a serious incident (lost-time-injury, fire accident, etc.) occurred 回答者全員が、重大インシデント（休業災害・出火事故等）発生時、管理監督者（事業所長、作業主任）が原因分析プロセス（例:JS分析）に参加対応していると述べた。
C8: Prioritization 優先付け | D8: 5 | E8: Does site manager review lagging OH&S KPIs (e.g. number of incidents, frequency, severity) at least monthly? 事業所長は、結果系KPI(災害・出火事故件数、度数率、強度率等)をフォローし、見直ししていますか？ | F8: Site manager 事業所長 | G8: レ | J8: Site leadership follows safety lagging OH&S KPIs, and give directions to review the safety program if necessary. 事業所長は、結果系KPIをフォローし、必要に応じて安全施策の見直しを指示している。
C9: Prioritization 優先付け | D9: 6 | E9: Are the root causes of incidents categorized and then tracked? 災害の原因は、分類（要因分析）され、追跡（フォロー）されていますか？ | F9: Site manager or if available, site safety 事業所長もしくは拠点安全担当 | I9: レ | J9: The cause of incident in the most recent year has been determined and the countermeasures are followed-up by the termination. 直近１年間の災害(労働災害・業務上疾病・ヒヤリ)の原因が特定され、対策完了までフォローされている。
C10: Decisions 意思決定 | D10: 7 | E10: Are safety initiatives being implemented to improve safety? Is there any document to show that? 安全性向上のために、リーダーシップが発揮されていますか？それを示す書類がありますか？ | F10: Site manager or if available, site safety 事業所長もしくは拠点安全担当 | G10: レ | I10: レ | J10: Site leadership can show a plan to improve safety activities in the site and explain that the plan is implemented. 事業所長は自事業所の安全活動改善計画を提示でき、その計画が実行されていることを説明できる。
B12: Standardized | C12: Support 支援 | D12: 8 | E12: Does Site leaders actively provide feedback to teammates and promote safety whilst on tours? 管理監督者（事業所長および作業主任）は、巡回時、積極的に技能員へフィードバックを行い、安全を推進していますか？ | F12: Site manager and Supervisor 事業所長および作業主任 | G12: レ | J12: The respondents can show an example that they provide feedbacks to teammates to ensure adherence to safety rules, such as procedures, standards, etc. 回答者は、手順、規格などの安全ルールが遵守されるように巡回等の現場確認を行い、技能員へフィードバックをした具体例をあげることができる。
C13: Support 支援 | D13: 9 | E13: What is your responsibility for safety? 安全に関するあなたの責任や義務は何ですか？ | F13: Teammate 技能員 | G13: レ | J13: All respondents can explain their own responsibilities for safety. (e.g. participation of safety activity, etc.) 回答者全員が、安全に関する自身の責任や義務（例：安全活動への参加等）を説明できる。
C14: Decisions 意思決定 | D14: 10 | E14: Do you know how important teammates' involvement in safety is? Besides, do you explain the importance to teammates and involve them in safety activities? あなたは、安全（活動）に従業員を参加させることの重要性を理解していますか？また、その重要性を従業員に説明し、従業員を安全活動に参加させていますか？ | F14: Site manager 事業所長 | G14: レ | J14: Site manager could both explain why teammate involvement in safety management is important and can provide examples of actions taken to promote this and the results of those actions. 事業所長は、安全管理への従業員の参加対応が重要である理由を説明し、その促進活動の例と結果を示すことができる。
C15: Decisions 意思決定 | D15: 11 | E15: Is there a H&S meeting with representation from teammates, leadership and site H&S (if available)? Does leadership give directions to solve issues? 技能員と管理者（事業所長、作業主任等）が出席する安全衛生会議が開催されていますか？事業所長は課題解決のための指示をしていますか？ | F15: Site manager 事業所長 | I15: レ | J15: The meeting minute indicates that the meetings are held at planned intervals and the participants discuss the improvement of safety on site. 会議議事録より、計画された間隔で会議が開催され、出席者が現場の安全性向上について議論していることが確認できる。
C16: Prioritization 優先付け | D16: 12 | E16: Are there repercussions/consequences for teammates that do not follow the Safety Rules and Procedures? 安全ルール違反をした従業員に対し、影響/結果（罰則）はありますか？ | F16: Site manager 事業所長 | I16: レ | J16: Site manager can show disciplinary procedure or documented examples (e.g. consequence matrix) of carrying out disciplinary action, etc. 事業所長は、罰則手順書や罰則事例を提示することができる。
B18: Proactive | C18: Prioritization 優先付け | D18: 13 | E18: Does site manager follow and review "Leading indicators" in their safety result tracking? 事業所長は、安全関連の指標について、先行指標（プロセスKPI）をフォローし、見直ししていますか？ | F18: Site manager 事業所長 | G18: レ | J18: Site leadership follow not only lagging indicator(e.g. # of injuries), but also leading indicators, and give directions to review and/or improve safety programs if necessary. 事業所長は、結果系KPI（災害件数等）だけでなく、先行指標(プロセスKPI）をフォローし、必要に応じて施策の見直し・改善を指示している。
C19: Decisions 意思決定 | D19: 14 | E19: Can you show examples of implemented safety measures based on teammate feedback? 現場の意見を踏まえた上で安全の課題を認識し、その対応や改善に取り組んでいますか？ | F19: Site manager or if available, site safety 事業所長もしくは拠点安全担当 | G19: レ | I19: レ | J19: The respondents can show an example of ongoing safety project with allocated budgets. 回答者は、予算が割り当てられ、現在取り組んでいる安全プロジェクトの具体例を示すことができる。
C20: Prioritization 優先付け | D20: 15 | E20: When creating the annual (or more) safety implementation plan, do you consider the KPI result/progress in previous year? 年次安全衛生実施計画を作る際に、前年度のKPI達成度合いを評価し、翌年度の実施項目や目標を立てていますか？ | F20: Site manager or if available, site safety 事業所長もしくは拠点安全担当 | G20: レ | I20: レ | J20: The respondent can explain an example that was changed from annual planning for previous year and its reason. 前年度から変更した実施項目や目標値と、変更した理由を説明できる。
C21: Support 支援 | D21: 16 | E21: Do you recognize good safety behaviors of teammates and give them rewards? あなたは、技能員の優れた安全行動を認知し、彼らを表彰していますか? | F21: Site manager 事業所長 | G21: レ | J21: Site manager can explain an example of this kind of reward in the most recent year. 事業所長はが、直近1年間の表彰事例を説明することができる。
C22: Support 支援 | D22: 17 | E22: Does management have a mid-term plan including Safety and DP items and their necessary resources to improve safety on site? 管理者は、安全防災項目と必要予算が含まれる中期計画を作成しているか？ | F22: Site manager 事業所長 | I22: レ | J22: The plan clarifies the Safety and/or DP items and their presumed recourses to implement. 中期計画(MBP)は、SBUやBSB本社ガイドラインを考慮し安全防災の項目も折り込み、予算化されている。
B24: Excellence | C24: Decisions 意思決定 | D24: 18 | E24: Have you gathered best practices on safety activity from GBS/SBU, and implement them in the site? GBS/SBUから展開された安全活動の好事例を事業所へ適用し、推進していますか？ | F24: Site manager or if available, site safety 事業所長もしくは拠点安全担当 | G24: レ | J24: The respondents can give examples of industry best practices, where they came from and how they are being implemented on site. 回答者は、業界のベストプラクティスの例、その出所、現場における導入方法を示すことができる。
C25: Support 支援 | D25: 19 | E25: Is there an external/cross site safety meeting? If so, does safety manager share H&S issues or best practices? 他事業所、もしくは社外との安全会議があり、課題や好事例を共有しているか？ | F25: Site manager or if available, site safety 事業所長もしくは拠点安全担当 | I25: レ | J25: Meeting minute indicate that the respondent contributes to discussion in the safety meeting. (e.g. Site managers meeting in SBU, meeting in the local safety association, etc.) 会議議事録より回答者が安全会議(例:SBU内の事業所長会議、地域の安全協力会等)で議論に参加している（安全衛生の改善に向けた困りごと・問題・課題の提起、ベストプラクティスの共有等）ことが確認できる。
C26: Support 支援 | D26: 20 | E26: Do you feel comfortable stopping work if you feel there is a risk of injury? あなたは、災害リスクに直面した際、作業を停止することを、よいことだと感じていますか？ | F26: Teammate 技能員 | G26: レ | J26: All respondents confirm that they feel safety is essential. They are comfortable stopping work when they feel their safety is compromised. 回答者全員、安全が絶対不可欠であると述べた。安全が損なわれると思ったときには、躊躇なく作業を停止できる。
C27: Prioritization 優先付け | D27: 21 | E27: Do you motivate teammates to find and implement new best practices relevant to safety in other BS sites? あなたは、所属員に対し、安全に関するベストプラクティスの収集や実行を推進していますか？ | F27: Site manager 事業所長 | G27: レ | J27: Site manager can explain how he/she motivate teammates to find best practices and how he/she allocate resources to implement them. (e.g. Teammates join in safety meeting where other site's members are present) 事業所長は、所属員に対してベストプラクティスを模索する動機付けの方法、および導入するためのリソースを割り当てる方法を説明できる。 (例. 他事業所との安全会議に所属員も参加する、他事業所へ安全調査に行く等)
C28: Prioritization 優先付け | D28: 22 | E28: Does the site management team benchmark Safety and DP trends in logistics industry / other external companies and consider incorporation into site targets/activities? 物流業界や社外の安全防災動向を収集し、自事業所の活動への取り入れを検討していますか？ | F28: Site manager or if available, site safety 事業所長もしくは拠点安全担当 | G28: レ | J28: The respondent can give example of Safety and DP trends which the management team referred. 回答者は、収集した業界や社外の動向事例を説明することができる。
C31: *Best practice includes information gathered from other sites or external companies. The items which were already standardized are excluded. (E.g. Engineering/recurrence prevention measures defined in the international standard or SBU standard)
C32: *ベストプラクティスには、事業所や他社から入手した好事例が含まれる。但し、既に標準化/規格化/要領化された内容を除く。（例：国際規格やSBU規格に規定されている設備対策・類災対策）
C33: *Incidents: lost-time-injury, fire accident, occupational disease, near-miss, etc. インシデント：災害・火災・業務上疾病・ヒヤリ 等

Sheet TM Engagement
B1: Level | C1: Element エレメント | D1: No | E1: Question 質問 | F1: Answered by 回答者 | G1: How to check 確認方法 | J1: Judgement Criteria 判断基準 | K1: Judgement 判断 | L1: Reason 判断理由
G2: Interview | H2: On-site observation | I2: Document check | J2: Note: Global target number of TMs who are interviewed is 10% and more in the site. Minimum target number is 3 in case 10% of all TMs is <3. 注記：インタビューする技能員の人数は、全従業員の10%以上をグローバル目標とする。なお10％が3人未満となる場合は、3人を目標とする。
B3: Ad-hoc | C3: Capability 能力 | D3: 1 | E3: What are H&S risks relevant to your work? What makes you recognize them? あなたの仕事に関連のある安全衛生リスクは何ですか？そのリスクはどのように教わりましたか？ | F3: Teammate 技能員 | G3: レ | J3: All respondents are trained to recognize the H&S risks applicable in the site. 回答者全員が、自職場の安全衛生関連のリスクを教育訓練で教えられている。
C4: Action 行動 | D4: 2 | E4: What would be considered a priority: complete the operation plan or follow safety procedures? あなたは、作業を計画通り完了させることと安全手順を守ることのどちらが優先されるべきだと考えますか？ | F4: Teammate 技能員 | G4: レ | J4: All respondents know that safety is considered more important than operation. 回答者全員が、作業よりも安全を優先するという意識を持っている。
C5: Capability 能力 | D5: 3 | E5: Are you aware of your personal impact on safety? How do you contribute to improve safety? あなたは、安全に対する自身の影響力を認識していますか？どのように安全向上に貢献していますか？ | F5: Site manager 事業所長 | G5: レ | J5: Site manager stated that they have an impact on teammate safety. They can show an example of their contribution for safety. (e.g. They patrol on site, prioritize safety measures, allocate budget, etc.) 事業所長は、自身が従業員の安全に影響を及ぼすことを認識していると述べ、どのように貢献しているか具体例を説明できる。（例：巡回による安全状況確認、安全対策の優先順位付け、予算割り当て等）
C6: Knowledge 知識 | D6: 4 | E6: What requirement, based on safety regulations do you explain to teammate? 安全に関する法的要求に関して、あなたはどういった内容を技能員に説明していますか？ | F6: Supervisor 作業主任 | G6: レ | J6: The respondent can show an example that they explain safety requirements based on regulation to teammates. 回答者は、安全に関する法的要求事項を技能員へ説明した具体例をあげることができる。
B8: Reactive | C8: Capability 能力 | D8: 5 | E8: Do teammates know how to report incidents? 技能員はインシデント（災害、ヒヤリ等）発生時の報告方法を知っていますか？ | F8: Teammate 技能員 | G8: レ | I8: レ | J8: All respondents can explain how to report when incident happen. A review of the incident records from the last month show that teammates have been reporting incidents and near misses. 回答者全員がインシデント発生時の報告方法を知っている。前月のインシデント記録を検証すると、インシデントやニアミスを従業員が報告していることがわかる。
C9: Action 行動 | D9: 6 | E9: What actions do you take during your operations to prevent reoccurrence of an incident which occurred in your site? 自事業所で発生した災害の再発防止のため、どのような対策を日々実践していますか？ | F9: Teammate 技能員 | G9: レ | J9: All respondents can explain the actions required to prevent the reoccurrence of incident that occurred in their site. They stated that they are involved in the required actions. 回答者全員が、自倉庫で発生した災害の再発防止対策が何か説明することができ、それを実践していると回答した。
C10: Knowledge 知識 | D10: 7 | E10: What incidents and the countermeasures at your site did you receive from managements recently? 最近、事業所長または作業主任から連絡を受けた、自職場のインシデント（災害、ヒヤリ等）とその対策は何ですか？ | F10: Teammate 技能員 | G10: レ | I10: レ | J10: All respondents are informed of recent safety incidents in their site and countermeasures. Their statements match incident records. 回答者全員が、自職場で最近発生した安全インシデント（災害、ヒヤリ等）と対策の連絡を受けている。その回答は、インシデント記録と一致する。
B12: Standardized | C12: Capability 能力 | D12: 8 | E12: What are the most important safety rules in your site/job and why? あなたの職場や作業で最も重要な安全ルールは何ですか？それはなぜですか。 | F12: Teammate 技能員 | G12: レ | J12: All respondents can explain their site/job safety rules and why they are important. 回答者全員が、自分の職場や業務の安全ルールとその重要性を説明できる。
C13: Knowledge 知識 | D13: 9 | E13: Are you regularly trained about your site/job safety rules? あなたは、自分の職場や作業に関する安全ルールについて、定期的に教育を受けていますか？ | F13: Teammate 技能員 | G13: レ | J13: All respondents agreed that they are regularly reminded and trained of their site/job safety rules. 回答者全員が、自分の職場や業務の安全ルールについて定期的に周知・教育されていると回答した。
C14: Action 行動 | D14: 10 | E14: Are the site/job safety rules being followed? 職場や作業における安全ルールは順守されているか？ | F14: Tour 現場確認 | H14: レ | J14: On-site observation indicates that teammates follow their site/job safety rules. 現場確認の結果、技能員が自職場や自業務の安全ルールを守っていた。
B16: Proactive | C16: Capability 能力 | D16: 11 | E16: Do you understand the greatest potential risks in your work, and how they are controlled? あなたは、自分の業務で最も危険なリスクとその管理方法（対策）を理解していますか？ | F16: Teammate 技能員 | G16: レ | J16: All respondents can explain the greatest potential risks in their work and controls to mitigate these risks. 回答者全員が、自分の業務で最も危険なリスクとそのリスク低減措置について説明できる。
C17: Knowledge 知識 | D17: 12 | E17: Have you taken training on residual risks in your work? How are you trained? あなたは、自分の業務の残留リスクについて教育を受けましたか？どのように教育されましたか？ | F17: Teammate 技能員 | G17: レ | J17: All respondents stated that they took the training on residual risks based on the work standard. 回答者全員が、残留リスクについて作業標準ベースに教育を受けていると述べた。
C18: Action 行動 | D18: 13 | E18: Have teammates proposed improvements of H&S risks and risk mitigation measures at the creations or revisions of work standards, training materials, etc? 技能員は、作業標準や教育資料等を作成、改訂する際、安全リスクや低減策の改善提案をしていますか？ | F18: Site manager or if available, site safety 事業所長もしくは拠点安全担当 | I18: レ | J18: Materials indicate that teammates propose improvements of H&S risks and risk mitigation measures at the creations or revisions of work standards, training materials, etc. 文書確認にて、作業標準や教育資料等を作成、改訂する際、技能員が、安全リスクや低減策の改善提案をしていることが示される。
B20: Excellent | C20: Knowledge 知識 | D20: 14 | E20: Are there opportunities to share H&S risks and countermeasures of other sites at the safety meeting in your site? 自事業所の安全会議など、他事業所の安全リスク/対策を共有する場がありますか？ | F20: Teammate 技能員 | I20: レ | J20: Meeting material or minute indicate that H&S risks and countermeasures of other sites have been shared at the safety meeting in your site. 会議資料や議事録より、自事業所の安全会議等で、他事業所の安全リスク/対策について共有されていることが確認できる。
C21: Capability 能力 | D21: 15 | E21: How do you encourage communication between sites to share best-practices and lessons-learned? あなたは、どのように事業所間でベストプラクティスや教訓を共有するためのコミュニケーションを推奨していますか？ | F21: Site manager or if available, site safety 事業所長もしくは拠点安全担当 | G21: レ | J21: The respondent can explain how to share H&S risks and control to mitigate these risks between sites. (e.g. Teammates introduce their safety activities to other site teammates.) 回答者は、安全衛生リスクとリスク低減措置について事業所間でどのように共有するか説明できた。(例. 他事業所との安全交流会で、所属員が自事業所の安全活動を紹介している。)
C22: Action 行動 | D22: 16 | E22: What response would you expect from your colleague when you act unsafe? What will you do if you find unsafe behavior of your colleague? あなたが不安全行動をした場合、あなたの同僚はどのような反応をすると思いますか？もし同僚の不安全行動を見つけたら、あなたはどうしますか？ | F22: Teammate 技能員 | G22: レ | J22: All respondents stated that unsafe behavior is unacceptable and anyone acting unsafe will be corrected by their peers. 回答者全員が、不安全行動は容認できないと述べ、不安全行動をとる者は同僚によって指摘されると述べた。
C25: *Best practice includes information gathered from other sites or external companies. The items which were already standardized are excluded. (E.g. Engineering/recurrence prevention measures defined in the international standard or SBU standard)
C26: *ベストプラクティスには、事業所や他社から入手した好事例が含まれる。但し、既に標準化/規格化/要領化された内容を除く。（例：国際規格やSBU規格に規定されている設備対策・類災対策）

Sheet Organization
B1: Level | C1: Element エレメント | D1: No | E1: Question 質問 | F1: Answered by 回答者 | G1: How to check 確認方法 | J1: Judgement Criteria 判断基準 | K1: Judgement 判断 | L1: Reason 判断理由
G2: Interview | H2: On-site observation | I2: Document check | J2: Note: Global target number of TMs who are interviewed is 10% and more in the site. Minimum target number is 3 in case 10% of all TMs is <3. 注記：インタビューする技能員の人数は、全従業員の10%以上をグローバル目標とする。なお10％が3人未満となる場合は、3人を目標とする。
B3: Ad-hoc | C3: Information 情報 | D3: 1 | E3: Is the legally required H&S training given to all teammates? 法令で要求される安全衛生教育は、全ての従業員に実施されていますか？ | F3: Site manager or if available, site safety 事業所長もしくは拠点安全担当 | I3: レ | J3: Compliance evaluation and training records in the most recent year indicate that H&S training required by regulation has been provided to all teammates. 直近１年間の法令遵守状況評価と教育訓練記録から、法令に定められた安全衛生関連の教育訓練が全従業員に実施されていることが示される。
C4: Communication コミュニケーション | D4: 2 | E4: Do teammates communicate injuries/near-misses/defects to managers, and does management follow up them until close? 管理者は、災害/ヒヤリ/不具合情報を技能員から入手し、対策完了までフォローアップ（追加の確認等）していますか？ | F4: Supervisor 作業主任 | G4: レ | J4: All respondents can show items recently reported to him/her and the examples of follow-ups associated with the reports. 作業主任は、最近報告された内容とそのフォローアップ活動の例を示すことができる。
C5: Communication コミュニケーション | D5: 3 | E5: Are H&S/DP rules communicated to teammates when updated/changed/newly created. 安全衛生や防災に関するルールは、新設/改訂があった際に従業員へ周知されていますか？ | F5: Site manager or if available, site safety 事業所長もしくは拠点安全担当 | I5: レ | J5: Notifications board, document record etc show that updated/created H&S/DP rules are communicated to teammates. 掲示板や教育記録を見ると、新設/改訂のあった安全衛生や防災に関するルール内容が従業員へ周知されていた。
C6: Participation 参加 | D6: 4 | E6: Does management have defined roles and responsibilities for safety activities? 管理者は、自職場の安全活動の担当者の役割を明確にし、任命していますか？ | F6: Site manager 事業所長 | G6: レ | J6: The site manager can explain their roles and responsibilities on safety activity in their teams. 事業所長は、自職場の安全活動における役割と責任を説明できる。
B8: Reactive | C8: Information 情報 | D8: 5 | E8: Are incident investigations carried out by qualified people? 災害調査は、知識・能力をもった者が実施していますか？ | F8: Site manager or if available, site safety 事業所長もしくは拠点安全担当 | I8: レ | J8: A review of the last incident (injury, disease/illness, near-miss) record show that the incident was investigated by qualified people (managements or site safety), and the identified causes were added to the risk tracking. 直近のインシデント（災害・業務上疾病・ヒヤリ）記録より、インシデントが知識・能力を有した者（管理監督者や拠点安全担当）によって調査され、特定された原因はリスク登録簿に追加されていた。
C9: Communication コミュニケーション | D9: 6 | E9: Do you know what safety initiatives are on going on site and how they are performing? 管理者は、現場で実行されている安全の取り組みと、その効果を把握していますか？ | F9: Site manager 事業所長 | G9: レ | J9: All respondents could describe the most recent H&S initiatives (key projects or activities) to improve H&S management on site, and knew if the results were positive or negative. 事業所長は、現場の安全衛生管理改善を目的とした直近の安全衛生の取り組みを説明でき、結果の良し悪しを知っていた。
C10: Participation 参加 | D10: 7 | E10: Is there collaboration between Logistics safety dept. and site management to address recurring incidents? 再発防止において、物流安全機能部署と事業所長は連携していますか？ | F10: Site manager 事業所長 | I10: レ | J10: A review of the last incident (injury, disease/illness, near-miss) record show evidence that site management and Logistic safety dept. collaborate to prevent reoccurrence of the accident by addressing the causation. 直近のインシデント(災害・業務上疾病・ヒヤリ)記録より、管理者と物流安全機能部署が協力して、事故の因果関係を調査し、再発防止に取り組んでいることが確認できる。
C11: Participation 参加 | D11: 8 | E11: Do safety training sessions for newcomers reference relevant frequent incidents and severe risks? *Frequent incident means that same incident is re-occurring 新人・転入者向けの安全教育において、よく発生するインシデント(災害・業務上疾病・ヒヤリ)と重大リスクが言及されていますか？ | F11: Site manager or if available, site safety 事業所長もしくは拠点安全担当 | I11: レ | J11: The safety training material for newcomers includes frequent incidents, severe risks and their controls. 新人・転入者向けの安全教育資料に、よく発生するインシデント(災害・業務上疾病・ヒヤリ)、重大リスク、その管理項目（対策）が含まれている。
B13: Standardized | C13: Information 情報 | D13: 9 | E13: Are safety rule's effectiveness being evaluated by the H&S (if available), teammates and their site leaders? 管理監督者や技能員によって、安全ルールの有効性が評価されていますか？ | F13: Site manager or if available, site safety 事業所長もしくは拠点安全担当 | G13: レ | J13: The site manager or site safety (if available) could describe how the H&S rule's effectiveness is evaluated, who is involved in the evaluation process and how the processes are improved after evaluation. 事業所長は、誰がどのように安全ルールの有効性を評価し、評価後はどのように改善されるか説明できる。
C14: Communication コミュニケーション | D14: 10 | E14: When a safety issue would occur, who would you report to? 安全上の課題が発生した場合、あなたは誰に報告しますか？ | F14: Teammate 技能員 | G14: レ | J14: All respondents stated that they would report specific safety issues to their site leadership (e.g. site manager and supervisor) . 回答者全員が、安全関連の特定の課題を管理監督者（事業所長、作業主任等）に報告すると回答した。
C15: Communication コミュニケーション | D15: 11 | E15: What is a content of system and a scope for "management of change"? 4M変更管理の仕組みの内容と対象を説明してください。 | F15: Supervisors 作業主任 | G15: レ | J15: All supervisors could explain system and scope of management of change (4M changes). 作業主任全員が、４M変更管理の仕組み・対象について説明できた。
C16: Participation 参加 | D16: 12 | E16: Are safety processes updated and improved frequently using findings from the review? 安全面に関する作業標準は頻繁に見直され、見直し結果をもとに改善されていますか？ | F16: Site manager or if available, site safety 事業所長もしくは拠点安全担当 | I16: レ | J16: Document history of H&S procedures and standards from the last year showed that safety processes had been updated to address newly identified risks and controls based on review. 安全衛生関連の手順書や標準書の前年以降の改訂履歴より、新たなリスクや課題について、安全手順が審議を得て改訂されたことが確認された。
B18: Proactive | C18: Communication コミュニケーション | D18: 13 | E18: Do you communicate with OH&S expert about upcoming changes on site when there are any concerns on Safety? あなたは、職場の予定された変更に関して安全衛生上の懸念がある場合、安全衛生の専門家(物流安全機能や工場安全機能、社外等)と話し合っていますか？ | F18: Site manager 事業所長 | G18: レ | J18: The respondent could show an example that he/she discuss the injury/illness/fire risks associated with upcoming changes to work processes with internal/external safety expert. 回答者は、作業場のレイアウトや作業方法などの変更時に、安全衛生・防災面について社内または社外専門機能と討議した事例を説明できた。
C19: Information 情報 | D19: 14 | E19: Do work/job specific trainings highlight safety risks and processes associated with that work/job? 技能訓練時、作業標準書の安全の急所や回避方法を教えていますか？ | F19: Supervisor 作業主任 | I19: レ | J19: Safety instructions and safety training are included in the work/job specific training materials. 作業訓練資料に、安全関連の指示事項と安全教育訓練項目が含まれている。
C20: Participation 参加 | D20: 15 | E20: Have you involved TMs in periodical review on safety action plans? 安全実施計画のレビュー(成り行き確認)に技能員を参加させていますか？ | F20: Site manager or if available, site safety 事業所長もしくは拠点安全担当 | I20: レ | J20: A review of the safety action plans (ex. meeting minutes, RA, etc.) from the most recent safety projects (safety programs or safety activities) show that teammates were involved and consulted. 直近の安全プロジェクト（安全会議やRA等の安全に関する取り組み）における安全関連の活動計画を検証すると、技能員の参加対応と協議があったことが示された。
C21: Communication コミュニケーション | D21: 16 | E21: What was the feedback from management on your hazard report? あなたが危険状況を報告した際、管理者からどのようなフィードバックをもらいましたか？ | F21: Teammate 技能員 | G21: レ | J21: All respondents stated that management had taken specific actions to address hazards they reported, and these actions have been communicated to them. 回答者全員が、自分たちが報告した危険状況に対して、管理者が特定の対応措置を実施し、その件について自分たちに報告があったと述べた。
B23: Excellence | C23: Participation 参加 | D23: 17 | E23: Do teammates comply with safety rules and improve risks actively being conscious of safety for not only their selves, but also teammates. ? 技能員は、自分だけでなく他者の安全を意識し、安全の標準・ルールを守り、リスク改善を積極的に行っていますか？ | F23: Teammate 技能員 | G23: レ | H23: レ | J23: Observation in genba showed that teammates are actively conscious of their safety and the safety of others. Activities for improvement were conducted in CFT being conscious of safety for not only their selves, but also teammates. 作業現場を視察すると、技能員が自身の安全と他者の安全を積極的に意識していることが示された。改善活動は、自分だけでなく他者の安全を意識し、小集団・CFTで実施されている
C24: Participation 参加 | D24: 18 | E24: Do you engage with *external parties to obtain and exchange knowledge on safety? *External includes other company, SBU, other BS sites あなたは、外部の関係者と安全に関する知識の習得や情報交換をしていますか？ *外部には他社、SBU、他事業所を含む | F24: Site manager 事業所長 | G24: レ | J24: The site manager could explain an example that they voluntarily discussed safety with managers from other sites or external parties to improve safety knowledge. 事業所長は、安全関連の知識を向上するため、自発的に他の現場や外部の管理者と安全について討議した具体例を説明できた。
C25: Information 情報 | D25: 19 | E25: Is risk assessment taken when planning new projects/work sessions? 新たなプロジェクト/作業の計画段階において、RAが実施されていますか？ | F25: Site manager 事業所長 | G25: レ | I25: レ | J25: The site manager said that risk assessment is always done in the early planning stages for upcoming projects/work sessions and could show the recent RA result . 事業所長が、新しいプロジェクトや作業の初期計画段階でリスク評価を常に実施していると述べ、直近のRA結果を提示することができた。
C26: Communication コミュニケーション | D26: 20 | E26: Do you receive feedback from third party on effectiveness of safety management system to imorove it? 第三者（例.社外認証機関、SBU安全、BSB上位職者）による倉庫巡回やフィードバックを受け、改善に取り組んでいるか？ | F26: Site manager or if available, site safety 事業所長もしくは拠点安全担当 | G26: レ | J26: Regarding the safety management system in the sites, the respondent can explain evaluation results by third party (external, SBU Safety or Logistic Top management), feedback, and the actions. 回答者は、事業所の安全衛生マネジメントに対する第三者評価結果、フィードバック、およびその対応を説明できる。
K27: =IF(COUNTIF(K23:K26, "No"),"No","Yes") -> Yes
C29: *Incidents: lost-time-injury, fire accident, occupational disease, near-miss, etc. インシデント：災害・火災・業務上疾病・ヒヤリ 等

Sheet System
B1: Level | C1: System システム | D1: Element エレメント | E1: No | F1: Question 質問 | G1: Answered by 回答者 | H1: How to check 確認方法 | K1: Judgement Criteria 判断基準 | L1: Judgement 判断 | M1: Reason 判断理由
H2: Interview | I2: On-site observation | J2: Document check | K2: Note: Global target number of TMs who are interviewed is 10% and more in the site. Minimum target number is 3 in case 10% of all TMs is <3. 注記：インタビューする技能員の人数は、全従業員の10%以上をグローバル目標とする。なお10％が3人未満となる場合は、3人を目標とする。
B3: Ad-hoc | C3: Training and Education 教育訓練 | D3: Integration 関連付け | E3: 1 | F3: Have teammates been trained on the safety mission statement and high risk activity? *High-risk activity: Activity which are risk category III&IV. E.g. Work at height, heavy object handling, mobile equipment, caught by machine, tire inflation, etc. 従業員は、安全宣言および高リスク作業（5大リスク・重ポテ作業）について、教育を受けているか？ *高リスク作業：リスクカテゴリーIII&IVに該当するもの。例：高所作業、重量物、動力車、挟まれ・巻き込まれリスクのある作業、空気充填 等 | G3: Site manager or if available, site safety 事業所長もしくは拠点安全担当 | J3: レ | K3: Training records show all teammates on site have been given training on the Safety Mission Statement. Training records show that required employees have received training for high risk activities. 全ての従業員が安全宣言の教育を受けた記録がある。必要な従業員が高リスク作業に関する教育を受けた記録がある。
C4: Training and Education 教育訓練 | D4: Design 設計 | E4: 2 | F4: Are you aware of the regulations concerning safety training? あなたは、安全教育に関する法令要求を理解していますか？ | G4: Site manager 事業所長 | H4: レ | K4: The reapondent can explain the regulations concerning safety training. 回答者は、安全教育に関する法令要求を説明できる。
C5: Emergency Planning 緊急事態計画 | D5: Change & Emergency planning 変更管理 & 緊急事態準備 | E5: 3 | F5: Are the roles & responsibilities of emergency organization defined in the emergency response policy/procedure that complies with legal & local regulations? 法令要求を満足する緊急時対応手順があり、手順には対応組織と責任が明確化されているか？ | G5: Site manager or if available, site safety 事業所長もしくは拠点安全担当 | J5: レ | K5: The site emergency response policy/procedure has clarified the roles & responsibilities of each emerfency responders and been checked by the safety team to ensure the compliance with legal & local regulation. 事業所の緊急時対応手順は、緊急時対応者の役割と責任が含まれ、物流安全機能による法規面の確認を得ている。
C6: Communication コミュニケーション | D6: Integration 関連付け | E6: 4 | F6: When implementation of regular OH&S communication and OH&S training, does the site manager use the language where the teammates are familiar? 法令で要求される安全衛生の情報伝達や教育では、従業員の使用言語を用いているか？ | G6: Site manager or if available, site safety 事業所長もしくは拠点安全担当 | J6: レ | K6: There is no difference between the language used by teammates and the language used in the sampled communication record or training material. (or Multiple forms are used and language differences are accounted for.) 従業員の使用言語と、情報伝達や教育で用いたれる言語との齟齬がない。 (または、従業員にあわせて複数の言語で実施されている)
C7: LOTO Standard LOTO標準 | D7: Integration 関連付け | E7: 5 | F7: Do you conduct the LOTO training to the teammates who perform servicing or maintenance tasks, and distribute the Lock-out & Tag-out devices? 対象従業員に対し、LOTOの教育と、ロックアウト器具及びLOTO札の配布を行っていますか？ | G7: Site manager or if available, site safety 事業所長もしくは拠点安全担当 | I7: レ | J7: レ | K7: Training record indicates that the teammates who perform servicing or maintenance tasks have been trained on LOTO. On-site observation indicate that service and maintenance teammates who need LOTO have locks and tags. LOTO対象者へのLOTO教育した記録がある。また、現場確認にて、LOTO対象者がキーとタグを持っていることが確認できる。
C8: Safety Rules 安全ルール | D8: Integration 関連付け | E8: 6 | F8: Do tyou know the safety rules that are required to be followed? (8 common safety rules, mobile equipment rules, crane & hoist rules and tire inflation rules applying to his/her job position) あなたは、順守しなければならない安全ルールを知っていますか？(共通8ルール＋動力車+クレーン+空気充填) | G8: Teammate 技能員 | H8: レ | K8: All respondents know the applicable All Bridgestone Safety Rules in their job positions. 回答者全員が、自職場に適用されるブリヂストン共通安全ルールを知っている。
C9: Work at Height 高所作業 | D9: Integration 関連付け | E9: 7 | F9: Have you communicated Work at height requirements to teammates performing Work at height? 高所作業の要求事項は、高所作業を行う作業者に周知されていますか？ | G9: Supervisor 作業主任 | J9: レ | K9: There is the training and/or communication record for teammates performing Work at height. 高所作業を行う作業者への教育記録コミュニケーション記録（テスト記録）がある。
C10: Mobile Equipment 動力車 | D10: Integration 関連付け | E10: 8 | F10: Have you communicated requirements on mobile equipment to the drivers? 動力車の運転に関する要求事項は、動力車使用者に周知されていますか？ | G10: Supervisor 作業主任 | J10: レ | K10: There is the training and/or communication record for mobile equipment drivers. 動力車使用者への教育記録コミュニケーション記録（テスト記録）がある。
C11: 3S | D11: Integration 関連付け | E11: 9 | F11: Has the need for 3S(Select & remove, Sort, Keep clean) in the work area been communicated? 作業場における3S(整理・整頓・清掃）の必要性は、周知されているか？ | G11: Supervisor 作業主任 | J11: レ | K11: There is evidence that the need of 3S has been communicated to teammates. 3Sの必要性を従業員へ周知した記録がある。
C12: 3S | D12: Integration 関連付け | E12: 10 | F12: Are 3S visual standards displayed in work area? 3Sビジュアル標準は現場に表示されていますか？ | G12: Tour 現場確認 | I12: レ | K12: 3S Documents are displayed in work areas. 3S標準は現場に掲示されている。
C13: Crane and Hoist クレーン・ホイスト | D13: Integration 関連付け | E13: 11 | F13: How do you identify and ensure compliance to crane and hoist relevant safety legislation ? クレーン・ホイストの安全法令について、どのような方法で特定・順守確認を行っていますか？ | G13: Site manager or if available, site safety 事業所長もしくは拠点安全担当 | H13: レ | K13: The respondent can explain the regulations and give at least one method for ensuring compliance. 回答者は、法令要求を説明できる。また、それを保証する方法を少なくとも１つ提示できる。
C14: Crane and Hoist クレーン・ホイスト | D14: Integration 関連付け | E14: 12 | F14: Is there an established crane and hoist safety standard that complies with legal requirements? 作成されているクレーン・ホイスト標準は、法令要求を順守していますか？ | G14: Site manager or if available, site safety 事業所長もしくは拠点安全担当 | J14: レ | K14: There is a crane and hoist safety standard that highlights the legal requirements. クレーン・ホイストの標準は、法令要求を含んでいる。
C15: KY | D15: Integration 関連付け | E15: 13 | F15: Have the the process and the importance of KY been communicated to the teammates? KYの手順（4ラウンドKYT）と重要性は従業員へ周知されているか？ | G15: Supervisor 作業主任 | J15: レ | K15: There is evidence of a defined KY process that been communicated with teammates. 規定されたKYの手順を従業員へ周知した記録がある。
C16: Tire Inflation Operation タイヤ空気充填作業 | D16: Integration 関連付け | E16: 14 | F16: Has the tire inflation standard been communicated to the teammates? タイヤ空気充填作業標準は、作業者に周知されているか？ | G16: Teammate 技能員 | H16: レ | K16: The respondent can explain the key points which need to pay attention to in the tire inflation process. 回答者は、タイヤ空気充填作業における作業の急所(注意の必要な箇所)を説明できる。
C17: Contractor management 協力会社の安全管理 | D17: Integration 関連付け | E17: 15 | F17: Do you certify if contractor employees who perform unload/load the tires have required skills? (e.g. mobile equipment) 工事/作業を行う協力会社の従業員は、工事/作業に必要な能力・法的資格(例：クレーン・ホイスト）を有していることをどのように確認していますか？ | G17: Site manager or if available, site safety 事業所長もしくは拠点安全担当 | J17: レ | K17: There is evidence to certify that contractor employees who perform unload/load the tires have required skills. (e.g. mobile equipment) BSが、協力会社の従業員が工事/作業に必要な能力・法的資格(例：クレーン・ホイスト）を有していることを確認していることを示す書類がある。
C18: Large Tire Manual Handling Operation 大型タイヤハンドリング作業 | D18: Integration 関連付け | E18: 16 | F18: Are large tire manual handling operations identified and justified? Is there a procedure for each of these operations? 大型タイヤのハンドリング作業は特定されており、これらの各作業の標準はあるか？ | G18: Site manager or if available, site safety 事業所長もしくは拠点安全担当 | J18: レ | K18: Operations requiring manual handling of large tires are properly identified and justified. A working procedure exists for each. 大型タイヤの手動ハンドリングを必要とする作業は、適切に識別されており、各作業の作業標準が準備されている。
C19: Large Tire Manual Handling Operation 大型タイヤハンドリング作業 | D19: Integration 関連付け | E19: 17 | F19: Has the Large Tire Manual Handling Operation procedure been communicated to the relevant people? 大型タイヤハンドリング作業の標準は、関係者へコミュニケーション（周知）されているか？ | G19: Supervisor 作業主任 | J19: レ | K19: Training records show that all relevant people within the site have been given training on the Large Tire Manual Handling Operations procedure. 事業所内の全ての関係者が大型タイヤの手動ハンドリング作業手順に関する教育を受けたことを教育記録から確認できる。
C20: Integrated risk assessment リスクアセスメント | D20: Integration 関連付け | E20: 18 | F20: Have the OH&S and Fire risks in the site evaluated? 安全防災リスク評価を実施していますか？ | G20: Site manager or if available, site safety 事業所長もしくは拠点安全担当 | J20: レ | K20: There is evidence that OH&S and/or Fire risks in the site are evaluated. 事業所内の安全防災リスクを評価した記録がある。
C21: Integrated incidents management 災害対応・類災防止 | D21: Integration 関連付け | E21: 19 | F21: To whom do you report when incidents are identified? 労災や発火発煙事故、ヒヤリがあった場合、誰に報告しますか？ | G21: Teammate 技能員 | H21: レ | K21: The respondents can explain the person to whom they have to report. 回答者は、災害やヒヤリ情報を誰に報告すべきか回答できる。
C22: Integrated incidents management 災害対応・類災防止 | D22: Integration 関連付け | E22: 20 | F22: Are the incidents that occurred at other sites (BS group or external) communicated? 他事業所で起こった労働災害や発火発煙事故について、発生都度説明を受けていますか？ | G22: Teammate 技能員 | H22: レ | K22: The respondents can show an example of incident that occurred at other site 回答者は、他事業所で起きた災害事例を説明できる。
B24: Reactive | C24: Training and Education 教育訓練 | D24: Integration 関連付け | E24: 21 | F24: Have role specific trainings been identified and are given to the necessary people? 職種毎に教育が特定され、必要な人に教育されているか？ | G24: Supervisors 作業主任 | J24: レ | K24: There are knowledge/skill matrix table for each occupation/role, necessary training is described, and the implementation or plan of training can be confirmed. 各職種ごとの知識・技能要件表があり、必要な教育が記載されており、教育の実施または計画が確認できる。
C25: Training and Education 教育訓練 | D25: Design 設計 | E25: 22 | F25: Are the needs and the content of trainings reviewed and improved after an accident occurs? 災害発生後、教育の必要性や内容が見直し、改善されているか？ | G25: Supervisors 作業主任 | J25: レ | K25: Training documents indicate that training was reviewed after an accident. 災害後に教育内容や方法が見直された事例が、書面で確認できる。
C26: Emergency Planning 緊急事態計画 | D26: Change & Emergency planning 変更管理 & 緊急事態準備 | E26: 23 | F26: Do emergency drills periodically take place? 緊急時対応訓練は、定期的に実施されているか？ | G26: Site manager or if available, site safety 事業所長もしくは拠点安全担当 | J26: レ | K26: There is evidence of an emergency drill performed within the last 12 months. 過去1年間に実施した緊急事態訓練の実施記録がある。
C27: Emergency Planning 緊急事態計画 | D27: Change & Emergency planning 変更管理 & 緊急事態準備 | E27: 24 | F27: Are the emergency procedures reviewed and updated based on the results of drills or actual emergencies? 緊急時対応手順は、実際に発生した緊急時対応または訓練結果を踏まえ、見直しが行われているか？ | G27: Site manager or if available, site safety 事業所長もしくは拠点安全担当 | H27: レ | J27: レ | K27: The emergency response procedure was updated based on the review on the drills or performance of actual emergencies. 緊急時対応手順は、訓練結果や緊急時対応結果にもとづき見直しされている。
C28: Communication コミュニケーション | D28: Integration 関連付け | E28: 25 | F28: Are the causes of accidents/incidents communicated to teammates? 災害・事故の原因は従業員に周知されているか？ | G28: Teammate 技能員 | H28: レ | K28: The respondent indicates that the causes of incidents are communicated to him/her and how these information are communicated. 回答者は、災害の原因と、それが周知された場面を説明できる。
C29: LOTO Standard LOTO標準 | D29: Design 設計 | E29: 26 | F29: Is the LOTO standard reviewed after incidents, audits or opportunity areas have been identified? LOTO標準は、災害、監査、特定された（改善の）機会の後、見直しされていますか？ | G29: Site manager or if available, site safety 事業所長もしくは拠点安全担当 | H29: レ | J29: レ | K29: The respondent can show an example that LOTO standard (site standard, ECP, work standard, etc.) is reviewed in response to incidents, audit findings, authority guidance and concerns raised by teammates. The respondence agrees with the revision history of LOTO standard. 回答者は、災害・監査結果・行政指導・従業員からの困り事に基づき、LOTO標準（事業所の標準・ECP・作業標準等）が見直しされた事例を説明できる。その回答は、標準改訂履歴と一致する。
C30: Safety Rules 安全ルール | D30: Design 設計 | E30: 27 | F30: Is the effectiveness of the Site Safety Rules reviewed after incidents, audits or opportunity areas have been identified? 事業所の安全ルールの有効性は、災害、監査、特定された（改善の）機会の後、見直されていますか？ | G30: Site manager or if available, site safety 事業所長もしくは拠点安全担当 | H30: レ | K30: The respondent can show an example that Site Safety Rules are reviewed and improved. 回答者は、安全ルールが見直された、もしくは改善された事例を説明できる。
C31: Work at Height 高所作業 | D31: Design 設計 | E31: 28 | F31: What are the countermeasures against a incident involving work at height which occurred in your site in last 1 year? 過去1年間に自事業場で発生した高所作業関連の労働災害や事故に対する再発防止策は何ですか？ | G31: Teammate 技能員 | H31: レ | K31: All respondents can explain sampled countermeasures against the incident involving work at height which occurred in the site. 回答者全員が、過去1年間に自事業場で起きた高所作業の労働災害や事故の再発防止策を説明できる。
C32: Mobile Equipment 動力車 | D32: Design 設計 | E32: 29 | F32: What are the countermeasures against a incident involving mobile equipment which occurred in your site in last 1 year? 過去1年間に自事業場で発生した動力車関連の労働災害や事故に対する再発防止策は何ですか？ | G32: Teammate 技能員 | H32: レ | K32: All respondents can explain sampled countermeasures against the incident involving mobile equipment which occurred in the site. 回答者全員が、過去1年間に自事業場で起きた動力車関連の労働災害や事故の再発防止策を説明できる。
C33: 3S | D33: Integration 関連付け | E33: 30 | F33: Have 3S leaders been assigned from shop floor workers and have 3S self check by 3S leaders been periodically performed? 3Sリーダーを選任し、3Sリーダーによるセルフチェックは定期的に実施されていますか？ | G33: Site manager 事業所長 | H33: レ | K33: 3S leaders has been assigned and there is evidence of 3S self check performed by the 3S leaders. 3Sリーダーが選任され、セルフチェックを行った記録がある。
C34: Crane and Hoist クレーン・ホイスト | D34: Integration 関連付け | E34: 31 | F34: Is there a list of licensed crane operators? クレーンの有資格者リストはありますか？ | G34: Site manager or if available, site safety 事業所長 | J34: レ | K34: There is an official list of licensed crane operators that highlights the expiry dates of their licenses. クレーンの有資格者、および資格の期限に関し、正式なリストがある。
C35: Crane and Hoist クレーン・ホイスト | D35: Integration 関連付け | E35: 32 | F35: What are the countermeasures against a hoist & crane incident which occurred in your site in last 1 year? 過去1年間に自事業場で発生したクレーン関連の労働災害や事故に対する再発防止策は何ですか？ | G35: Teammate 技能員 | H35: レ | K35: All respondents can explain sampled countermeasures against hoist & crane incident which occurred in the site. 回答者全員が、過去1年間に自事業場で起きたクレーン関連の労働災害や事故の再発防止策を説明できる。
C36: KY | D36: Integration 関連付け | E36: 33 | F36: Have a KY leader and KY representatives been appointed? KY実行責任者とKY推進リーダーは、任命されていますか？ | G36: Site manager 事業所長 | H36: レ | K36: There are an officially appointed KY leader and KY representatives on site. 事業所で正式に任命されたKY実行責任者とKY推進リーダーがいる。
C37: Tire Inflation Operation タイヤ空気充填作業 | D37: Integration 関連付け | E37: 34 | F37: Is there a clearly marked area specifically for tire inflation? タイヤ空気充填の作業エリアは、明示されていますか？ | G37: Tour 現場確認 | I37: レ | K37: There is a clearly marked tire inflation area. 明確に明示されたタイヤ空気充填作業場がある。
C38: Tire Inflation Operation タイヤ空気充填作業 | D38: Integration 関連付け | E38: 35 | F38: Is basic safety equipment available in the inflation area? タイヤ空気充填の作業エリアにおいて、安全ゲージなどの災害防止措置は使える状態ですか？ | G38: Tour 現場確認 | I38: レ | K38: All the required safety equipment as stated in the Tire Inflation Operation procedure is in the inflation area. タイヤ空気充填作業手順に規定されている必要な安全装備は、充填作業場に用意されている。
C39: Contractor management 協力会社の安全管理 | D39: Integration 関連付け | E39: 36 | F39: Are pre-work meetings conducted prior to the start of work, are risks identified and risk mitigation measures/administrative controls defined. 作業の開始前に事前打ち合わせを実施し、リスクの顕在化およびその対応/リスク低減対策を決めていますか？ | G39: Site manager 事業所長 | J39: レ | K39: There is evidence that pre-work meetings are conducted prior to the start of work, risks are identified and risk mitigation measures/administrative controls are defined. 作業の開始前に事前打ち合わせを実施し、リスクの顕在化およびその対応/リスク低減対策を決めている記録がある。
C40: Large Tire Manual Handling Operation 大型タイヤハンドリング作業 | D40: Integration 関連付け | E40: 37 | F40: Is the large tire manual handling operation procedure reviewed in response to incidents? 災害・ヒヤリの発生に対して、大型タイヤ手動ハンドリング標準のレビュー（見直し）を行っているか？ | G40: Site manager or if available, site safety 事業所長もしくは拠点安全担当 | J40: レ | K40: The revision history of the large tire manual handling operations procedure indicate that it was reviewed based on a reported incident 大型タイヤの手動ハンドリング標準書の改訂履歴より、報告された災害・ヒヤリに基づいて、標準書が見直されていることが確認できる。
C41: Integrated risk assessment リスクアセスメント | D41: Integration 関連付け | E41: 38 | F41: Does the risk evaluation address the foreseeable hazards related to machine? 設備起因のリスクについて評価していますか？ | G41: Site manager or if available, site safety 事業所長もしくは拠点安全担当 | J41: レ | K41: There is evidence that machines risks in the site are evaluated. 設備RAを実施した記録がある。
...

Sheet (Ref.)Dashboard
C3: G-SMS Maturity Assessment / 安全成熟度
C4: Site: | H4: G-SMS Maturity Assessment / 安全成熟度
C5: Date:
C6: Assessor/評価者:
C7: Assessment type/評価種類: | F7: Validation assessment 妥当性評価
C9: Summary Result of Safety Maturity Assessment 安全成熟度評価結果 サマリー
C11: Maturity Levels | F11: Safety Maturity Outcome / 安全成熟度 結果
F12: =(F16+L16)/2 -> 0 | G12: =IF(F12=0,"N/A",IF(F12<2,"Ad-Hoc",IF(F12<3,"Reactive",IF(F12<4,"Standardized",IF(F12<5,"Proactive",IF(F12=5,"Excellence","N/A")))))) -> N/A
C13: 1 | D13: Ad-hoc
C15: 2 | D15: Reactive | F15: Safety Awareness ﾘｰﾀﾞｰ/一人ひとりの安全意識 | L15: System Implementation 安全ﾏﾈｼﾞﾒﾝﾄｼｽﾃﾑの運用度
F16: =(I20+F20)/2 -> 0 | G16: =IF(F16=0,"N/A",IF(F16<2,"Ad-Hoc",IF(F16<3,"Reactive",IF(F16<4,"Standardized",IF(F16<5,"Proactive",IF(F16=5,"Excellence","N/A")))))) -> N/A | L16: =(L20+O20)/2 -> 0 | M16: =IF(L16=0,"N/A",IF(L16<2,"Ad-Hoc",IF(L16<3,"Reactive",IF(L16<4,"Standardized",IF(L16<5,"Proactive",IF(L16=5,"Excellence","N/A")))))) -> N/A
C17: 3 | D17: Standardized
C19: 4 | D19: Proactive | F19: Leadership ﾘｰﾀﾞｰｼｯﾌﾟ | I19: Teammate Engagement 一人ひとり | L19: Organization 組織 | O19: System システム
F20: =MIN(F24:F26) -> 0 | G20: =IF(F20=0,"N/A",IF(F20<2,"Ad-Hoc",IF(F20<3,"Reactive",IF(F20<4,"Standardized",IF(F20<5,"Proactive",IF(F20=5,"Excellence","N/A")))))) -> N/A | I20: =MIN(I24:I26) -> 0 | J20: =IF(I20=0,"N/A",IF(I20<2,"Ad-Hoc",IF(I20<3,"Reactive",IF(I20<4,"Standardized",IF(I20<5,"Proactive",IF(I20=5,"Excellence","N/A")))))) -> N/A | L20: =MIN(L24:L26) -> 0 | M20: =IF(L20=0,"N/A",IF(L20<2,"Ad-Hoc",IF(L20<3,"Reactive",IF(L20<4,"Standardized",IF(L20<5,"Proactive",IF(L20=5,"Excellence","N/A")))))) -> N/A | O20: =MIN(O24:O26) -> 0 | P20: =IF(O20=0,"N/A",IF(O20<2,"Ad-Hoc",IF(O20<3,"Reactive",IF(O20<4,"Standardized",IF(O20<5,"Proactive",IF(O20=5,"Excellence","N/A")))))) -> N/A
C21: 5 | D21: Excellence
F23: Leadership Elements | I23: Teammate Engagement Elements | L23: Organization Elements | O23: System Elements
F24: ='Calculation sheet'!B29 -> - | G24: Prioritization 優先付け | I24: ='Calculation sheet'!B25 -> - | J24: Action 行動 | L24: ='Calculation sheet'!B21 -> - | M24: Participation 参画 | O24: ='Calculation sheet'!B17 -> - | P24: Design 設計
F25: ='Calculation sheet'!B30 -> - | G25: Decisions 意思決定 | I25: ='Calculation sheet'!B26 -> - | J25: Capability 能力 | L25: ='Calculation sheet'!B22 -> - | M25: Information 情報 | O25: ='Calculation sheet'!B18 -> - | P25: Integration 関連付け
F26: ='Calculation sheet'!B31 -> - | G26: Support 支援 | I26: ='Calculation sheet'!B27 -> - | J26: Knowledge 知識 | L26: ='Calculation sheet'!B23 -> - | M26: Communication コミュニケーション | O26: ='Calculation sheet'!B19 -> - | P26: Change & emergency planning 変更管理 & 緊急事態準備
C28: Output Visualization 成熟度の見える化
C30: Output Visualization 安全成熟度 | L30: Individual Process Results 規格の順守状況
F33: =F20 -> 0 | I33: =O20 -> 0
F44: =I20 -> 0 | I44: =L20 -> 0
C47: 4 Pillars | E47: Maturity level | G47: Strength 長所 | J47: Opportunity for Improvement 改善機会 | M47: Action items 実施事項 | P47: Due date 納期
C48: Leadership リーダーシップ | E48: =F20 -> 0
C49: Teammate Engagement 一人ひとり | E49: =I20 -> 0
C50: Organization 組織 | E50: =L20 -> 0
C51: System システム | E51: =O20 -> 0

Sheet Calculation sheet
A1: Checklist options | D1: Assessment types
A2: Yes | D2: Self-assessment セルフアセスメント
A3: No | D3: Validation assessment 妥当性評価
A5: Maturity levels
A6: Excellence | B6: 5 | C6: Excellence
A7: Proactive | B7: 4 | C7: Proactive
A8: Standardised | B8: 3 | C8: Standardised
A9: Reactive | B9: 2 | C9: Reactive
A10: Passive | B10: 1 | C10: Passive
C15: Ad-hoc | F15: Reactive | I15: Standardized | L15: Proactive | O15: Excellent | R15: Total | S15: filled out
B16: Score | C16: Yes | D16: No | E16: Other | F16: Yes | G16: No | H16: Other | I16: Yes | J16: No | K16: Other | L16: Yes | M16: No | N16: Other | O16: Yes | P16: No | Q16: Other | R16: questions | S16: questions | T16: <System>
A17: Design | B17: {=_xlfn.IFS(S17="to be done","-",D17+G17>0,1,J17>0,2,I17=0,_xlfn.IFS(M17>0,2,L17=0,_xlfn.IFS(P17>0,2,I17>0,3,O17=0,4,P17=0,5)),L17=0,_xlfn.IFS(M17>0,3,O17=0,3,P17>0,3),M17>0,3,P17>0,4,O17>0,5,O17=0,4)} -> - | C17: =COUNTIFS(System!$D$3:$D$22,T17,System!$L$3:$L$22,C$16) -> 0 | D17: =COUNTIFS(System!$D$3:$D$22,T17,System!$L$3:$L$22,D$16) -> 0 | E17: =COUNTIFS(System!$D$3:$D$22,T17,System!$L$3:$L$22,"N/A")+COUNTIFS(System!$D$3:$D$22,T17,System!$L$3:$L$22,"Not rolled out yet") -> 0 | F17: =COUNTIFS(System!$D$24:$D$44,T17,System!$L$24:$L$44,F$16) -> 0 | G17: =COUNTIFS(System!$D$24:$D$44,T17,System!$L$24:$L$44,G$16) -> 0 | H17: =COUNTIFS(System!$D$24:$D$44,T17,System!$L$24:$L$44,"N/A")+COUNTIFS(System!$D$24:$D$44,T17,System!$L$24:$L$44,"Not rolled out yet") -> 0 | I17: =COUNTIFS(System!$D$46:$D$67,T17,System!$L$46:$L$67,I$16) -> 0 | J17: =COUNTIFS(System!$D$46:$D$67,T17,System!$L$46:$L$67,J$16) -> 0 | K17: =COUNTIFS(System!$D$46:$D$67,T17,System!$L$46:$L$67,"N/A")+COUNTIFS(System!$D$46:$D$67,T17,System!$L$46:$L$67,"Not rolled out yet") -> 0 | L17: =COUNTIFS(System!$D$69:$D$90,T17,System!$L$69:$L$90,L$16) -> 0 | M17: =COUNTIFS(System!$D$69:$D$90,T17,System!$L$69:$L$90,M$16) -> 0 | N17: =COUNTIFS(System!$D$69:$D$90,T17,System!$L$69:$L$90,"N/A")+COUNTIFS(System!$D$69:$D$90,T17,System!$L$69:$L$90,"Not rolled out yet") -> 0 | O17: =COUNTIFS(System!$D$92:$D$107,T17,System!$L$92:$L$107,O$16) -> 0 | P17: =COUNTIFS(System!$D$92:$D$107,T17,System!$L$92:$L$107,P$16) -> 0 | Q17: =COUNTIFS(System!$D$92:$D$107,T17,System!$L$92:$L$107,"N/A")+COUNTIFS(System!$D$92:$D$107,T17,System!$L$92:$L$107,"Not rolled out yet") -> 0 | R17: =COUNTIF(System!$D$3:$D$107,T17) -> 23 | S17: =IF(SUM(C17:Q17)=R17,"done","to be done") -> to be done | T17: Design 設計
A18: Integration | B18: {=_xlfn.IFS(S18="to be done","-",D18+G18>0,1,J18>0,2,I18=0,_xlfn.IFS(M18>0,2,L18=0,_xlfn.IFS(P18>0,2,I18>0,3,O18=0,4,P18=0,5)),L18=0,_xlfn.IFS(M18>0,3,O18=0,3,P18>0,3),M18>0,3,P18>0,4,O18>0,5,O18=0,4)} -> - | C18: =COUNTIFS(System!$D$3:$D$22,T18,System!$L$3:$L$22,C$16) -> 0 | D18: =COUNTIFS(System!$D$3:$D$22,T18,System!$L$3:$L$22,D$16) -> 0 | E18: =COUNTIFS(System!$D$3:$D$22,T18,System!$L$3:$L$22,"N/A")+COUNTIFS(System!$D$3:$D$22,T18,System!$L$3:$L$22,"Not rolled out yet") -> 0 | F18: =COUNTIFS(System!$D$24:$D$44,T18,System!$L$24:$L$44,F$16) -> 0 | G18: =COUNTIFS(System!$D$24:$D$44,T18,System!$L$24:$L$44,G$16) -> 0 | H18: =COUNTIFS(System!$D$24:$D$44,T18,System!$L$24:$L$44,"N/A")+COUNTIFS(System!$D$24:$D$44,T18,System!$L$24:$L$44,"Not rolled out yet") -> 0 | I18: =COUNTIFS(System!$D$46:$D$67,T18,System!$L$46:$L$67,I$16) -> 0 | J18: =COUNTIFS(System!$D$46:$D$67,T18,System!$L$46:$L$67,J$16) -> 0 | K18: =COUNTIFS(System!$D$46:$D$67,T18,System!$L$46:$L$67,"N/A")+COUNTIFS(System!$D$46:$D$67,T18,System!$L$46:$L$67,"Not rolled out yet") -> 0 | L18: =COUNTIFS(System!$D$69:$D$90,T18,System!$L$69:$L$90,L$16) -> 0 | M18: =COUNTIFS(System!$D$69:$D$90,T18,System!$L$69:$L$90,M$16) -> 0 | N18: =COUNTIFS(System!$D$69:$D$90,T18,System!$L$69:$L$90,"N/A")+COUNTIFS(System!$D$69:$D$90,T18,System!$L$69:$L$90,"Not rolled out yet") -> 0 | O18: =COUNTIFS(System!$D$92:$D$107,T18,System!$L$92:$L$107,O$16) -> 0 | P18: =COUNTIFS(System!$D$92:$D$107,T18,System!$L$92:$L$107,P$16) -> 0 | Q18: =COUNTIFS(System!$D$92:$D$107,T18,System!$L$92:$L$107,"N/A")+COUNTIFS(System!$D$92:$D$107,T18,System!$L$92:$L$107,"Not rolled out yet") -> 0 | R18: =COUNTIF(System!$D$3:$D$107,T18) -> 71 | S18: =IF(SUM(C18:Q18)=R18,"done","to be done") -> to be done | T18: Integration 関連付け
A19: Change & Emergency | B19: {=_xlfn.IFS(S19="to be done","-",D19+G19>0,1,J19>0,2,I19=0,_xlfn.IFS(M19>0,2,L19=0,_xlfn.IFS(P19>0,2,I19>0,3,O19=0,4,P19=0,5)),L19=0,_xlfn.IFS(M19>0,3,O19=0,3,P19>0,3),M19>0,3,P19>0,4,O19>0,5,O19=0,4)} -> - | C19: =COUNTIFS(System!$D$3:$D$22,T19,System!$L$3:$L$22,C$16) -> 0 | D19: =COUNTIFS(System!$D$3:$D$22,T19,System!$L$3:$L$22,D$16) -> 0 | E19: =COUNTIFS(System!$D$3:$D$22,T19,System!$L$3:$L$22,"N/A")+COUNTIFS(System!$D$3:$D$22,T19,System!$L$3:$L$22,"Not rolled out yet") -> 0 | F19: =COUNTIFS(System!$D$24:$D$44,T19,System!$L$24:$L$44,F$16) -> 0 | G19: =COUNTIFS(System!$D$24:$D$44,T19,System!$L$24:$L$44,G$16) -> 0 | H19: =COUNTIFS(System!$D$24:$D$44,T19,System!$L$24:$L$44,"N/A")+COUNTIFS(System!$D$24:$D$44,T19,System!$L$24:$L$44,"Not rolled out yet") -> 0 | I19: =COUNTIFS(System!$D$46:$D$67,T19,System!$L$46:$L$67,I$16) -> 0 | J19: =COUNTIFS(System!$D$46:$D$67,T19,System!$L$46:$L$67,J$16) -> 0 | K19: =COUNTIFS(System!$D$46:$D$67,T19,System!$L$46:$L$67,"N/A")+COUNTIFS(System!$D$46:$D$67,T19,System!$L$46:$L$67,"Not rolled out yet") -> 0 | L19: =COUNTIFS(System!$D$69:$D$90,T19,System!$L$69:$L$90,L$16) -> 0 | M19: =COUNTIFS(System!$D$69:$D$90,T19,System!$L$69:$L$90,M$16) -> 0 | N19: =COUNTIFS(System!$D$69:$D$90,T19,System!$L$69:$L$90,"N/A")+COUNTIFS(System!$D$69:$D$90,T19,System!$L$69:$L$90,"Not rolled out yet") -> 0 | O19: =COUNTIFS(System!$D$92:$D$107,T19,System!$L$92:$L$107,O$16) -> 0 | P19: =COUNTIFS(System!$D$92:$D$107,T19,System!$L$92:$L$107,P$16) -> 0 | Q19: =COUNTIFS(System!$D$92:$D$107,T19,System!$L$92:$L$107,"N/A")+COUNTIFS(System!$D$92:$D$107,T19,System!$L$92:$L$107,"Not rolled out yet") -> 0 | R19: =COUNTIF(System!$D$3:$D$107,T19) -> 7 | S19: =IF(SUM(C19:Q19)=R19,"done","to be done") -> to be done | T19: Change & Emergency planning 変更管理 & 緊急事態準備
T20: <Organization>
A21: Participation | B21: {=_xlfn.IFS(S21="to be done","-",D21+G21>0,1,J21>0,2,I21=0,_xlfn.IFS(M21>0,2,L21=0,_xlfn.IFS(P21>0,2,I21>0,3,O21=0,4,P21=0,5)),L21=0,_xlfn.IFS(M21>0,3,O21=0,3,P21>0,3),M21>0,3,P21>0,4,O21>0,5,O21=0,4)} -> - | C21: =COUNTIFS(Organization!$C$3:$C$6,T21,Organization!$K$3:$K$6,C$16) -> 0 | D21: =COUNTIFS(Organization!$C$3:$C$6,T21,Organization!$K$3:$K$6,D$16) -> 0 | E21: =COUNTIFS(Organization!$C$3:$C$6,T21,Organization!$K$3:$K$6,"N/A")+COUNTIFS(Organization!$C$3:$C$6,T21,Organization!$K$3:$K$6,"Not rolled out yet") -> 0 | F21: =COUNTIFS(Organization!$C$8:$C$11,T21,Organization!$K$8:$K$11,F$16) -> 0 | G21: =COUNTIFS(Organization!$C$8:$C$11,T21,Organization!$K$8:$K$11,G$16) -> 0 | H21: =COUNTIFS(Organization!$C$8:$C$11,T21,Organization!$K$8:$K$11,"N/A")+COUNTIFS(Organization!$C$8:$C$11,T21,Organization!$K$8:$K$11,"Not rolled out yet") -> 0 | I21: =COUNTIFS(Organization!$C$13:$C$16,T21,Organization!$K$13:$K$16,I$16) -> 0 | J21: =COUNTIFS(Organization!$C$13:$C$16,T21,Organization!$K$13:$K$16,J$16) -> 0 | K21: =COUNTIFS(Organization!$C$13:$C$16,T21,Organization!$K$13:$K$16,"N/A")+COUNTIFS(Organization!$C$13:$C$16,T21,Organization!$K$13:$K$16,"Not rolled out yet") -> 0 | L21: =COUNTIFS(Organization!$C$18:$C$21,T21,Organization!$K$18:$K$21,L$16) -> 0 | M21: =COUNTIFS(Organization!$C$18:$C$21,T21,Organization!$K$18:$K$21,M$16) -> 0 | N21: =COUNTIFS(Organization!$C$18:$C$21,T21,Organization!$K$18:$K$21,"N/A")+COUNTIFS(Organization!$C$18:$C$21,T21,Organization!$K$18:$K$21,"Not rolled out yet") -> 0 | O21: =COUNTIFS(Organization!$C$23:$C$26,T21,Organization!$K$23:$K$26,O$16) -> 0 | P21: =COUNTIFS(Organization!$C$23:$C$26,T21,Organization!$K$23:$K$26,P$16) -> 0 | Q21: =COUNTIFS(Organization!$C$23:$C$26,T21,Organization!$K$23:$K$26,"N/A")+COUNTIFS(Organization!$C$23:$C$26,T21,Organization!$K$23:$K$26,"Not rolled out yet") -> 0 | R21: =COUNTIF(Organization!$C$3:$C$26,T21) -> 7 | S21: =IF(SUM(C21:Q21)=R21,"done","to be done") -> to be done | T21: Participation 参加
A22: Information | B22: {=_xlfn.IFS(S22="to be done","-",D22+G22>0,1,J22>0,2,I22=0,_xlfn.IFS(M22>0,2,L22=0,_xlfn.IFS(P22>0,2,I22>0,3,O22=0,4,P22=0,5)),L22=0,_xlfn.IFS(M22>0,3,O22=0,3,P22>0,3),M22>0,3,P22>0,4,O22>0,5,O22=0,4)} -> - | C22: =COUNTIFS(Organization!$C$3:$C$6,T22,Organization!$K$3:$K$6,C$16) -> 0 | D22: =COUNTIFS(Organization!$C$3:$C$6,T22,Organization!$K$3:$K$6,D$16) -> 0 | E22: =COUNTIFS(Organization!$C$3:$C$6,T22,Organization!$K$3:$K$6,"N/A")+COUNTIFS(Organization!$C$3:$C$6,T22,Organization!$K$3:$K$6,"Not rolled out yet") -> 0 | F22: =COUNTIFS(Organization!$C$8:$C$11,T22,Organization!$K$8:$K$11,F$16) -> 0 | G22: =COUNTIFS(Organization!$C$8:$C$11,T22,Organization!$K$8:$K$11,G$16) -> 0 | H22: =COUNTIFS(Organization!$C$8:$C$11,T22,Organization!$K$8:$K$11,"N/A")+COUNTIFS(Organization!$C$8:$C$11,T22,Organization!$K$8:$K$11,"Not rolled out yet") -> 0 | I22: =COUNTIFS(Organization!$C$13:$C$16,T22,Organization!$K$13:$K$16,I$16) -> 0 | J22: =COUNTIFS(Organization!$C$13:$C$16,T22,Organization!$K$13:$K$16,J$16) -> 0 | K22: =COUNTIFS(Organization!$C$13:$C$16,T22,Organization!$K$13:$K$16,"N/A")+COUNTIFS(Organization!$C$13:$C$16,T22,Organization!$K$13:$K$16,"Not rolled out yet") -> 0 | L22: =COUNTIFS(Organization!$C$18:$C$21,T22,Organization!$K$18:$K$21,L$16) -> 0 | M22: =COUNTIFS(Organization!$C$18:$C$21,T22,Organization!$K$18:$K$21,M$16) -> 0 | N22: =COUNTIFS(Organization!$C$18:$C$21,T22,Organization!$K$18:$K$21,"N/A")+COUNTIFS(Organization!$C$18:$C$21,T22,Organization!$K$18:$K$21,"Not rolled out yet") -> 0 | O22: =COUNTIFS(Organization!$C$23:$C$26,T22,Organization!$K$23:$K$26,O$16) -> 0 | P22: =COUNTIFS(Organization!$C$23:$C$26,T22,Organization!$K$23:$K$26,P$16) -> 0 | Q22: =COUNTIFS(Organization!$C$23:$C$26,T22,Organization!$K$23:$K$26,"N/A")+COUNTIFS(Organization!$C$23:$C$26,T22,Organization!$K$23:$K$26,"Not rolled out yet") -> 0 | R22: =COUNTIF(Organization!$C$3:$C$26,T22) -> 5 | S22: =IF(SUM(C22:Q22)=R22,"done","to be done") -> to be done | T22: Information 情報
A23: Communication | B23: {=_xlfn.IFS(S23="to be done","-",D23+G23>0,1,J23>0,2,I23=0,_xlfn.IFS(M23>0,2,L23=0,_xlfn.IFS(P23>0,2,I23>0,3,O23=0,4,P23=0,5)),L23=0,_xlfn.IFS(M23>0,3,O23=0,3,P23>0,3),M23>0,3,P23>0,4,O23>0,5,O23=0,4)} -> - | C23: =COUNTIFS(Organization!$C$3:$C$6,T23,Organization!$K$3:$K$6,C$16) -> 0 | D23: =COUNTIFS(Organization!$C$3:$C$6,T23,Organization!$K$3:$K$6,D$16) -> 0 | E23: =COUNTIFS(Organization!$C$3:$C$6,T23,Organization!$K$3:$K$6,"N/A")+COUNTIFS(Organization!$C$3:$C$6,T23,Organization!$K$3:$K$6,"Not rolled out yet") -> 0 | F23: =COUNTIFS(Organization!$C$8:$C$11,T23,Organization!$K$8:$K$11,F$16) -> 0 | G23: =COUNTIFS(Organization!$C$8:$C$11,T23,Organization!$K$8:$K$11,G$16) -> 0 | H23: =COUNTIFS(Organization!$C$8:$C$11,T23,Organization!$K$8:$K$11,"N/A")+COUNTIFS(Organization!$C$8:$C$11,T23,Organization!$K$8:$K$11,"Not rolled out yet") -> 0 | I23: =COUNTIFS(Organization!$C$13:$C$16,T23,Organization!$K$13:$K$16,I$16) -> 0 | J23: =COUNTIFS(Organization!$C$13:$C$16,T23,Organization!$K$13:$K$16,J$16) -> 0 | K23: =COUNTIFS(Organization!$C$13:$C$16,T23,Organization!$K$13:$K$16,"N/A")+COUNTIFS(Organization!$C$13:$C$16,T23,Organization!$K$13:$K$16,"Not rolled out yet") -> 0 | L23: =COUNTIFS(Organization!$C$18:$C$21,T23,Organization!$K$18:$K$21,L$16) -> 0 | M23: =COUNTIFS(Organization!$C$18:$C$21,T23,Organization!$K$18:$K$21,M$16) -> 0 | N23: =COUNTIFS(Organization!$C$18:$C$21,T23,Organization!$K$18:$K$21,"N/A")+COUNTIFS(Organization!$C$18:$C$21,T23,Organization!$K$18:$K$21,"Not rolled out yet") -> 0 | O23: =COUNTIFS(Organization!$C$23:$C$26,T23,Organization!$K$23:$K$26,O$16) -> 0 | P23: =COUNTIFS(Organization!$C$23:$C$26,T23,Organization!$K$23:$K$26,P$16) -> 0 | Q23: =COUNTIFS(Organization!$C$23:$C$26,T23,Organization!$K$23:$K$26,"N/A")+COUNTIFS(Organization!$C$23:$C$26,T23,Organization!$K$23:$K$26,"Not rolled out yet") -> 0 | R23: =COUNTIF(Organization!$C$3:$C$26,T23) -> 8 | S23: =IF(SUM(C23:Q23)=R23,"done","to be done") -> to be done | T23: Communication コミュニケーション
T24: <TM engagement>
