Workbook

Sheet Safety Cover
X1: Issue: 2025/7/7
W2: 7310
B3: Safety Solidification Report
B4: Site | D4: BMT | G4: Date | J4: June 11 - 13, 2025
B6: QM foundation (management system) 3 axes
C8: Items | J8: 2025 | L8: 2024 | O8: 3 Axes Chart
J9: Score | L9: Score
I10: Total Ave | J10: =Cal!#REF! -> #REF! | K10: =IF(J10<2,"C",IF(J10<3,"B-",IF(J10<4,"B",IF(J10<5,"B+",IF(J10=5,"A",""))))) -> #REF! | L10: =Cal!#REF! -> #REF! | M10: =IF(L10=5,"A",IF(L10>=4,"B+",IF(L10>=3,"B",IF(L10>=2,"B-",IF(L10>=1, "C","-"))))) -> #REF!
D11: 3 Axes Evaluation | E11: Risk Detection and Reduction/Continuous Improvement | H11: Ave | J11: =Cal!#REF! -> #REF! | K11: =IF(J11=5,"A",IF(J11>=4,"B+",IF(J11>=3,"B",IF(J11>=2,"B-",IF(J11>=1, "C","-"))))) -> #REF! | L11: =Cal!#REF! -> #REF! | M11: =IF(L11=5,"A",IF(L11>=4,"B+",IF(L11>=3,"B",IF(L11>=2,"B-",IF(L11>=1, "C","-"))))) -> #REF!
H12: Distribution | I12: B+ or more | J12: =Cal!#REF! -> #REF! | L12: =Cal!#REF! -> #REF!
I13: B | J13: =Cal!#REF! -> #REF! | L13: =Cal!#REF! -> #REF!
I14: B- | J14: =Cal!#REF! -> #REF! | L14: =Cal!#REF! -> #REF!
I15: C | J15: =Cal!#REF! -> #REF! | L15: =Cal!#REF! -> #REF!
E16: Safety Rule Compliance/Safety Awareness Cultivation | H16: Ave | J16: =Cal!#REF! -> #REF! | K16: =IF(J16=5,"A",IF(J16>=4,"B+",IF(J16>=3,"B",IF(J16>=2,"B-",IF(J16>=1, "C","-"))))) -> #REF! | L16: =Cal!#REF! -> #REF! | M16: =IF(L16=5,"A",IF(L16>=4,"B+",IF(L16>=3,"B",IF(L16>=2,"B-",IF(L16>=1, "C","-"))))) -> #REF!
H17: Distribution | I17: B+ or more | J17: =Cal!#REF! -> #REF! | L17: =Cal!#REF! -> #REF!
I18: B | J18: =Cal!#REF! -> #REF! | L18: =Cal!#REF! -> #REF! | O18: Distribution
I19: B- | J19: =Cal!#REF! -> #REF! | L19: =Cal!#REF! -> #REF! | O19: Risk | Q19: 2025
I20: C | J20: =Cal!#REF! -> #REF! | L20: =Cal!#REF! -> #REF! | Q20: 2024
E21: Strengthening of Governance and Systems to Make Quality Management More Effective | H21: Ave | J21: =Cal!#REF! -> #REF! | K21: =IF(J21=5,"A",IF(J21>=4,"B+",IF(J21>=3,"B",IF(J21>=2,"B-",IF(J21>=1, "C","-"))))) -> #REF! | L21: =Cal!#REF! -> #REF! | M21: =IF(L21=5,"A",IF(L21>=4,"B+",IF(L21>=3,"B",IF(L21>=2,"B-",IF(L21>=1, "C","-"))))) -> #REF! | O21: Compliance | Q21: 2025
H22: Distribution | I22: B+ or more | J22: =Cal!#REF! -> #REF! | L22: =Cal!#REF! -> #REF! | Q22: 2024
I23: B | J23: =Cal!#REF! -> #REF! | L23: =Cal!#REF! -> #REF! | O23: Governance | Q23: 2025
I24: B- | J24: =Cal!#REF! -> #REF! | L24: =Cal!#REF! -> #REF! | Q24: 2024
I25: C | J25: =Cal!#REF! -> #REF! | L25: =Cal!#REF! -> #REF!
B27: QM foundation (management system) 5 axes
C29: Solidification 5 items | F29: 2025 | J29: 2024 | O29: Ave Score | T29: Min Score
F30: Ave | H30: Min | J30: Ave | L30: Min
F31: Score | H31: Score | J31: Score | L31: Score
C32: Issue solving | F32: =Cal!#REF! -> #REF! | G32: =IF(F32<2,"C",IF(F32<3,"B-",IF(F32<4,"B",IF(F32<5,"B+",IF(F32=5,"A",""))))) -> #REF! | H32: =Cal!#REF! -> #REF! | I32: =IF(H32<2,"C",IF(H32<3,"B-",IF(H32<4,"B",IF(H32<5,"B+",IF(H32=5,"A",""))))) -> #REF! | J32: =Cal!#REF! -> #REF! | K32: =IF(J32<2,"C",IF(J32<3,"B-",IF(J32<4,"B",IF(J32<5,"B+",IF(J32=5,"A",""))))) -> #REF! | L32: =Cal!#REF! -> #REF! | M32: =IF(L32<2,"C",IF(L32<3,"B-",IF(L32<4,"B",IF(L32<5,"B+",IF(L32=5,"A",""))))) -> #REF!
C33: Risk Management | F33: =Cal!#REF! -> #REF! | G33: =IF(F33<2,"C",IF(F33<3,"B-",IF(F33<4,"B",IF(F33<5,"B+",IF(F33=5,"A",""))))) -> #REF! | H33: =Cal!#REF! -> #REF! | I33: =IF(H33<2,"C",IF(H33<3,"B-",IF(H33<4,"B",IF(H33<5,"B+",IF(H33=5,"A",""))))) -> #REF! | J33: =Cal!#REF! -> #REF! | K33: =IF(J33<2,"C",IF(J33<3,"B-",IF(J33<4,"B",IF(J33<5,"B+",IF(J33=5,"A",""))))) -> #REF! | L33: =Cal!#REF! -> #REF! | M33: =IF(L33<2,"C",IF(L33<3,"B-",IF(L33<4,"B",IF(L33<5,"B+",IF(L33=5,"A",""))))) -> #REF!
C34: Business Strategy Adjustment | F34: =Cal!#REF! -> #REF! | G34: =IF(F34<2,"C",IF(F34<3,"B-",IF(F34<4,"B",IF(F34<5,"B+",IF(F34=5,"A",""))))) -> #REF! | H34: =Cal!#REF! -> #REF! | I34: =IF(H34<2,"C",IF(H34<3,"B-",IF(H34<4,"B",IF(H34<5,"B+",IF(H34=5,"A",""))))) -> #REF! | J34: =Cal!#REF! -> #REF! | K34: =IF(J34<2,"C",IF(J34<3,"B-",IF(J34<4,"B",IF(J34<5,"B+",IF(J34=5,"A",""))))) -> #REF! | L34: =Cal!#REF! -> #REF! | M34: =IF(L34<2,"C",IF(L34<3,"B-",IF(L34<4,"B",IF(L34<5,"B+",IF(L34=5,"A",""))))) -> #REF!
C35: Independency and Continuity | F35: =Cal!#REF! -> #REF! | G35: =IF(F35<2,"C",IF(F35<3,"B-",IF(F35<4,"B",IF(F35<5,"B+",IF(F35=5,"A",""))))) -> #REF! | H35: =Cal!#REF! -> #REF! | I35: =IF(H35<2,"C",IF(H35<3,"B-",IF(H35<4,"B",IF(H35<5,"B+",IF(H35=5,"A",""))))) -> #REF! | J35: =Cal!#REF! -> #REF! | K35: =IF(J35<2,"C",IF(J35<3,"B-",IF(J35<4,"B",IF(J35<5,"B+",IF(J35=5,"A",""))))) -> #REF! | L35: =Cal!#REF! -> #REF! | M35: =IF(L35<2,"C",IF(L35<3,"B-",IF(L35<4,"B",IF(L35<5,"B+",IF(L35=5,"A",""))))) -> #REF!
C36: Integration/ Incorporation | F36: =Cal!#REF! -> #REF! | G36: =IF(F36<2,"C",IF(F36<3,"B-",IF(F36<4,"B",IF(F36<5,"B+",IF(F36=5,"A",""))))) -> #REF! | H36: =Cal!#REF! -> #REF! | I36: =IF(H36<2,"C",IF(H36<3,"B-",IF(H36<4,"B",IF(H36<5,"B+",IF(H36=5,"A",""))))) -> #REF! | J36: =Cal!#REF! -> #REF! | K36: =IF(J36<2,"C",IF(J36<3,"B-",IF(J36<4,"B",IF(J36<5,"B+",IF(J36=5,"A",""))))) -> #REF! | L36: =Cal!#REF! -> #REF! | M36: =IF(L36<2,"C",IF(L36<3,"B-",IF(L36<4,"B",IF(L36<5,"B+",IF(L36=5,"A",""))))) -> #REF!
C38: Total Ave | F38: =AVERAGE(F32:F36) -> #REF! | G38: =IF(F38<2,"C",IF(F38<3,"B-",IF(F38<4,"B",IF(F38<5,"B+",IF(F38=5,"A",""))))) -> #REF! | H38: =AVERAGE(H32:H36) -> #REF! | I38: =IF(H38<2,"C",IF(H38<3,"B-",IF(H38<4,"B",IF(H38<5,"B+",IF(H38=5,"A",""))))) -> #REF! | J38: =AVERAGE(J32:J36) -> #REF! | K38: =IF(J38<2,"C",IF(J38<3,"B-",IF(J38<4,"B",IF(J38<5,"B+",IF(J38=5,"A",""))))) -> #REF! | L38: =AVERAGE(L32:L36) -> #REF! | M38: =IF(L38<2,"C",IF(L38<3,"B-",IF(L38<4,"B",IF(L38<5,"B+",IF(L38=5,"A",""))))) -> #REF!
B40: Comment
C42: <Improvement Status from the last year's instruction> From last year, some issues found in the 2024 assessment have been improved, and at this time, we could observe some items could be more improved. <Comments from 3 axes points of view> Safety activities have been conducted and followed-up as plan by EHS team's leadership. Please promote KAIZEN improvement with use of autonomously KY, RA, etc. with reviewing the activities progress and result. Not only making periodical action plan, but we can find other points could be improved. <Risk> RIsk management have been well maintained. By comparing the reslut of RA with same machine, process, not only inside plant but other SC plant to realize what/where the risks exist, and how to reduce it. *In GENBA tour at this time, we could find some machines that have risks by using one hand swith - should have both hands swith when it is upgraded/renewed. Please see the appendix for detail. <Compliance> This area's score is lower than the other two area because of basic training leakage. (BSFA/LOTO) These kind of basic training should be periodically given to all teammates, to make them understand/remind the contents. Please make sure all training framework again. <Governance> Almost safety activities are well managed by action plan and its reviewing. For more works as BMT(plant wide), please confrim all managers understanding of safety activity - why do we need the items in action plan. And make sure of sharing management review from safety/DP point of view with all managers to understand safety safety activities result and what issues do we have.

Sheet Safety Instruction
M1: 発行日： | N1: 45128
C2: Solidification Assessment Safety Instruction
C4: Site | D4: ='Safety Cover'!D4 -> BMT | N4: 継続：現状維持、 レベルアップ：A、B＋、Bレベルへの改善 新規：過去に指摘・提案がない
C6: Solidification 5 items | D6: Point of Evaluation | E6: Primary Categoty | F6: Secondary Categoty | G6: 3 Axes Evaluation | H6: Result | J6: 2026 Target | K6: Issues and/or Changes | L6: Instruction - Items could be Incorporated into MBP | M6: Implementation Items | N6: Category
H7: 2024 | I7: 2025 | N7: Continue | O7: Level up | P7: New
C9: Issue solving | D9: Quickness of issue solving Deep root cause analysis, standardization and implementation | E9: Cuntermeasures and Recurrence prevention | F9: Information Sharing | G9: Governance | H9: =INDEX(Data!$P$4:$AA$33,MATCH('Safety Instruction'!$F9,Data!$Q$4:$Q$33,0),MATCH('Safety Instruction'!$D$4,Data!$P$4:$AA$4,0)) -> A | I9: ='Safety cal.'!Z15 -> A | J9: A | K9: Safety incidents which occurred on your site and other sites are informed to all teammates. H&S risks/measures of other departments are not shared within your site. | L9: Consider to share H&S risks/measures of other departments. (ex. Tapping risk is shared with factory operators.) | M9: Prepare an opportunity to H&S risks/measures of other departments. | O9: X | S9: 情報展開 | T9: Information Sharing
F10: Recurrence Prevention | G10: Risk | H10: =INDEX(Data!$P$4:$AA$33,MATCH('Safety Instruction'!$F10,Data!$Q$4:$Q$33,0),MATCH('Safety Instruction'!$D$4,Data!$P$4:$AA$4,0)) -> C | I10: ='Safety cal.'!Z16 -> A | J10: B+ | K10: Injury information was well informed with teammates but some operator could not cleary stated the relation to their operation. (only stated the glass crash accident) | L10: Not only information itself, but please consider to inform operator including similar/same situation in one's workplace. | M10: Please consider to instruct supervisors to inform operator including similar/same situation in one's workplace. | O10: X | S10: 再発防止 対策 | T10: Recurrence Prevention
F11: Injury Reporting | G11: Governance | H11: =INDEX(Data!$P$4:$AA$33,MATCH('Safety Instruction'!$F11,Data!$Q$4:$Q$33,0),MATCH('Safety Instruction'!$D$4,Data!$P$4:$AA$4,0)) -> A | I11: ='Safety cal.'!Z17 -> A | J11: A | K11: Keep the current condition. | L11: - | M11: Continue to report timely. | N11: X | S11: 災害報告 | T11: Injury Reporting
F12: Recurrence Prevention Process KPI | G12: Risk | H12: =INDEX(Data!$P$4:$AA$33,MATCH('Safety Instruction'!$F12,Data!$Q$4:$Q$33,0),MATCH('Safety Instruction'!$D$4,Data!$P$4:$AA$4,0)) -> A | I12: ='Safety cal.'!Z18 -> A | J12: A | K12: Keep the current condition. | L12: - | M12: Continue to take countermeasures timely. | N12: X | S12: 類災対策 プロセスKPI | T12: Recurrence Prevention Process KPI
C13: Risk Management | D13: Symptom Management for QM defect Management and analysis of information which is explored, issued | E13: Risk Management | F13: RA Progress | G13: Risk | H13: =INDEX(Data!$P$4:$AA$33,MATCH('Safety Instruction'!$F13,Data!$Q$4:$Q$33,0),MATCH('Safety Instruction'!$D$4,Data!$P$4:$AA$4,0)) -> B+ | I13: ='Safety cal.'!Z19 -> A | J13: A | K13: Keep the current condition. | L13: - | M13: Proceed RA as planned. | N13: X | S13: RA評価推進 | T13: RA Progress
F14: Equipment RA | G14: Risk | H14: =INDEX(Data!$P$4:$AA$33,MATCH('Safety Instruction'!$F14,Data!$Q$4:$Q$33,0),MATCH('Safety Instruction'!$D$4,Data!$P$4:$AA$4,0)) -> C | I14: ='Safety cal.'!Z20 -> A | J14: B+ | K14: Equipment RA has been conducted well but there are still residual risks should be countered/managed. | L14: Please consider to accelarate equipment RA activity. | M14: Consider to speed up equipment RA activity to reduce their risks as soon as possible. | O14: X | S14: 設備RA プロセスKPI | T14: Equipment RA
F15: Task RA | G15: Risk | H15: =INDEX(Data!$P$4:$AA$33,MATCH('Safety Instruction'!$F15,Data!$Q$4:$Q$33,0),MATCH('Safety Instruction'!$D$4,Data!$P$4:$AA$4,0)) -> C | I15: ='Safety cal.'!Z21 -> A | J15: B+ | K15: Task RA has been conducted well but there are still residual risks should be countered/managed. | L15: Please consider to accelarate task RA activity. | M15: Consider to speed up task RA activity to reduce their risks as soon as possible. | O15: X | S15: 作業RA プロセスKPI | T15: Task RA
F16: LOTO | G16: Compliance | H16: =INDEX(Data!$P$4:$AA$33,MATCH('Safety Instruction'!$F16,Data!$Q$4:$Q$33,0),MATCH('Safety Instruction'!$D$4,Data!$P$4:$AA$4,0)) -> B- | I16: ='Safety cal.'!Z22 -> A | J16: B | K16: LOTO training has been conducted only for the operators who conduct LOTO. | L16: Conduct basic LOTO training to ALL teammates. | M16: Make plan of LOTO training, and implement them as planned. | O16: X | S16: LOTO 運用徹底 | T16: LOTO
F17: Training | G17: Compliance | H17: =INDEX(Data!$P$4:$AA$33,MATCH('Safety Instruction'!$F17,Data!$Q$4:$Q$33,0),MATCH('Safety Instruction'!$D$4,Data!$P$4:$AA$4,0)) -> A | I17: ='Safety cal.'!Z23 -> A | J17: A | K17: Keep the current condition. | L17: - | M17: Continue to train and confirm teammates' skill/knowledge as your standard. | N17: X | S17: TYM/TS
C18: Business Strategy Adjustment | D18: Fundamental enhancement by Cpk and COPQ analysis QM management assurance across value chain | E18: Management System | F18: Policy/ Purpose/ Target | G18: Governance | H18: =INDEX(Data!$P$4:$AA$33,MATCH('Safety Instruction'!$F18,Data!$Q$4:$Q$33,0),MATCH('Safety Instruction'!$D$4,Data!$P$4:$AA$4,0)) -> B+ | I18: ='Safety cal.'!Z24 -> A | J18: A | K18: Policy and action pland have been issued and managers understand it. | L18: Please consider to compare the policy when you consider to update it to make it more effective. | M18: Consider to have a step to compare the policy when you consider to update. | O18: X | S18: 教育訓練 | T18: Training
F19: Implementation Plan | G19: Governance | H19: =INDEX(Data!$P$4:$AA$33,MATCH('Safety Instruction'!$F19,Data!$Q$4:$Q$33,0),MATCH('Safety Instruction'!$D$4,Data!$P$4:$AA$4,0)) -> B+ | I19: ='Safety cal.'!Z25 -> A | J19: B+ | K19: Some manager could not clearly stated the resut of last year, and what is updated/improved point(s) in the action plan. | L19: From previous result, please review the IIP's progress (and good/bad point) and consider to update it to go more forward. | M19: Consider to have a step to review the result of IIP, and update BMT's safety activity based on the review. | O19: X | S19: 方針・目的・目標 | T19: Policy/ Purpose/ Target
F20: Audit | G20: Governance | H20: =INDEX(Data!$P$4:$AA$33,MATCH('Safety Instruction'!$F20,Data!$Q$4:$Q$33,0),MATCH('Safety Instruction'!$D$4,Data!$P$4:$AA$4,0)) -> A | I20: ='Safety cal.'!Z26 -> A | J20: A | K20: Keep the current condition. | L20: - | M20: Continue to have internal audit and correspond opportunity for improvement from ISO45001 point of view. | N20: X | S20: 実施計画 | T20: Implementation Plan
C21: Independency and Continuity | D21: Awareness and knowledge for QM | E21: Independent implementation of BSFA | F21: BSFA Training | G21: Compliance | H21: =INDEX(Data!$P$4:$AA$33,MATCH('Safety Instruction'!$F21,Data!$Q$4:$Q$33,0),MATCH('Safety Instruction'!$D$4,Data!$P$4:$AA$4,0)) -> - | I21: ='Safety cal.'!Z27 -> A | J21: B | K21: Some operator stated that BSFA training is not annually. (few times only) | L21: Make sure BSFA training requirement (once a year) and standardize if needed. | M21: Standardize and plan BSFA training at least once a year. | O21: X | S21: 監査 | T21: Audit
F22: 3S | G22: Risk | H22: =INDEX(Data!$P$4:$AA$33,MATCH('Safety Instruction'!$F22,Data!$Q$4:$Q$33,0),MATCH('Safety Instruction'!$D$4,Data!$P$4:$AA$4,0)) -> B+ | I22: ='Safety cal.'!Z28 -> A | J22: B+ | K22: Workplace 3S is good condition, and almost of area's 3S level 4. | L22: Keep 3S condition based on 3S guideline. | M22: For more improvement, communication with the other site could be helpful so please consider to have this kind of opportunity. | O22: X | S22: BS共通安全 規定項目 教育 | T22: BSFA Training
F23: KYT/ Practical KYT | G23: Compliance | H23: =INDEX(Data!$P$4:$AA$33,MATCH('Safety Instruction'!$F23,Data!$Q$4:$Q$33,0),MATCH('Safety Instruction'!$D$4,Data!$P$4:$AA$4,0)) -> A | I23: ='Safety cal.'!Z29 -> A | J23: A | K23: Keep the current condition. | L23: - | M23: Continue KYT activity based on IMD standard. | N23: X | S23: 3S | T23: 3S
F24: Autonomously KY | G24: Risk | H24: =INDEX(Data!$P$4:$AA$33,MATCH('Safety Instruction'!$F24,Data!$Q$4:$Q$33,0),MATCH('Safety Instruction'!$D$4,Data!$P$4:$AA$4,0)) -> B | I24: ='Safety cal.'!Z30 -> A | J24: A | K24: Autonomous KY activity is well going and updated compare with last year. | L24: Please consider to visualize KY point in map to make it easy to see which place has high risk. | M24: Please consider to use the maps to visualize everyone's KY point, and KAIZEN cycle to improve it. | N24: X | S24: KYT 実践型KYT | T24: KYT/ Practical KYT
F25: RA | G25: Risk | H25: =INDEX(Data!$P$4:$AA$33,MATCH('Safety Instruction'!$F25,Data!$Q$4:$Q$33,0),MATCH('Safety Instruction'!$D$4,Data!$P$4:$AA$4,0)) -> B | I25: ='Safety cal.'!Z31 -> A | J25: B | K25: RA process itself was well maintained by leadership of EHS team. | L25: Please consider to train teammates in the other process to make them enable to conduct RA process. | M25: Consider to have RA training to the production department. | O25: X | S25: 自律的KY ・改善 | T25: Autonomously KY
F26: Safety Rule | G26: Compliance | H26: =INDEX(Data!$P$4:$AA$33,MATCH('Safety Instruction'!$F26,Data!$Q$4:$Q$33,0),MATCH('Safety Instruction'!$D$4,Data!$P$4:$AA$4,0)) -> B+ | I26: ='Safety cal.'!Z32 -> A | J26: B+ | K26: Some operator could not state cleary about their workplace safety rules. *Not only BS commmon rules, but SOP including safety point(s) | L26: Please make sure of all teammates' understandings of their safety rule. | M26: Consider to have remind/periodical training process to make sure all teammates understanding of safety rule. | O26: X | S26: RA | T26: RA
F27: 4M Change Management | G27: Risk | H27: =INDEX(Data!$P$4:$AA$33,MATCH('Safety Instruction'!$F27,Data!$Q$4:$Q$33,0),MATCH('Safety Instruction'!$D$4,Data!$P$4:$AA$4,0)) -> - | I27: ='Safety cal.'!Z33 -> A | J27: A | K27: Keep the current condition. | L27: - | M27: Continue to manage 4M change. | N27: X | S27: 安全ルール | T27: Safety Rule
F28: Management System: P | G28: Governance | H28: =INDEX(Data!$P$4:$AA$33,MATCH('Safety Instruction'!$F28,Data!$Q$4:$Q$33,0),MATCH('Safety Instruction'!$D$4,Data!$P$4:$AA$4,0)) -> B+ | I28: ='Safety cal.'!Z34 -> A | J28: A | K28: Safety IIP has been issued but some manager could not state its backgound. (how/what is updated/improved from last year) | L28: Please make sure of all manager's understanding of safety IIP. | M28: Consider to make all manager understand not only safety action plan itself but its background. | N28: X | S28: 4M変更管理 | T28: 4M Change Management
F29: Management System: D | G29: Governance | H29: =INDEX(Data!$P$4:$AA$33,MATCH('Safety Instruction'!$F29,Data!$Q$4:$Q$33,0),MATCH('Safety Instruction'!$D$4,Data!$P$4:$AA$4,0)) -> B+ | I29: ='Safety cal.'!Z35 -> A | J29: A | K29: Safety IIP covers actions for direct employees but not covered the others*. (could not validated) *contructors, hourly employees and so on. | L29: Consider to add aciton(s) for indirect employees. (contructors etc.) | M29: Consider to update safety action plan with including actions for indirect employees. | N29: X | S29: 【モデル工場】 P | T29: Management System: P
F30: Management System: C | G30: Governance | H30: =INDEX(Data!$P$4:$AA$33,MATCH('Safety Instruction'!$F30,Data!$Q$4:$Q$33,0),MATCH('Safety Instruction'!$D$4,Data!$P$4:$AA$4,0)) -> B | I30: ='Safety cal.'!Z36 -> A | J30: B+ | K30: Safety IIP has been followed up but could not see the evidence of GENBA validation. | L30: For items in safety IIP, please consider to confirm its progress in GENBA situation. | M30: Consider to validate safety acition items in GENBA situation. | O30: X | S30: 【モデル工場】 D | T30: Management System: D
F31: Management System: A | G31: Governance | H31: =INDEX(Data!$P$4:$AA$33,MATCH('Safety Instruction'!$F31,Data!$Q$4:$Q$33,0),MATCH('Safety Instruction'!$D$4,Data!$P$4:$AA$4,0)) -> B | I31: ='Safety cal.'!Z37 -> A | J31: B | K31: Safety IIP has been updated, but some manager could not state why IIP has been updated or not. (just thinking needs by oneself without reviewing the result of last year) | L31: Make sure all manager's understanding of updated or shoud be updated part(s) in IIP. | M31: Consider to have a meeting or something to validate all manager's understanding of IIP - last year's review, issues, good point, and what should be updated or not. | O31: X | S31: 【モデル工場】 C | T31: Management System: C
C32: Integration/ Incorporation | D32: Resource and Organization for QM | E32: Plant Management | F32: Safety Organization | G32: Governance | H32: =INDEX(Data!$P$4:$AA$33,MATCH('Safety Instruction'!$F32,Data!$Q$4:$Q$33,0),MATCH('Safety Instruction'!$D$4,Data!$P$4:$AA$4,0)) -> A | I32: ='Safety cal.'!Z38 -> A | J32: A | K32: Keep the current condition. | L32: - | M32: Continue to keep EHS organization. | N32: X | S32: 【モデル工場】 A | T32: Management System: A
F33: SE | G33: Governance | H33: =INDEX(Data!$P$4:$AA$33,MATCH('Safety Instruction'!$F33,Data!$Q$4:$Q$33,0),MATCH('Safety Instruction'!$D$4,Data!$P$4:$AA$4,0)) -> C | I33: ='Safety cal.'!Z39 -> A | J33: ー | K33: Some BMT teammates have taken SE training given by BSJP, but no one assigned as exclusive duty. | L33: Cosinder to keep SE skill as BMT (plant) unit. | M33: Cosinder to plan for taking SE training (incuding level-up training) tokeep SE skill as BMT (plant) unit. | S33: 安全組織 | T33: Safety Organization
F34: Budget | G34: Governance | H34: =INDEX(Data!$P$4:$AA$33,MATCH('Safety Instruction'!$F34,Data!$Q$4:$Q$33,0),MATCH('Safety Instruction'!$D$4,Data!$P$4:$AA$4,0)) -> B+ | I34: ='Safety cal.'!Z40 -> A | J34: B+ | K34: Budget for safety was prepared and well managed, but some manager stated safety budget was not enough. | L34: Make sure all manager's understanding for management of budget - prioriy, validity and so on. | M34: Make sure of all teammates understanding of budget management. | O34: X | S34: 安全担当
S35: SE | T35: SE
S36: 安全専任 職長
S37: 予算確保 | T37: Budget

Sheet DP Report
X1: Issue:
W2: 45972
B3: D.P. Solidification Report (This is trial result, the score will not be recorded as BSAPIC's solidification)
B4: Site | G4: Date
B6: QM foundation (management system) 3 axes
C8: Items | J8: 2025 | L8: 2028 | O8: 3 Axes Chart
J9: Score | K9: Level | L9: Score | M9: Level
I10: Total Ave | J10: =Cal!D44 -> 5 | K10: =IF(J10<2,"C",IF(J10<3,"B-",IF(J10<4,"B",IF(J10<5,"B+",IF(J10=5,"A",""))))) -> A | L10: =Cal!E44 -> 0
D11: 3 Axes Evaluation | E11: Risk Detection and Reduction/Continuous Improvement | H11: Ave | J11: =Cal!D43 -> 5 | K11: =IF(J11=5,"A",IF(J11>=4,"B+",IF(J11>=3,"B",IF(J11>=2,"B-",IF(J11>=1, "C","-"))))) -> A | L11: =Cal!E43 -> 0 | M11: =IF(L11=5,"A",IF(L11>=4,"B+",IF(L11>=3,"B",IF(L11>=2,"B-",IF(L11>=1, "C","-"))))) -> -
H12: Distribution | I12: B+ or more | J12: =Cal!E56 -> 8 | L12: =Cal!F56 -> 0
I13: B | J13: =Cal!E57 -> 0 | L13: =Cal!F57 -> 0
I14: B- | J14: =Cal!E58 -> 0 | L14: =Cal!F58 -> 0
I15: C | J15: =Cal!E59 -> 0 | L15: =Cal!F59 -> 0
E16: Safety Rule Compliance/Safety Awareness Cultivation | H16: Ave | J16: =Cal!D41 -> 5 | K16: =IF(J16=5,"A",IF(J16>=4,"B+",IF(J16>=3,"B",IF(J16>=2,"B-",IF(J16>=1, "C","-"))))) -> A | L16: =Cal!E41 -> 0 | M16: =IF(L16=5,"A",IF(L16>=4,"B+",IF(L16>=3,"B",IF(L16>=2,"B-",IF(L16>=1, "C","-"))))) -> -
H17: Distribution | I17: B+ or more | J17: =Cal!E62 -> 16 | L17: =Cal!F62 -> 0
I18: B | J18: =Cal!E63 -> 0 | L18: =Cal!F63 -> 0 | O18: Distribution
I19: B- | J19: =Cal!E64 -> 0 | L19: =Cal!F64 -> 0 | O19: Risk | Q19: 2028
I20: C | J20: =Cal!E65 -> 0 | L20: =Cal!F65 -> 0 | Q20: 2025
E21: Strengthening of Governance and Systems to Make Quality Management More Effective | H21: Ave | J21: =Cal!D42 -> 5 | K21: =IF(J21=5,"A",IF(J21>=4,"B+",IF(J21>=3,"B",IF(J21>=2,"B-",IF(J21>=1, "C","-"))))) -> A | L21: =Cal!E42 -> 0 | M21: =IF(L21=5,"A",IF(L21>=4,"B+",IF(L21>=3,"B",IF(L21>=2,"B-",IF(L21>=1, "C","-"))))) -> - | O21: Compliance | Q21: 2028
H22: Distribution | I22: B+ or more | J22: =Cal!E68 -> 7 | L22: =Cal!F68 -> 0 | Q22: 2025
I23: B | J23: =Cal!E69 -> 0 | L23: =Cal!F69 -> 0 | O23: Governance | Q23: 2028
I24: B- | J24: =Cal!E70 -> 0 | L24: =Cal!F70 -> 0 | Q24: 2025
I25: C | J25: =Cal!E71 -> 0 | L25: =Cal!F71 -> 0
B27: QM foundation (management system) 5 axes
C29: Solidification 5 items | F29: 2025 | J29: 2028 | O29: Ave Score | T29: Min Score
F30: Ave | H30: Min | J30: Ave | L30: Min
F31: Score | G31: Level | H31: Score | I31: Level | J31: Score | K31: Level | L31: Score | M31: Level
C32: Issue solving | F32: =Cal!E48 -> 5 | G32: =IF(F32<2,"C",IF(F32<3,"B-",IF(F32<4,"B",IF(F32<5,"B+",IF(F32=5,"A",""))))) -> A | H32: =Cal!D48 -> 5 | I32: =IF(H32<2,"C",IF(H32<3,"B-",IF(H32<4,"B",IF(H32<5,"B+",IF(H32=5,"A",""))))) -> A
C33: Risk Management | F33: =Cal!E49 -> 5 | G33: =IF(F33<2,"C",IF(F33<3,"B-",IF(F33<4,"B",IF(F33<5,"B+",IF(F33=5,"A",""))))) -> A | H33: =Cal!D49 -> 5 | I33: =IF(H33<2,"C",IF(H33<3,"B-",IF(H33<4,"B",IF(H33<5,"B+",IF(H33=5,"A",""))))) -> A
C34: Business Strategy Adjustment | F34: =Cal!E50 -> 5 | G34: =IF(F34<2,"C",IF(F34<3,"B-",IF(F34<4,"B",IF(F34<5,"B+",IF(F34=5,"A",""))))) -> A | H34: =Cal!D50 -> 5 | I34: =IF(H34<2,"C",IF(H34<3,"B-",IF(H34<4,"B",IF(H34<5,"B+",IF(H34=5,"A",""))))) -> A
C35: Independency and Continuity | F35: =Cal!E51 -> 5 | G35: =IF(F35<2,"C",IF(F35<3,"B-",IF(F35<4,"B",IF(F35<5,"B+",IF(F35=5,"A",""))))) -> A | H35: =Cal!D51 -> 5 | I35: =IF(H35<2,"C",IF(H35<3,"B-",IF(H35<4,"B",IF(H35<5,"B+",IF(H35=5,"A",""))))) -> A
C36: Integration/ Incorporation | F36: =Cal!E52 -> 5 | G36: =IF(F36<2,"C",IF(F36<3,"B-",IF(F36<4,"B",IF(F36<5,"B+",IF(F36=5,"A",""))))) -> A | H36: =Cal!D52 -> 5 | I36: =IF(H36<2,"C",IF(H36<3,"B-",IF(H36<4,"B",IF(H36<5,"B+",IF(H36=5,"A",""))))) -> A
C38: Total Ave | F38: =AVERAGE(F32:F36) -> 5 | G38: =IF(F38<2,"C",IF(F38<3,"B-",IF(F38<4,"B",IF(F38<5,"B+",IF(F38=5,"A",""))))) -> A | H38: =AVERAGE(H32:H36) -> 5 | I38: =IF(H38<2,"C",IF(H38<3,"B-",IF(H38<4,"B",IF(H38<5,"B+",IF(H38=5,"A",""))))) -> A
B40: Comment
C42: <Comments from 3 axes points of view> <Risk> <Compliance> <Governance>

Sheet DP Cover
W2: BSAPIC CQO
B3: D.P. Solidification Report
B4: Site | D4: BSIDp
B6: QM foundation (management system) 3 axes
C8: Items | J8: 2025 | L8: 2028 | O8: 3 Axes Chart
J9: Score | K9: Level | L9: Score | M9: Level
I10: Total Ave | J10: =Cal!D44 -> 5 | K10: =IF(J10<2,"C",IF(J10<3,"B-",IF(J10<4,"B",IF(J10<5,"B+",IF(J10=5,"A",""))))) -> A | L10: =Cal!E44 -> 0
D11: 3 Axes Evaluation | E11: Risk Detection and Reduction/Continuous Improvement | H11: Ave | J11: =Cal!D43 -> 5 | K11: =IF(J11=5,"A",IF(J11>=4,"B+",IF(J11>=3,"B",IF(J11>=2,"B-",IF(J11>=1, "C","-"))))) -> A | L11: =Cal!E43 -> 0 | M11: =IF(L11=5,"A",IF(L11>=4,"B+",IF(L11>=3,"B",IF(L11>=2,"B-",IF(L11>=1, "C","-"))))) -> -
H12: Distribution | I12: B+ or more | J12: =Cal!E56 -> 8 | L12: =Cal!F56 -> 0
I13: B | J13: =Cal!E57 -> 0 | L13: =Cal!F57 -> 0
I14: B- | J14: =Cal!E58 -> 0 | L14: =Cal!F58 -> 0
I15: C | J15: =Cal!E59 -> 0 | L15: =Cal!F59 -> 0
E16: Safety Rule Compliance/Safety Awareness Cultivation | H16: Ave | J16: =Cal!D41 -> 5 | K16: =IF(J16=5,"A",IF(J16>=4,"B+",IF(J16>=3,"B",IF(J16>=2,"B-",IF(J16>=1, "C","-"))))) -> A | L16: =Cal!E41 -> 0 | M16: =IF(L16=5,"A",IF(L16>=4,"B+",IF(L16>=3,"B",IF(L16>=2,"B-",IF(L16>=1, "C","-"))))) -> -
H17: Distribution | I17: B+ or more | J17: =Cal!E62 -> 16 | L17: =Cal!F62 -> 0
I18: B | J18: =Cal!E63 -> 0 | L18: =Cal!F63 -> 0 | O18: Distribution
I19: B- | J19: =Cal!E64 -> 0 | L19: =Cal!F64 -> 0 | O19: Risk | Q19: 2028
I20: C | J20: =Cal!E65 -> 0 | L20: =Cal!F65 -> 0 | Q20: 2025
E21: Strengthening of Governance and Systems to Make Quality Management More Effective | H21: Ave | J21: =Cal!D42 -> 5 | K21: =IF(J21=5,"A",IF(J21>=4,"B+",IF(J21>=3,"B",IF(J21>=2,"B-",IF(J21>=1, "C","-"))))) -> A | L21: =Cal!E42 -> 0 | M21: =IF(L21=5,"A",IF(L21>=4,"B+",IF(L21>=3,"B",IF(L21>=2,"B-",IF(L21>=1, "C","-"))))) -> - | O21: Compliance | Q21: 2028
H22: Distribution | I22: B+ or more | J22: =Cal!E68 -> 7 | L22: =Cal!F68 -> 0 | Q22: 2025
I23: B | J23: =Cal!E69 -> 0 | L23: =Cal!F69 -> 0 | O23: Governance | Q23: 2028
I24: B- | J24: =Cal!E70 -> 0 | L24: =Cal!F70 -> 0 | Q24: 2025
I25: C | J25: =Cal!E71 -> 0 | L25: =Cal!F71 -> 0
B27: QM foundation (management system) 5 axes
C29: Solidification 5 items | F29: 2025 | J29: 2028 | O29: Ave Score | T29: Min Score
F30: Ave | H30: Min | J30: Ave | L30: Min
F31: Score | G31: Level | H31: Score | I31: Level | J31: Score | K31: Level | L31: Score | M31: Level
C32: Issue solving | F32: =Cal!E48 -> 5 | G32: =IF(F32<2,"C",IF(F32<3,"B-",IF(F32<4,"B",IF(F32<5,"B+",IF(F32=5,"A",""))))) -> A | H32: =Cal!D48 -> 5 | I32: =IF(H32<2,"C",IF(H32<3,"B-",IF(H32<4,"B",IF(H32<5,"B+",IF(H32=5,"A",""))))) -> A
C33: Risk Management | F33: =Cal!E49 -> 5 | G33: =IF(F33<2,"C",IF(F33<3,"B-",IF(F33<4,"B",IF(F33<5,"B+",IF(F33=5,"A",""))))) -> A | H33: =Cal!D49 -> 5 | I33: =IF(H33<2,"C",IF(H33<3,"B-",IF(H33<4,"B",IF(H33<5,"B+",IF(H33=5,"A",""))))) -> A
C34: Business Strategy Adjustment | F34: =Cal!E50 -> 5 | G34: =IF(F34<2,"C",IF(F34<3,"B-",IF(F34<4,"B",IF(F34<5,"B+",IF(F34=5,"A",""))))) -> A | H34: =Cal!D50 -> 5 | I34: =IF(H34<2,"C",IF(H34<3,"B-",IF(H34<4,"B",IF(H34<5,"B+",IF(H34=5,"A",""))))) -> A
C35: Independency and Continuity | F35: =Cal!E51 -> 5 | G35: =IF(F35<2,"C",IF(F35<3,"B-",IF(F35<4,"B",IF(F35<5,"B+",IF(F35=5,"A",""))))) -> A | H35: =Cal!D51 -> 5 | I35: =IF(H35<2,"C",IF(H35<3,"B-",IF(H35<4,"B",IF(H35<5,"B+",IF(H35=5,"A",""))))) -> A
C36: Integration/ Incorporation | F36: =Cal!E52 -> 5 | G36: =IF(F36<2,"C",IF(F36<3,"B-",IF(F36<4,"B",IF(F36<5,"B+",IF(F36=5,"A",""))))) -> A | H36: =Cal!D52 -> 5 | I36: =IF(H36<2,"C",IF(H36<3,"B-",IF(H36<4,"B",IF(H36<5,"B+",IF(H36=5,"A",""))))) -> A
C38: Total Ave | F38: =AVERAGE(F32:F36) -> 5 | G38: =IF(F38<2,"C",IF(F38<3,"B-",IF(F38<4,"B",IF(F38<5,"B+",IF(F38=5,"A",""))))) -> A | H38: =AVERAGE(H32:H36) -> 5 | I38: =IF(H38<2,"C",IF(H38<3,"B-",IF(H38<4,"B",IF(H38<5,"B+",IF(H38=5,"A",""))))) -> A
B40: Comment
C42: BSIDp has achieved a B level across all three axes, exceeding BSAPIC expectations with no axis falling below the B rating. To further elevate performance to the B+ level, APICTC recommends strengthening system governance and compliance execution through enhanced hot work permit control, improved daily inspection effectiveness, and reinforced competency of responsible personnel. Additionally, proper grounding and bonding conditions must be ensured for gasoline cement equipment through systematic inspection and personnel training. Meanwhile, the inspection program for fire barriers such as firewall and shutter doors should be revised with complete documentation and record traceability. In governance, BSIDp should establish a clear reporting timeline with accountability to ensure that both preliminary and final fire incident reports are submitted to BSAPIC on time with complete root-cause analysis, as well as improve DP inspection resources and clarify the roles and responsibilities to secure consistent inspection quality. These improvements will support operational compliance, enhance DP capability, and strengthen overall governance maturity toward achieving a B+ level.

Sheet DP overall
C3: Solidification Assessment - Disaster Prevention [DP] | N3: DP Manager
N4: Manager
N5: Supervisor | O5: BSAPIC re.2
N6: Operator | O6: 46144
B7: Judgement Criteria
C8: ・各項目ごとの最低点を取る Pick the lowest score from each items
C9: ・各項目は、直近1年間の取り組み状況から判断する Time scope is one year from evaluating
C10: ・技能員を対象とした設問は、原則として各係・工程から1名以上選出して評価する。 Questions for operators, need to have interview at least one person from production department.
C11: ・計画対比の進捗状況について評価する設問は、評価実施時点での計画対比実施状況を見て判断する In case of question that is asking its progress, that should be evaluated at the day of evaluation.
C13: Solidification 5 items | D13: DP item No. | E13: Secondary Category | F13: Current Issues Disposition | H13: Potential Risk Prevention | L13: Proactive Prevention | N13: Independent Quality Management | Q13: 安全/ 防災 | R13: 判定記入 | W13: スコア | X13: 評価 | Y13: 3軸分類
F14: 1 | G14: Judge | H14: 2 | I14: Judge | J14: 3 | K14: Judge | L14: 4 | M14: Judge | N14: 5 | O14: Judge | R14: 1 | S14: 2 | T14: 3 | U14: 4 | V14: 5
F15: C | H15: B- | J15: B | L15: B+ | N15: A | R15: C | S15: B- | T15: B | U15: B+ | V15: A
C16: Issue solving | D16: 1 | E16: Information Sharing | F16: Leadership Involvement in Serious Incidents All teammates stated that, at a minimum, the safety manager and a site leadership representative (e.g., plant manager, department manager, or line manager) were involved in the root cause analysis process whenever a serious incident (e.g., fire) occurred. (Leadership: Operator: No.5) | G16: =OP!H4 -> 0 | H16: Informed of Recent Incidents All teammates can confirm that they have been informed of recent D.P.-related incidents (e.g., fire, near-miss) in their areas and that actions have been taken to address these incidents. If no D.P. incident has occurred since the start of their employment, confirmation will be made based on D.P. incidents that have previously occurred at the site. (Teammate Engagement: Operator: No.7) | I16: =OP!H5 -> 0 | J16: Understanding of Information Contribution All teammates stated that they are well informed and can explain how the communicated information contributes to strengthening fire prevention. (System: Operator: No.64) Information may include fire, smoke, near-miss, etc. If no D.P. incident has occurred since the start of their employment, confirmation will be based on D.P. incidents that have previously occurred at the site. | K16: =OP!H6 -> 0 | L16: Examples from Other Facilities Teammates are able to provide examples of fire incidents that occurred at other facilities and can explain how this information was obtained. (System: Operator: No.110) | M16: =OP!H7 -> 0 | N16: Cross-site and Cross-department Sharing D.P. risks and measures from other sites or departments have been shared during the safety meeting in your department. (Teammate Engagement: Operator: No.17) | O16: =OP!H8 -> 0 | Q16: 防災 | R16: =G16 -> 0 | S16: =I16 -> 0 | T16: =K16 -> 0 | U16: =M16 -> 0 | V16: =O16 -> 0 | W16: =IF(R16="No",1,IF(S16="No",1,IF(T16="No",2,IF(U16="No",3,IF(V16="No",4,5))))) -> 5 | X16: =IF(W16<2,"C",IF(W16<3,"B-",IF(W16<4,"B",IF(W16<5,"B+",IF(W16=5,"A",""))))) -> A | Y16: ガバナンス
D17: 2 | E17: Recurrence Prevention | F17: Implement prevent the recurrence of incidents There is evidence that actions have been implemented to prevent the recurrence of incidents, and SVs are able to explain these actions. (System: Safety Manager: No.30) *ask SVs | G17: =SV!H4 -> 0 | H17: OP know and participate In a sample of 3 teammates, at least 1 (more than 33%) stated that they participate in the actions required to prevent D.P. accidents and provide feedback if these actions are not appropriate or effective. If no D.P. incident has occurred since the start of their employment, in a sample of three teammates, at least one (more than 33%) commented on the need for improvement based on identified problems or defects related to D.P. (Teammate Engagement: Operator: No.6) | I17: =OP!H9 -> 0 | J17: SVs can explain the actions SVs can explain the actions required for recurrence prevention in the event of a D.P. accident. They are able to describe measures taken in terms of prevention, detection, and protection based on the analysis. In addition, SVs can explain how to prevent the recurrence of accidents that have occurred in their own processes. Genba improvement, all completed without delay (System: Safety Manager: No.86) *Ask SVs | K17: =SV!H5 -> 0 | L17: OP feedback All teammates stated that management has taken specific actions to address the hazards they reported, and that these actions have been communicated back to them. (D.P. point of view) (Organization: Operator: No.16) | M17: =OP!H10 -> 0 | N17: Recurrence Prevention action PDCA and feedback to SBU SVs can explain how such reviews are conducted and why the chosen method(s) are effective, using 4M change examples and other cases. They provide feedback to the SBU and assist in determining appropriate countermeasures. (Example: Sharing more effective safety measures than those initially proposed by GBS/SBU) This is subject to countermeasures derived from D.P. incidents, near misses, and defect information raised by operators.(System: Safety Manager: No.140) *Ask SVs Manager: No.140) | O17: =SV!H6 -> 0 | Q17: 防災 | R17: =G17 -> 0 | S17: =I17 -> 0 | T17: =K17 -> 0 | U17: =M17 -> 0 | V17: =O17 -> 0 | W17: =IF(R17="No",1,IF(S17="No",1,IF(T17="No",2,IF(U17="No",3,IF(V17="No",4,5))))) -> 5 | X17: =IF(W17<2,"C",IF(W17<3,"B-",IF(W17<4,"B",IF(W17<5,"B+",IF(W17=5,"A",""))))) -> A | Y17: リスク
D18: 3 | E18: Fire Reporting | F18: With SBU Support Issuing fire report with SBU's support. (DP Manager) | G18: ='DP MGR'!H4 -> 0 | H18: Issued but Delayed The fire report was issued by the plant; however, there was a delay beyond the due date specified in the guideline. (DP Manager) | I18: ='DP MGR'!H5 -> 0 | J18: Issued On Time with RCA & Countermeasures The fire report was issued by the plant within the due date standardized in the guideline. Furthermore, the root cause analysis and corresponding countermeasures were completed, and the related report was also issued within the due date specified in the guideline. (DP Manager) | K18: ='DP MGR'!H6 -> 0 | L18: On Time + Countermeasure Expansion & Reporting to SBU The fire report was issued by the plant within the due date standardized in the guideline. The root cause analysis and corresponding countermeasures were also completed, and the report was issued within the required timeframe. In addition, the countermeasures were expanded to similar machines and tasks. After the implementation of the countermeasures, a report was submitted to the SBU.(DP Manager) | M18: ='DP MGR'!H7 -> 0 | N18: Periodic Review of Countermeasures Past countermeasures have been periodically re-checked to confirm their implementation status, subject to D.P. incidents that have occurred in the past at the site or in the workplace. At a minimum, progress must be reviewed within 1 year. (Safety Manager) *Also ask SVs | O18: =SV!H7 -> 0 | Q18: 防災 | R18: =G18 -> 0 | S18: =I18 -> 0 | T18: =K18 -> 0 | U18: =M18 -> 0 | V18: =O18 -> 0 | W18: =IF(R18="No",1,IF(S18="No",1,IF(T18="No",2,IF(U18="No",3,IF(V18="No",4,5))))) -> 5 | X18: =IF(W18<2,"C",IF(W18<3,"B-",IF(W18<4,"B",IF(W18<5,"B+",IF(W18=5,"A",""))))) -> A | Y18: ガバナンス
D19: 4 | E19: Recurrence Prevention Process KPI | F19: No Plan There is no plan for countermeasures originating from outside of the plant. In this context, “countermeasures” refers to those issued under BSAPIC Request/ Notification. (DP Manager) | G19: ='DP MGR'!H8 -> 0 | H19: Plan but Delayed (No Corrective Action) There is a plan for countermeasures; however, the implementation is delayed, and no corrective plan for addressing the delay has been established. (DP Manager) | I19: ='DP MGR'!H9 -> 0 | J19: Plan in Progress There is a countermeasure plan that is currently in progress but not yet completed. Alternatively, if there is a delay, a corrective plan has been established and is being implemented. (DP Manager) | K19: ='DP MGR'!H10 -> 0 | L19: Do Ahead of Schedule There is a countermeasure plan in place, and progress is ahead of schedule; however, it has not yet been completed. (DP Manager) | M19: ='DP MGR'!H11 -> 0 | N19: All Countermeasures Completed All countermeasures have been completed. (DP Manager) | O19: ='DP MGR'!H12 -> 0 | Q19: 防災 | R19: =G19 -> 0 | S19: =I19 -> 0 | T19: =K19 -> 0 | U19: =M19 -> 0 | V19: =O19 -> 0 | W19: =IF(R19="No",1,IF(S19="No",1,IF(T19="No",2,IF(U19="No",3,IF(V19="No",4,5))))) -> 5 | X19: =IF(W19<2,"C",IF(W19<3,"B-",IF(W19<4,"B",IF(W19<5,"B+",IF(W19=5,"A",""))))) -> A | Y19: リスク
C20: Risk Management | D20: 5 | E20: Fire RA Progress | F20: Plan Established There is a plan for Fire RA. (DP Manager) | G20: ='DP MGR'!H13 -> 0 | H20: Plan Delayed (No Corrective Action) There is a plan for Fire RA; however, its implementation is delayed, and no corrective plan has been established to address the delay. (DP Manager) | I20: ='DP MGR'!H14 -> 0 | J20: Plan in Progress There is a plan for Fire RA, which is currently progressing according to the plan. Alternatively, if there is a delay, a corrective plan has been established and is ongoing. In some cases, all Fire RAs have already been completed. The contents of the assessment sheet should be confirmed. (DP Manager) | K20: ='DP MGR'!H15 -> 0 | L20: Results Shared – Risk III/IV The results of the Fire RA have been shared within the plant. Operators are informed of the risks and countermeasures for Gross Risk III/IV. If no Risk III/IV exists, they are informed accordingly. (DP Manager) *Ask SVs | M20: =SV!H8 -> 0 | N20: Results Shared & Understood – Risk I/II Awareness The results of the Fire RA have been shared within the plant, and all teammates have demonstrated understanding. Operators are informed of the risks and countermeasures for Gross Risk III/IV. If no Risk III/IV exists, operators are made aware of the high-risk areas in their plant or process categorized under Risk I/II. (Operators) | O20: =OP!H11 -> 0 | Q20: 防災 | R20: =G20 -> 0 | S20: =I20 -> 0 | T20: =K20 -> 0 | U20: =M20 -> 0 | V20: =O20 -> 0 | W20: =IF(R20="No",1,IF(S20="No",1,IF(T20="No",2,IF(U20="No",3,IF(V20="No",4,5))))) -> 5 | X20: =IF(W20<2,"C",IF(W20<3,"B-",IF(W20<4,"B",IF(W20<5,"B+",IF(W20=5,"A",""))))) -> A | Y20: リスク
D21: 6 | E21: Fire RA | F21: No Plan There is no countermeasure plan in place for the risks detected by the Fire RA. (D.P. Manager) | G21: ='DP MGR'!H16 -> 0 | H21: Delay without Corrective Plan There is a plan for countermeasures for the fire risk; however, the implementation is delayed, and no corrective plan has been established. (DP Manager) | I21: ='DP MGR'!H17 -> 0 | J21: Ongoing / Delay with Corrective Plan There is a plan for countermeasures for the fire risk, and it is progressing according to schedule. Alternatively, if there is a delay, a corrective plan has been established and is currently being implemented. (DP Manager) | K21: ='DP MGR'!H18 -> 0 | L21: Ahead of Schedule There is a plan for countermeasures for the fire risk, and progress is ahead of schedule, though completion has not yet been achieved. (DP Manager) | M21: ='DP MGR'!H19 -> 0 | N21: Completed / Not Applicable All countermeasures for Fire Risk III and IV have been completed, or no Fire Risk III and IV have been identified. (DP Manager) | O21: ='DP MGR'!H20 -> 0 | Q21: 防災 | R21: =G21 -> 0 | S21: =I21 -> 0 | T21: =K21 -> 0 | U21: =M21 -> 0 | V21: =O21 -> 0 | W21: =IF(R21="No",1,IF(S21="No",1,IF(T21="No",2,IF(U21="No",3,IF(V21="No",4,5))))) -> 5 | X21: =IF(W21<2,"C",IF(W21<3,"B-",IF(W21<4,"B",IF(W21<5,"B+",IF(W21=5,"A",""))))) -> A | Y21: リスク
D22: 7 | E22: DP Inspection | F22: Planned Inspection items (based on legal & BS requirements) are determined at the plant, and there is a plan for inspection. (DP Manager) | G22: ='DP MGR'!H21 -> 0 | H22: Delayed – No Corrective Plan Inspection items (based on legal & BS requirements) are determined at the plant, and there is a plan for inspection; however, the plan is delayed, and no corrective plan has been established. (DP Manager) | I22: ='DP MGR'!H22 -> 0 | J22: Ongoing / Delayed with Corrective Plan Inspection items (based on legal & BS requirements) are determined at the site, and there is a plan for inspection. The plan is ongoing, with evidence that inspections have been conducted as scheduled. Alternatively, if there is a delay, a corrective plan has been established and is currently in progress. (DP Manager) | K22: ='DP MGR'!H23 -> 0 | L22: NG Shared Inspection NG items have been shared within the plant through meetings and other communication channels. (DP Manager) | M22: ='DP MGR'!H24 -> 0 | N22: Continuous Improvement Inspection items (including standards and procedures) have, in some cases, been reviewed and updated based on inspection results. (DP Manager) | O22: ='DP MGR'!H25 -> 0 | Q22: 防災 | R22: =G22 -> 0 | S22: =I22 -> 0 | T22: =K22 -> 0 | U22: =M22 -> 0 | V22: =O22 -> 0 | W22: =IF(R22="No",1,IF(S22="No",1,IF(T22="No",2,IF(U22="No",3,IF(V22="No",4,5))))) -> 5 | X22: =IF(W22<2,"C",IF(W22<3,"B-",IF(W22<4,"B",IF(W22<5,"B+",IF(W22=5,"A",""))))) -> A | Y22: リスク
D23: 8 | E23: Electrical Wiring Inspection | F23: Not Conducted / No Plan Inspection to identify defective wiring has not been conducted at the seven visual checkpoints, or there is no plan in place to conduct it. (Including items such as outlets, plugs, overcapacity, tangled cords, electric drums) (DP manager) | G23: ='DP MGR'!H26 -> 0 | H23: Conducted but Delayed Inspection has been conducted and there is a plan in place; however, implementation is delayed at the plant. Defects identified have been immediately corrected. At least one inspection point in GENBA should be validated. (DP manager) | I23: ='DP MGR'!H27 -> 0 | J23: Ongoing / Delayed with Corrective Plan There is a plan for countermeasures based on the defect wiring inspection, and it is progressing according to the plan. Alternatively, if there is a delay, a corrective plan has been established and is currently ongoing. Inspection records of electrical wiring must be confirmed. (DP Manager) | K23: ='DP MGR'!H28 -> 0 | L23: Ahead of Schedule There is a plan for countermeasures from the defect wiring inspection, and progress is ahead of schedule, though not yet completed. (DP manager) | M23: ='DP MGR'!H29 -> 0 | N23: Completed / No Defects Based on the results of the electrical wiring inspection, no defects requiring countermeasures were identified. (All countermeasures have been completed and no defects were detected.) At least one GENBA should be validated. | O23: ='DP MGR'!H30 -> 0 | Q23: 防災 | R23: =G23 -> 0 | S23: =I23 -> 0 | T23: =K23 -> 0 | U23: =M23 -> 0 | V23: =O23 -> 0 | W23: =IF(R23="No",1,IF(S23="No",1,IF(T23="No",2,IF(U23="No",3,IF(V23="No",4,5))))) -> 5 | X23: =IF(W23<2,"C",IF(W23<3,"B-",IF(W23<4,"B",IF(W23<5,"B+",IF(W23=5,"A",""))))) -> A | Y23: リスク
D24: 9 | E24: Abnormal noise/ vibration and temperature inspection (Motor, M/C moving part) | F24: Not Conducted / No Plan Noise/Vibration and Temperature inspection has not been conducted, or there is no plan in place to conduct it. At least one case in GENBA must be validated. (DP manager) | G24: ='DP MGR'!H31 -> 0 | H24: Conducted but Delayed Noise/Vibration and Temperature inspection has been conducted, and there is a plan in place; however, the plan is delayed. At least one case in GENBA must be validated. (DP manager) | I24: ='DP MGR'!H32 -> 0 | J24: Ongoing / Delayed with Corrective Plan / Completed There is a plan for countermeasures from the Noise/Vibration and Temperature inspection, and it is progressing according to the plan. Alternatively, if there is a delay, a corrective plan has been established and is currently ongoing. In some cases, all countermeasures have already been completed. (DP manager) | K24: ='DP MGR'!H33 -> 0 | L24: Ahead of Schedule There is a plan for countermeasures from the Noise/Vibration and Temperature inspection, and progress is ahead of schedule, though not yet completed. (DP Manager) | M24: ='DP MGR'!H34 -> 0 | N24: Completed / No Defects Based on the results of the Noise/Vibration and Temperature inspection, no defects requiring countermeasures were identified. (All countermeasures have been completed and no defects were detected.) At least one GENBA must be validated. (DP manager) | O24: ='DP MGR'!H35 -> 0 | Q24: 防災 | R24: =G24 -> 0 | S24: =I24 -> 0 | T24: =K24 -> 0 | U24: =M24 -> 0 | V24: =O24 -> 0 | W24: =IF(R24="No",1,IF(S24="No",1,IF(T24="No",2,IF(U24="No",3,IF(V24="No",4,5))))) -> 5 | X24: =IF(W24<2,"C",IF(W24<3,"B-",IF(W24<4,"B",IF(W24<5,"B+",IF(W24=5,"A",""))))) -> A | Y24: リスク
C25: Business Strategy Adjustment | D25: 10 | E25: Policy/ Purpose/ Target | F25: Not Issued D.P. policy/target has not been issued. (DP Manager) | G25: ='DP MGR'!H36 -> 0 | H25: Management have Information Management can show the site's OH&S objectives and goals. (System: Manager: No.66) *Ask Manager (not safety) | I25: =MGR!H4 -> 0 | J25: Management Understanding Management can describe and explain the site's OH&S objectives and goals. (System: Manager: No.66) *Ask Manager (not safety) | K25: =MGR!H5 -> 0 | L25: Planned Goals Aligned with Risks The plan contains goals to be achieved which are relevant to the incidents and risks identified by the SBU. (System: Manager: No.98) *Ask Manager (not safety) | M25: =MGR!H6 -> 0 | N25: Benchmarking There is evidence of OH&S benchmarking with other sites. (System: DP Manager: No.123) | O25: ='DP MGR'!H37 -> 0 | Q25: 防災 | R25: =G25 -> 0 | S25: =I25 -> 0 | T25: =K25 -> 0 | U25: =M25 -> 0 | V25: =O25 -> 0 | W25: =IF(R25="No",1,IF(S25="No",1,IF(T25="No",2,IF(U25="No",3,IF(V25="No",4,5))))) -> 5 | X25: =IF(W25<2,"C",IF(W25<3,"B-",IF(W25<4,"B",IF(W25<5,"B+",IF(W25=5,"A",""))))) -> A | Y25: ガバナンス
D26: 11 | E26: Implementation Plan | F26: Not Issued D.P. policy/target has not been issued. (DP Manager) | G26: ='DP MGR'!H38 -> 0 | H26: Basic KPI Tracking D.P. KPIs are tracked at the plant, department, and line level. Site leadership follows D.P. KPIs and provides directions to review the D.P. program if necessary.(Leadership: Plant Manager: No.6) *Ask Manager (not safety) | I26: =MGR!H7 -> 0 | J26: KPI Tracking with Corrective Actions D.P. KPIs are tracked consistently at multiple levels. If delays or issues are identified, corrective actions are planned and are in progress to ensure alignment with D.P. objectives.(Leadership: Plant Manager: No.6) *Ask Manager (not safety) | K26: =MGR!H8 -> 0 | L26: Advanced KPI Tracking (Leading & Lagging Indicators) D.P. KPIs are tracked positively at the plant, department, and line level, using both leading indicators (e.g., training completion rate, inspection results) and lagging indicators (e.g., number of fires). Site leadership monitors both types of indicators and provides directions to review and improve D.P. programs as necessary. (Leadership: Plant Manager: No.14) *Ask Manager (not safety) | M26: =MGR!H9 -> 0 | N26: Strategic Implementation & Continuous Review The Plant Manager can describe the D.P. strategy, its goals, and the approach to achieve them. The strategy is reviewed quarterly to assess progress and validity, with revisions or instructions implemented by the Plant Manager.(Leadership: Plant manager: No.21) *Ask Manager (not safety) | O26: =MGR!H10 -> 0 | Q26: 防災 | R26: =G26 -> 0 | S26: =I26 -> 0 | T26: =K26 -> 0 | U26: =M26 -> 0 | V26: =O26 -> 0 | W26: =IF(R26="No",1,IF(S26="No",1,IF(T26="No",2,IF(U26="No",3,IF(V26="No",4,5))))) -> 5 | X26: =IF(W26<2,"C",IF(W26<3,"B-",IF(W26<4,"B",IF(W26<5,"B+",IF(W26=5,"A",""))))) -> A | Y26: ガバナンス
D27: 12 | E27: Audit | F27: Not Conducted Internal audit has not been conducted. (DP Manager) | G27: ='DP MGR'!H39 -> 0 | H27: Conducted – Not Shared Internal audit has been conducted, but the results have not been shared within the plant. (DP Manager) | I27: ='DP MGR'!H40 -> 0 | J27: Conducted – Shared Internal audit has been conducted, and the results have been shared within the plant, including with managers. (DP Manager) | K27: ='DP MGR'!H41 -> 0 | L27: KAIZEN Plan & Implementation Based on the results of the internal audit, a KAIZEN plan has been developed and implemented according to the plan. (DP Manager) | M27: ='DP MGR'!H42 -> 0 | N27: No Non-Conformities in QM Audit There is no non-conformity (Major/Minor) identified in the QM audit. (DP Manager) | O27: ='DP MGR'!H43 -> 0 | Q27: 防災 | R27: =G27 -> 0 | S27: =I27 -> 0 | T27: =K27 -> 0 | U27: =M27 -> 0 | V27: =O27 -> 0 | W27: =IF(R27="No",1,IF(S27="No",1,IF(T27="No",2,IF(U27="No",3,IF(V27="No",4,5))))) -> 5 | X27: =IF(W27<2,"C",IF(W27<3,"B-",IF(W27<4,"B",IF(W27<5,"B+",IF(W27=5,"A",""))))) -> A | Y27: ガバナンス
C28: Independency and Continuity | D28: 13 | E28: 3S for flammable/ combustible material storage | F28: Documentation & Self-Check 3S documents are displayed in flammable/combustible material storage, chemical storage, and paint storage areas, with evidence of compliance. Self-checks have been implemented. (System: Operator: No.75) | G28: =OP!H12 -> 0 | H28: 3S Organization & Leadership There is an officially appointed 3S leader on site. There is evidence of 3S inspections and recommended actions for improvement. A 3S promotion organization for each process is clearly defined, with group leaders and members appointed. (System: Safety Manager: No.44+45) *Ask SVs | I28: =SV!H9 -> 0 | J28: Visual Standards & Workplace Cleanliness The 3S Visual Standard has been established. All inspected work areas (production and office) are maintained as per the standard: clean floors, no spillages, and no unnecessary objects not currently in use. (System: Operator: No.75) | K28: =OP!H13 -> 0 | L28: Continuous Improvement 3S activities aimed at raising the 3S level have been implemented. (Improvement of the 3S level can be confirmed, or the 3S level is above 4.) (System: Operator: No.105) | M28: =OP!H14 -> 0 | N28: Best Practice Integration & Benchmarking Best practices on 3S have been collected from other plants/industries and incorporated into site procedures, with evidence of benchmarking or comparison with other plants. (System: DP Manager: No.133) | O28: ='DP MGR'!H44 -> 0 | Q28: 防災 | R28: =G28 -> 0 | S28: =I28 -> 0 | T28: =K28 -> 0 | U28: =M28 -> 0 | V28: =O28 -> 0 | W28: =IF(R28="No",1,IF(S28="No",1,IF(T28="No",2,IF(U28="No",3,IF(V28="No",4,5))))) -> 5 | X28: =IF(W28<2,"C",IF(W28<3,"B-",IF(W28<4,"B",IF(W28<5,"B+",IF(W28=5,"A",""))))) -> A | Y28: リスク
D29: 14 | E29: DP KYT | F29: Not Implemented DP KYT has not been implemented. (Safety Manager) *Ask SVs | G29: =SV!H10 -> 0 | H29: Process Defined & Communicated There is evidence of a defined DP KYT process that has been communicated with all staff at least once in the past year. (System: Manager: No.26) *Ask SVs | I29: =SV!H11 -> 0 | J29: Leadership & Representation There is an officially appointed DP KYT leader and DP KYT representatives on site. (System: Manager: No.55) *Ask SVs | K29: =SV!H12 -> 0 | L29: Participation & Recordkeeping DP KYT records show that all teammates and temporary staff have submitted a DP KYT within the last 3 months. Records confirm that DP KYT is conducted periodically in accordance with SBU and/or site standards, and participation includes everyone on site.(System: Safety Manager: No.83+112) *Ask SVs | M29: =SV!H13 -> 0 | N29: Evaluation & Continuous Improvement DP KYT activities are evaluated annually, and opportunities for improvement are discussed with the Plant Manager. SVs can describe planned improvements for the next year’s activities based on comments and advice from the Plant Manager.(System: Safety Manager: No.113) *Ask SVs | O29: =SV!H14 -> 0 | Q29: 防災 | R29: =G29 -> 0 | S29: =I29 -> 0 | T29: =K29 -> 0 | U29: =M29 -> 0 | V29: =O29 -> 0 | W29: =IF(R29="No",1,IF(S29="No",1,IF(T29="No",2,IF(U29="No",3,IF(V29="No",4,5))))) -> 5 | X29: =IF(W29<2,"C",IF(W29<3,"B-",IF(W29<4,"B",IF(W29<5,"B+",IF(W29=5,"A",""))))) -> A | Y29: 順守推進
D30: 15 | E30: Common Fire Prevention Rule | F30: Not Trained All teammates have not received training on the Common Fire Prevention Rule. (SVs) | G30: =SV!H16 -> 0 | H30: Training Completed All teammates have received training on the Common Fire Prevention Rule at least once a year. (Operator) | I30: =OP!H15 -> 0 | J30: Understanding & Explanation All teammates understand the Common Fire Prevention Rule and can explain at least two key points from the SOP to prevent fire. (At least 2 items) (Operator) | K30: =OP!H16 -> 0 | L30: GENBA Patrol & Feedback Managers and SVs conduct GENBA patrols or equivalent activities to ensure teammates follow the Common Fire Prevention Rule, and they provide feedback to operators. Confirmation of records indicating that checks and feedback have been conducted. (SVs) | M30: =SV!H17 -> 0 | N30: KAIZEN Application All teammates can explain an example of a KAIZEN activity from a D.P. point of view, based on the Common Fire Prevention Rule. Examples include updating SOPs to follow the DP rule or implementing hardware upgrades aligned with the DP rule.(Operator) | O30: =OP!H17 -> 0 | Q30: 防災 | R30: =G30 -> 0 | S30: =I30 -> 0 | T30: =K30 -> 0 | U30: =M30 -> 0 | V30: =O30 -> 0 | W30: =IF(R30="No",1,IF(S30="No",1,IF(T30="No",2,IF(U30="No",3,IF(V30="No",4,5))))) -> 5 | X30: =IF(W30<2,"C",IF(W30<3,"B-",IF(W30<4,"B",IF(W30<5,"B+",IF(W30=5,"A",""))))) -> A | Y30: 順守推進 | Z30: confirm items related
D31: 16 | E31: Fire Fighting | F31: No Training Fire extinguisher training has not been provided. ※ If training is provided, the judgement is “Yes”; if not, the judgement is “No.” | G31: ='DP MGR'!H45 -> 0 | H31: Limited Training Fire extinguisher training has been provided only to limited (not all) employees in the facility. Water spraying drills have been provided only to limited (not all) self-firefighting members in the facility. | I31: ='DP MGR'!H46 -> 0 | J31: Annual Training for All Employees Fire extinguisher training and education are provided to all employees in the facility at least once per year. Water spraying drills are provided annually to all employees appointed as self-firefighting members in the facility. | K31: ='DP MGR'!H47 -> 0 | L31: Expanded Training Water spraying drills and education are also provided at least once per year to employees who are not self-firefighting members. (Disaster Prevention Department) | M31: ='DP MGR'!H48 -> 0 | N31: Practical Training for Irregular Situations The site plans and conducts practical training for irregular situations such as: - fire at night - electrical power outage - fire on holidays - sudden/unexpected fires | O31: ='DP MGR'!H49 -> 0 | Q31: 防災 | R31: =G31 -> 0 | S31: =I31 -> 0 | T31: =K31 -> 0 | U31: =M31 -> 0 | V31: =O31 -> 0 | W31: =IF(R31="No",1,IF(S31="No",1,IF(T31="No",2,IF(U31="No",3,IF(V31="No",4,5))))) -> 5 | X31: =IF(W31<2,"C",IF(W31<3,"B-",IF(W31<4,"B",IF(W31<5,"B+",IF(W31=5,"A",""))))) -> A | Y31: 順守推進
D32: 17 | E32: Hot Work | F32: No Standard / Unsafe Practice There is no standard for hot work, or hot work equipment is used without: - advance application, - advance check*(e.g., presence of combustibles/flammables, preparation of extinguisher/water, spark prevention), - assignment of fire watcher, or - checking for residual fire after work. (If any one of these is missing/defective, the judgement is “No.”) | G32: ='DP MGR'!H50 -> 0 | H32: Standards Exist – Defects in Implementation Standards for hot work exist and equipment is used with advance application. However, there are defects in areas such as advance check, assignment of fire watcher, residual fire check, or 3S practices. | I32: ='DP MGR'!H51 -> 0 | J32: Controlled According to Standards Hot work is controlled in accordance with established standards. ※ At least one site (construction area, periodic repair area, or designated hot work area) must be checked. | K32: ='DP MGR'!H52 -> 0 | L32: 3S Visual Standard Applied Hot work in designated hot work areas is controlled in accordance with the standards. 3S is implemented based on 3S visual standards (MAP, position, number of items, cleaning level, etc.) or assessed as level 4 or higher. ※ Confirm at least one internal production site. SVs | M32: =SV!H18 -> 0 | N32: Best Practices & Continuous Improvement Hot work in designated hot work areas is controlled in accordance with the standards. 3S is implemented per 3S visual standards, and best practices from other sites/industries are applied for continuous improvement. (Or 3S level is assessed as 5.) ※ Confirm improvements at least at one internal production site. SVs | O32: =SV!H19 -> 0 | Q32: 防災 | R32: =G32 -> 0 | S32: =I32 -> 0 | T32: =K32 -> 0 | U32: =M32 -> 0 | V32: =O32 -> 0 | W32: =IF(R32="No",1,IF(S32="No",1,IF(T32="No",2,IF(U32="No",3,IF(V32="No",4,5))))) -> 5 | X32: =IF(W32<2,"C",IF(W32<3,"B-",IF(W32<4,"B",IF(W32<5,"B+",IF(W32=5,"A",""))))) -> A | Y32: 順守推進
