Workbook

Sheet Cover Sheet
B2: Validation Assessment Outline
B4: Assessment Data
B5: SBU | D5: Site Name | F5: Site Type | H5: Assessment Year | J5: Assessment Day
B6: BSAPIC | F6: Tire mfg.
B8: Assessor Name
G9: Safety assessor
G10: DP assessor
G11: Safety assessor
B15: Results of Previous Validation Assessment | H15: Date
B16: SMA Score | D16: Leadership | F16: Teammates | H16: Organization | J16: System
B19: Working Injury Data (Only Direct Employee)
B20: Year | F20: =IF($H$6="","",$H$6-3) -> 2022 | H20: =IF($H$6="","",$H$6-2) -> 2023 | J20: =IF($H$6="","",$H$6-1) -> 2024
B21: The number of total injury case (D+X1+X2+Y+N1)
B22: The number of fatality/serious injury case (D+X1+X2)
B23: Total Working Hour
B24: TIR* | F24: =IF(F23="","",F21/F23*1000000) -> 0.65156396 | H24: =IF(H23="","",H21/H23*1000000) -> 0.71273158 | J24: =IF(J23="","",J21/J23*1000000) -> 0.75060705
B25: SIR* | F25: =IF(F23="","",F22/F23*1000000) -> 0 | H25: =IF(H23="","",H22/H23*1000000) -> 0 | J25: =IF(J23="","",J22/J23*1000000) -> 0
B26: *These scores are calculated based on Global KPI's calculate rules.

Sheet Leadership Checklist
C1: Level | D1: Criteria 基準 | E1: Element エレメント | G1: Question 質問 | H1: Interview/Check インタビュー/確認 | U1: Interview インタビュー | V1: On-Site Observation 現場確認 | W1: Documents(example) 文書確認（例） | X1: Judgement Criteria 判断基準 | Y1: Judgement 判断 | Z1: Reason 判断理由
H2: Who? | I2: Plant Mgr. 工場長 | J2: Prod. GM 製造部長 | K2: Prod. Mgr. 製造課長 | L2: Foreperson 主任 | M2: Supervisor 職長 | N2: Teammate 技能員 | O2: Maintenance Manager 保全課長 | P2: Maintenance Foreman/Supervisor 保全主任/職長 | Q2: Maintenance Staff 保全員 | R2: Safety mgr. 安全担当課長 | S2: D.P. Manager 防災担当課長 | T2: Others その他 | U2: Content
B3: Ad-hoc | C3: 1 | D3: Site leadership can demonstrate general knowledge of their legal obligations in OH&S and DP management and how to fulfil these. 管理者は労働安全衛生および防災管理における法的義務とその履行方法に関する全般の知識を示すことができる。 | E3: Support 支援 | F3: 1 | G3: In general, does site leadership understand the legal OH&S and DP requirements & how these obligations are fulfilled? 管理者は、自身の安全衛生および防災に関する法的義務を理解しているか？ | H3: Plant manager 工場長 | I3: レ | U3: In general, how are the site's legal requirements identified and fulfilled? 法令要求は、どのように特定され、順守されていますか？ | X3: Plant manager can provide an overview of the legal requirements regarding OH&S and DP management and explain how these requirements are met and kept up to date. 工場長は労働安全衛生および防災管理に関する法的要件の概要を説明し、その要件に適合する方法、および内容が更新されていることを説明ができる。
C4: 1 | D4: Applicable site-specific OH&S regulations have been identified and current safety procedures and processes have been evaluated to ensure they are compliant with local regulation. SBU requirements. 労働安全衛生規則が制定されており、現行の安全手順・実施事項はローカル法規に準拠するよう評価されている。 | E4: Prioritization 優先付け | F4: 2 | G4: Have applicable site-specific OH&S regulations been identified, and site-specific safety procedures been implemented that they are compliant with local regulation and SBU standards? 安全衛生法令が特定されているか？また、安全手順が法令に準拠しているか確認するため、評価が実施されているか？ | H4: Safety Manager 安全担当課長 | R4: レ | U4: How have you ensured that all procedures applicable to your site have been developed & implemented, and meet local regulations & SBU standards? 安全手順・実施事項の法令順守を評価するため、どのような方法をとっていますか？ | X4: H&S manager can provide all of the applicable OH&S procedures for their specific site. 安全担当課長は、現場または事務所にて当該労働安全衛生規定の一覧を示すことができる。
C5: 1 | E5: Prioritization 優先付け | F5: 3 | H5: Safety Manager 安全担当課長 | R5: レ | X5: All safety procedures and processes have been issued and approved by an authorized company subject matter expert. すべての安全手順と安全プロセス（標準）は、権限を与えられた専門家によって承認・発行されている。
C6: 1 | D6: Review of records indicates that legally required OH&S management processes are implemented in a consistent manner. 記録を検証すると、法的要件の労働安全衛生の実施事項が一貫して実行されていることが確認できる。 | E6: Decisions 意思決定 | F6: 4 | G6: Are the OH&S management processes required by regulations executed on time? 法令で要求される労働安全衛生の実施事項が遅延なく、実行されているか？ | H6: Safety Manager 安全担当課長 | R6: レ | V6: Observe in >1 work area the implementation of OH&S processes required by regulation & SBU procedure (e.g. LOTO, Working at Heights) 法的要件の労働安全衛生の実施事項（LOTO、高所作業など）の実施状況について、3つ以上の作業地区を視察する。 | X6: All observed OH&S management processes have been implemented, and comply with SBU or external requirements(e.g. requirements required by regulation). 観察した労働安全衛生管理プロセスは、内部または外部要求（例:法令要求）に応じて遅延なく実行されている。
C7: 1 | D7: Interview statements from workers indicate that safety is considered a priority by leadership. 技能員との面談調査では、管理者のﾘｰﾀﾞｰｼｯﾌﾟによって、技能員は安全が最優先であることを理解している"ことが示される。 | E7: Support 支援 | F7: 5 | G7: Does Site Leadership consider safety a priority? 管理者は、安全を第一優先として、考慮しているか？ | H7: Teammate 技能員 | N7: レ | U7: How important is H&S at work? Does site leadership address safety at the morning assembly, roll-call, etc.? 職場において安全衛生は、どのように重要ですか？ 朝礼や点呼の際に、管理者は安全に関する話をしていますか？ | V7: Sample >3 work areas and talk with teammates about the importance of H&S on site. 3か所以上の作業地区を任意選択し、現場における安全衛生管理の重要性について技能員の話を聞く。 | X7: All teammates interviewed stated that H&S is considered a high priority on site. Leadership address safety at the morning assembly, roll call, etc. 面談した技能員の全員が、現場における安全衛生管理の優先度は高いと述べた。点呼・朝礼などの機会で安全に関する話を受けている。
C8: 1
B9: Reactive | C9: 2 | D9: Communication records and statements from workers indicate that leadership is involved in OH&S management when serious incidents(lost-time-injury, fire accident, etc.) occur. 技能員からの連絡記録および発言により、重大インシデント（休業災害・火災等）が発生した場合には管理者が労働安全衛生管理に参加対応していることが示される。 | E9: Support 支援 | F9: 6 | G9: Is Site Leadership involved in the OH&S management when a serious incident occurs? 管理者は、重大インシデント（休業災害・火災等）発生時、安全衛生管理に関与しているか？ | H9: Teammate 技能員 | N9: レ | U9: What normally happens when a serious incident (lost-time injury, fire accident, etc.) occurs, who does what in your view? 重大インシデント（休業災害・火災等）が発生すると、通常どのような事が起こりますか？あなたの見解では、誰が何をしますか？ | V9: Sample >3 work areas and talk with teammates about last serious incident (lost-time injury, fire accident, etc.) on their line/at site. 3か所以上の作業地区を任意選択し、ラインおよび現場にて最後に発生した重大インシデント（休業災害・火災等）について技能員の話を聞く。 | X9: All teammates stated that, at least, safety manager and site leadership representative (e.g. plant manager, department manager, line manager) was involved in the root cause analysis process when a serious incident(lost-time-injury, fire accident, etc.) occurred 重大インシデント発生時（休業災害・出火事故等）の原因分析プロセス(例:JS分析)には、技能員の全員が、少なくとも安全担当課長と現場の管理者（工場長、部門長、課長・主任・職長など）が参加対応していると述べた。
C10: 2 | D10: Safety performance (Safety KPIs) based on OH&S policy is monitored and tracked by site leadership. 安全成績・安全関連KPIは、安全衛生方針に基づき定められ、管理者によって監視され、追跡管理されている。 | E10: Prioritization 優先付け | F10: 7 | G10: Are safety results (KPIs) being monitored by leadership? 管理者は、安全結果をモニタリングしているか？ | H10: Plant manager 工場長 | I10: レ | V10: Review Line/Cell Boards (e.g. PDCA, Daily Meeting boards) for updated Safety KPI's ラインや作業地区のボード（PDCA、日次会議ボードなど）で、安全関連のKPIが更新されているかを検証する。 | W10: Review safety performance KPI's. 安全関連KPIの検証 | X10: Safety KPIs are tracked at plant, department and line level. 安全関連KPIは、工場、部門、ラインレベルで追跡管理されている。
C11: 2 | E11: Prioritization 優先付け | F11: 8 | H11: Plant manager 工場長 Production general manager 製造部長 | I11: レ | J11: レ | X11: To solve issues on H&S, site leadership follow safety KPIs, and give directions to review the safety program if necessary. 工場長は安全課題を解決するため、安全関連KPIをフォローし、必要に応じて安全施策の見直しを指示している。
C12: 2 | D12: Incident investigation records identify the root causes of incidents, categorizes them, and tracks the number of incidents by each category. (Human error, system error, Natural causes) *インシデント(災害・業務上疾病・ヒヤリ)記録により、インシデント原因を特定および分類し、分類ごとのインシデント件数を追跡管理している。（人的エラー、システムエラー、自然原因） | E12: Prioritization 優先付け | F12: 9 | G12: Are the root causes of incidents categorized and then tracked? 災害の原因は、分類（要因分析）され、追跡（フォロー）されているか？ | H12: Safety Manager 安全担当課長 | R12: レ | W12: Review incident investigation records and determine over a sample what common causes were. インシデント調査記録を検証し、任意選択したものの中から共通原因を判定する。 | X12: A review of 10 most recent incident records show that the cause has been determined and the countermeasures are followed-up by the termination. 直近10件の災害(労働災害・業務上疾病・ヒヤリ)記録を検証すると、分類ごとに原因が特定され、対策完了までフォローされている。
C13: 2 | D13: Safety Initiatives are being implemented to improve safety results, not operational performance results. 安全活動は生産性の改善ではなく、安全成績の改善を目的に実施されている。 | E13: Decisions 意思決定 | F13: 10 | G13: Are safety initiatives being implemented to improve safety or improve operational results? 安全性向上のために、リーダーシップが発揮されているか？ | H13: Safety Manager 安全担当課長 | R13: レ | U13: Review current safety related projects documentation, establishing their purpose and expected results. 現在の安全関連プロジェクトの書類、それらの目的、期待されるを結果は何か？ | W13: Project Charter; Technical Base Plan; Training documents. 取組み計画、技術基本計画（改造等）、教育関連資料。 | X13: Safety department plans to improve safety activities in the plant, and the plan is implemented. 安全担当部署では、工場全体の安全活動の改善業務が、計画され実行されている。
C14: 2
B15: Standardized | C15: 3 | D15: Site tour(s) indicate that line-management conducts floor observations to ensure adherence to safety rules, such as procedures, standards, etc. 現場を視察すると、手順、規格などの安全ルールが遵守されるように、製造課長・主任・職長が技能員を監督していることが示される。 | E15: Support 支援 | F15: 11 | G15: Does line management actively provide feedback to teammates and promote safety while touring their department/area? ライン管理者（課長・主任・職長）は、巡回時、積極的に技能員へフィードバックを行い、安全を推進しているか？ | H15: Managers 管理者 | K15: レ | L15: レ | M15: レ | O15: レ | P15: レ | V15: Sample >3 work areas and observe the extend to which the supervisor is actively supervising/coaching 3か所以上の作業地区を任意選択し、監督者（主任・職長）が積極的に監督および指示を実施している範囲を観察する。 | W15: Review any documented systems used by leadership that demonstrates that safety-focused safety tours, observations, coaching, etc. occur at regular/frequent intervals. The plan, progress, and records of these activities are confirmed. 管理者による安全巡回、現場確認、コーチングなどが定期/不定期で行われていることを示す、文書化されたシステムが整備されているか確認する。またこれらの計画・進捗および記録について確認する。 | X15: Line-management conducts floor observations(e.g. site tours) and provides feedback to teammates to ensure adherence to safety rules, such as procedures, standards, etc. 手順、規格などの安全ルールが遵守されるように、製造課長・主任・職長は巡回等の現場確認を行い、技能員へフィードバックを行っている。
C16: 3 | D16: Interview statements from teammates and line-managers indicate that they accept own responsibilities when it comes to safety management and the importance of their contributions. 技能員と製造課長の面談調査では、安全管理についてそれぞれが責任を有することを受け入れていることが示される。 | E16: Support 支援 | F16: 12 | G16: Do teammates know what their responsibilities are when it comes to Safety? 技能員は、安全に関する自身の責任を理解しているか？ | H16: Teammate 技能員 | N16: レ | U16: To what extend are you truly responsible for safety? And what does that mean to you? 実際にあなたが負っている安全に関する責任は何ですか？あなたにとってそれは、何を意味しますか？ | X16: A sample of 5 all stated that they acknowledge and accept their own responsibilities when it comes to safety management, and can explain what this means. 任意選択した5名の技能員の全員が、安全管理に関する義務があることを認識していることを示し、これを受け入れると述べた。
C17: 3 | D17: Leadership understand the importance of teammate involvement in safety management and can demonstrate clear actions regularly incorporated to help the site realize the positive results of those actions. 管理者は安全管理に従業員が参加することの重要性を理解し、活動結果を含めて、従業員の参加を実現するための明確な活動内容を示すことができる。 | E17: Decisions 意思決定 | F17: 13 | G17: Does leadership know how important teammate involvement in safety is, and involve teammates in safety activities? 管理者は、安全活動に従業員を参加させることの重要性を理解し、安全活動に参加させているか？ | H17: Managers 管理者 | I17: レ | J17: レ | K17: レ | O17: レ | R17: レ | U17: What are your expectations of teammates when it comes to the teammates' involvement in H&S management? あなたは、従業員に対し、安全衛生に関し、どのような期待を持っていますか？ | X17: A sample of 2 managers could both explain why teammate involvement in safety management is important and can provide examples of actions taken (e.g., assigned safety-related tasks/activities, participation in safety committee, etc.) to promote this and the results of those actions. 任意選択した2人の管理者が、安全管理への従業員の参加対応が重要である理由を説明し、その促進活動の例（例：安全活動への参加促進、業務指示、労働安全衛生委員会への出席等）および結果を示すことができる。
C18: 3 | D18: The H&S team, teammates and leadership meet at planned intervals to provide inputs to improve safety on site. 安全担当課、技能員、管理者は、現場の安全を改善する目的で、計画された間隔で会議を開催して意見を出している。 | E18: Decisions 意思決定 | F18: 14 | G18: Is there a H&S meeting with representation from teammates, leadership and H&S, and leadership give directions to solve issues? 技能員、管理者、安全衛生部署からの代表者で構成される安全衛生会議では、管理者、工場長による課題解決のための指示があるか？ | H18: Managers 管理者 | I18: レ | J18: レ | K18: レ | V18: Request attendance at such a meeting and observe what is being discussed. (If a validation assessment, and not able to attend such a meeting, ask for meeting minutes, attendance sheets, etc. that will support the judgement criteria.) そのような会議への出席許可を要請し、議論されている内容を観察する。 参加が難しい場合はそれら会議の議事録や出席表を確認し、判断の根拠とする。 | X18: During the attended meeting, the H&S team discussed the improvement of safety on site, and the meeting was well attended (>75% of members at every meeting). 出席した会議では、安全担当課が現場の安全性の向上について議論し、多数の参加者がいた（すべての会議で全メンバーの75%を超えるメンバーが参加）。
C19: 3 | D19: Leadership often emphasizes the importance of the Safety Rules and breaking the rules results in repercussions/consequences. 管理者は安全ルールの重要性を適時強調しており、規則違反に対しては対応や罰則が発生する。 | E19: Prioritization 優先付け | F19: 15 | G19: Are there repercussions/consequences for not following the Safety Rules and procedures? 安全ルール違反時の影響/結果（罰則・対応手順）はあるか？ | H19: Managers 管理者 | I19: レ | J19: レ | K19: レ | O19: レ | U19: Are there repercussions/consequences for teammates who break the safety rules and procedures? （安全）ルール違反をした従業員に対し、影響/結果（罰則）はありますか？ | W19: Review disciplinary procedure & documented examples of carrying out disciplinary action. 罰則手順書および罰則事例を検証する。 | X19: A sample of 3 managers all confirm that there are repercussions/consequences for teammates that do not follow the Safety Rules and Procedures. 任意選択した3人の管理者が、安全規則や手順を違反した従業員には罰則が発生することを示した。
C20: 3
B21: Proactive | C21: 4 | D21: Leadership keeps track of leading indicators to determine the results of investments made to improve health and safety at the facility 管理者は施設における安全衛生の向上に関する投資結果を示す主要指標を追跡管理している。 | E21: Prioritization 優先付け | F21: 16 | G21: Does Leadership use "Leading indicators" in their safety result tracking? 安全関連の指標について、先行指標（プロセスKPI）を使っているか？ | H21: Plant manager 工場長 | I21: レ | V21: Review site system for updating and communicated safety KPI's 安全関連のKPIが更新されコミュニケーションされていることを現場の仕組みで検証する | W21: Review safety performance KPI's to see if these are leading or lagging. Review Plant PDCA Board or other means of communicating safety results (KPI's) & updated status. 安全関連のKPIの項目が先行値か遅延値かを検証する。 工場のPDCAボードまたはその他の安全KPIや改善履歴について確認する。 | X21: Safety KPIs are tracked positively at plant, department and line level - using "Leading indicators"(e.g. Progress of RA, KPI for 3S activity, internal H&S audits findings, etc.) 安全関連KPIは「先行指標」（例：RA進捗、3S活動評価、内部監査の指摘事項等のプロセスKPI）を使用して、工場、部門、ラインのレベルで積極的に追跡管理されている。
C22: 4 | E22: Prioritization 優先付け | F22: 17 | H22: Plant manager 工場長 | I22: レ | X22: Site leadership follow not only lagging indicator(e.g. # of injuries), but also leading indicators, and give directions to review and/or improve safety programs/systems/activities if necessary. 工場長は、結果系KPI（災害件数等）だけでなく、先行指標(プロセスKPI）をフォローし、必要に応じて施策の見直し・改善を指示している。
C23: 4 | D23: There is a clear OH&S program consisting of multiple improvement/enhancement projects and allocated budgets to address defined OH&S priorities 明確な労働安全衛生プログラム（実施事項）があり、労働安全衛生について定義された優先事項について複数のプロジェクトがあり、予算が計上されている。 | E23: Decisions 意思決定 | F23: 18 | G23: Are there ongoing safety projects addressing safety issues? 安全の問題に対する、進行中の安全プロジェクト（安全に関する取り組み）があるか？ | H23: Safety Manager 安全担当課長 | R23: レ | U23: What are your top-3 risks and how are these being mitigated? あなたにとって、トップ3のリスクは何ですか？それらはどのように低減されていますか？ | X23: The H&S manager has identified the top 3 risks on site based on data and feedbacks from teammates, and can describe the measures or activity for improvement. 安全担当課長は、現場からの意見を踏まえた上で自職場の安全上の課題の優先度を認識しており、その対応方法や改善活動、計画とその進捗について説明できる。
C24: 4 | D24: Managers and/or the safety department are conduct pre- and post- assessments to determine the effectiveness of OH&S initiatives 労働安全衛生活動の有効性を確認するため、製造課長かつ/または安全担当課は安全衛生施策の開始前(導入前)と後に有効性の評価を行っている。 | E24: Prioritization 優先付け | F24: 19 | G24: Are pre and post assessments used to determine the effectiveness of OH&S initiatives? 安全衛生施策の有効性を確認するため、施策の導入前と後に有効性の評価を行っているか？ | H24: Safety Manager 安全担当課長 | R24: レ | W24: Sample 3 H&S projects and review the pre- and post assessment results 3件以上の安全衛生プロジェクトを任意選択し、事前評価と事後評価を検証する。 | X24: A sample of 3 OH&S projects all show that pre-assessments and post-assessments took place to monitor the effectiveness of new OH&S incentives. 任意選択した3件の安全衛生プロジェクトで、事前評価と事後評価が実施され、労働安全衛生インセンティブの有効性が確認できる。
C25: 4 | D25: Hazard reporting records indicate that teammates are actively involved in reporting and addressing hazards and risks in their daily jobs 危険状況報告記録では、日常業務における危険状況やリスクについて、技能員が積極的に報告および対応していることが示される。 | E25: Support 支援 | F25: 20 | G25: Do teammates report hazards (e.g., near misses, hidden dangers) regularly? 技能員は、定期的に危険源(例:ヒヤリ、不具合、潜在的危険源）を報告しているか？ | H25: Managers 管理者 | J25: レ | K25: レ | O25: レ | U25: What was the last hazard (e.g., hidden danger/near miss) reported from within your department and who reported it? 自部署において、直近で報告された危険源（潜在的危険源、ヒヤリ等）は、何ですか？誰がそれを報告しましたか？ | W25: Review how many hazards (e.g., hidden dangers, near misses) have been reported over a given time period. ある一定期間に報告された危険状況件数を検証する。 | X25: A review of the hazard reporting records for the last month show that at least 50% of hazards reported were from teammates on the factory floor. 前月の危険状況報告記録を検証すると、報告された危険状況の50%以上は技能員によるものであった。
C26: 4 | D26: Good safety behaviors of teammates are rewarded and recognized by managements. 技能員の優れた安全行動が管理者によって認知され、表彰されている | E26: Support 支援 | F26: 21 | G26: Are good safety behaviors of teammates rewarded and recognized by managements? 技能員の優れた安全行動が管理者によって認知され、表彰されているか? | H26: Management 管理者 | J26: レ | K26: レ | O26: レ | R26: レ | S26: レ | U26: How do you praise for safety behavior or performance? どのように優れた安全行動や成績を褒める/称賛していますか？ | X26: In a sample of 3 managers, all 3 can explain when rewards are provided for good safety behavior/performance, and give the examples. 任意選択した3人の管理者の全員が、優れた安全活動/成績を賞賛した事例を説明できる。
C27: 4
B28: Excellence | C28: 5 | D28: The safety team can demonstrate how industry(tire industry, rubber industry, manufacturing industry, etc.) *best-practice and scientifically proven best-practices are incorporated in their H&S program 安全担当課は、業界(タイヤ業界、ゴム業界、製造業界 等）の*ベストプラクティスおよび科学的に実証されたベストプラクティスが、安全衛生管理プログラム（実施事項）にどのように組み込まれているかを示すことができる。 | E28: Decisions 意思決定 | F28: 22 | G28: Have you gathered best practices on safety activity from GBS/SBU or external companies, and implement them in the plant? 社外またはGBS/SBUから展開された安全活動の好事例を自工場へ適用し、推進されているか？ | H28: Safety Manager 安全担当課長 | R28: レ | U28: How do you source best-practices and use these to benefit your H&S program? あなたは、どうやってベストプラクティスを収集していますか？ また、それらを事業所の安全衛生プログラムにどのように生かしていますか？ | X28: The H&S manager can give examples of industry best practices, where they came from and how they have been, or are being implemented on site. 安全担当課長は、業界のベストプラクティスの例、その出所、現場における導入方法を示すことができる。（今後実施予定のベストプラクティスを示すことも含める）
C29: 5 | D29: Management contributes to cross-plant and external H&S meetings during which H&S challenges and insights are shared 工場間会議および外部関係者の安全衛生会議では管理部門が貢献し、安全衛生に関する課題や考え方を共有している。 | E29: Support 支援 | F29: 23 | G29: Is there an external/cross-plant safety meeting? If so, does safety manager share H&S issues or best practices? 他工場、もしくは社外との安全会議があり、課題や好事例を共有しているか？ | H29: Safety Manager 安全担当課長 | R29: レ | V29: Request to attend such a meeting and review what is being discussed 会議への参加を依頼し（可能な場合）、議論の内容を確認する。 | W29: Review Meeting attendance Records and Minutes of Meetings shared. 会議出席記録、および議事録が共有されているかを検証する。 | X29: During the attended meeting, management contributed to discussions' in the cross-plant/external safety meeting. (E.g. Safety manager meeting in SBU, meeting in the local safety association, etc.) 出席した会議では、工場間会議および外部関係者の安全衛生会議(例:SBU内の安全課長会議、地域の安全協力会等)で管理者が貢献していた（安全衛生の改善に向けた困りごと・問題・課題提起・ベストプラクティス共有）
C30: 5 | D30: Site leadership has incorporated the OH&S program in their overall strategy and can explain how the conflicting objectives are prevented in that strategy 工場長は、総合戦略に労働安全衛生プログラム（実施事項）を取り入れて、戦略について相反する目標が発生するのを防止する方法を説明できる。 | E30: Support 支援 | F30: 24 | G30: Is there a long term OH&S strategy for the plant? 事業所の長期的な安全衛生計画はあるか？ | H30: Plant manager 工場長 | I30: レ | U30: What do you want to achieve in the area of H&S during the next 5 years and how is that resourced? 今後5年間で、安全衛生に関し、達成したことは何ですか？また、どのようにリソースを配分していますか？ | X30: The Plant Manager can describe his/her 5-year OH&S strategy and its goals, and how it will be implemented and the goals achieved. 工場長は、工場の労働安全衛生戦略、その目標、導入方法、達成済み目標を説明できる。
C31: 5 | D31: All interviewed workers confirm that safety is essential and that they feel comfortable stopping work whenever health or safety might be compromised 面談した技能員の全員から、安全が絶対不可欠であり、安全衛生が損なわれる可能性がある場合には躊躇なく作業を停止できるとの確認が得られる。 | E31: Support 支援 | F31: 25 | G31: Do teammates feel comfortable stopping work if they feel there is a risk of injury? 技能員は、災害リスクに直面した際、作業を停止することを、よいことだと感じているか？ | H31: Teammate 技能員 | N31: レ | U31: When health or safety might be compromised (e.g., you feel there is a risk of injury), what action do you take? Do you feel comfortable stopping or not starting work if you feel unsafe? 災害リスクに直面した際、どのような行動をとりますか？例えば、安全を確認できるまで作業を止めたり、開始せずに待機することをどのように感じますか？ | X31: A sample of 5 teammates all confirm that they feel safety is essential. They are comfortable stopping work when they feel their safety is compromised. 任意選択した5人の技能員が、安全が絶対不可欠であると述べた。安全が損なわれると思ったときには、躊躇なく作業を停止できる。
C32: 5 | D32: Leadership motivate teams to find the best safety practices and provide the resources to implement them. 管理者は、各チームが最善の安全対策を見つけるように推奨し、それを実施するためのリソースを提供している。 | E32: Prioritization 優先付け | F32: 26 | G32: Does leadership motivate teams to find and implement new best practices relevant to safety? 管理者は、各部署に対し、安全に関するベストプラクティスの収集や実行を推進しているか？ | H32: Managers 管理者 | J32: レ | K32: レ | O32: レ | R32: レ | S32: レ | U32: How do teams find the relevant best practices when it comes to safety? 各部署は、どのように安全衛生に関するベストプラクティスを収集していますか？ | X32: A sample of 3 managers, 1 can explain how they motivate teams to find best practices and how they allocate resources to implement them. 任意選択した3人の管理者のうち1人が、チームに対してベストプラクティスを模索する動機付けの方法、および導入するためのリソースを割り当てる方法を説明できる。
C33: 5
I34: =COUNTA(I3:I33) -> 9 | J34: =COUNTA(J3:J33) -> 7 | K34: =COUNTA(K3:K33) -> 7 | L34: =COUNTA(L3:L33) -> 1 | M34: =COUNTA(M3:M33) -> 1 | N34: =COUNTA(N3:N33) -> 4 | O34: =COUNTA(O3:O33) -> 6 | P34: =COUNTA(P3:P33) -> 1 | ... T34: =COUNTA(T3:T33) -> 0
D35: *Best practice includes information gathered from other plants or external companies. The items which were already standardized are excluded. (E.g. Engineering/recurrence prevention measures defined in the international standard or SBU standard)
D36: *ベストプラクティスには、他工場や他社から入手した好事例が含まれる。但し、既に標準化/規格化/要領化された内容を除く。（例：国際規格やSBU規格に規定されている設備対策・類災対策）
D37: *Incidents: lost-time-injury, fire accident, occupational disease, near-miss, recurrence prevention, etc.
D38: インシデントには、災害・出火事故・業務上疾病・ヒヤリ・類災 等を含む

Sheet Teammate Engagement Checklist
D1: Criteria 基準 | E1: Element エレメント | G1: Question 質問 | H1: Interview/Check インタビュー/確認 | U1: Interview インタビュー | V1: On-Site Observation 現場確認 | W1: Documents(example) 文書確認（例） | X1: Judgement Criteria 判断基準 | Y1: Judgement 判断 | Z1: Reason 判断理由 | AA1: Remark | AB1: F-up result (Jun) by APICTC
H2: Who? | I2: Plant Mgr. 工場長 | J2: Prod. GM 製造部長 | K2: Prod. Mgr. 製造課長 | L2: Foreperson 主任 | M2: Supervisor 職長 | N2: Teammate 技能員 | O2: Maintenance Manager 保全課長 | P2: Maintenance Foreman/Supervisor 保全主任/職長 | Q2: Maintenance Staff 保全員 | R2: Safety mgr. 安全担当課長 | S2: D.P. Manager 防災担当課長 | T2: Others その他 | U2: Content
B3: Ad-hoc | C3: 1 | D3: Teammates are made aware of general H&S risks during new hire training. 従業員は、新入社員研修により、一般的な安全衛生関連リスクを認識する。 | E3: Capability 能力 | F3: 1 | G3: Are general H&S risks explained during new-hire training to new teammates? 一般的な安全衛生リスクは、新入社員に周知されているか？ | H3: Teammate 技能員 | N3: レ | U3: What are the three greatest potential risks relevant to your work? あなたの仕事で3件の最重要リスクは何ですか。 | X3: A sample of 5 teammates recognize the H&S risks applicable in their areas and confirmed these were addressed in trainings. 任意選択した5人の技能員が、それぞれの地区に適用される安全衛生関連のリスクを認識しており、その内容が教育訓練で対応されていることが確認できる。
C4: 1 | D4: Teammates know that safety is considered more important than production. 従業員は、生産よりも安全を優先するという意識を持っている | E4: Action 行動 | F4: 2 | G4: Do you think that safety is considered more important than production? あなたは、生産よりも安全が優先されると考えますか？ | H4: Teammate 技能員 | N4: レ | U4: What would be considered a priority: complete the production plan or follow safety procedures? あなたにとって、生産計画の完了と安全手順の準拠ではどちらが優先事項ですか。 | V4: Conduct a site tour during peak and off hours to see if behavior is(un)safer Talk to teammates on the shop floor about the priority that safety has over production. ピーク時間帯とピーク以外の時間帯に現場を視察して、安全な行動を取っているかを確認する。 生産よりも安全が優先されることについて、製造現場の従業員と話をする。 | X4: Teammates know that safety is considered more important than operational results. 各従業員は、生産よりも安全が重要であることを知っている。
C5: 1 | D5: Management is aware of their responsibility in keeping teammates safe and enforcing safety rules and procedures. 管理者は、部下の安全を担保し、安全ルールを順守させる責任があることを認識している。 | E5: Capability 能力 | F5: 3 | G5: Is management aware of their personal impact on safety and do they leverage this to improve safety? 管理者は、安全に対する自身の影響力を認識し、安全向上に、活用しているか？ | H5: Management 管理者 | I5: レ | J5: レ | K5: レ | R5: レ | S5: レ | U5: How can/do you contribute to a safer execution (implementation) of safety procedures, projects, requirements? 安全な作業、要求事項を実行するために、あなたはどのような貢献ができますか。 | X5: In a sample of 3 managers, >1 stated that they do have an impact on teammate safety and they involve themselves with safety processes. 任意選択した3人の管理者のうち1人以上が、自身が従業員の安全に影響を及ぼし、安全プロセスに参加対応していると述べた。（例：巡回による安全状況確認、安全対策の優先順位付け、予算割り当て等）
C6: 1 | D6: Managers explain safety requirements based on regulation to teammate. 管理者は、部下に安全に関する法的要求事項を説明している。 | E6: Knowledge 知識 | F6: 4 | G6: Do managers explain safety requirements based on site-specific regulation to teammates? 管理者は、技能員に安全に関する法的要求事項を説明しているか？ | H6: Production Supervisor 製造主任 | L6: レ | U6: What requirement do you explain to operators on safety requirements based on regulation? 安全に関する法的要求に関して、あなたはどういった内容を技能員に説明していますか？ | W6: Review documented trainings, meetings, etc. where this information would be provided and explained. (e.g., minutes, education manual/record) これらの情報が提供される会議・打ち合わせもしくは教育の記録等を確認する。 | X6: In a sample of 3 managers, > 1 stated that they explain safety requirements based on site-specific regulation to teammates. 任意選択した3人の管理者のうち1人以上が、安全に関する法的要求事項を技能員へ説明している と述べた。
C7: 1
B8: Reactive | C8: 2 | D8: Teammates know how to report when incident(injury, occupational disease/illness, near-miss, hidden danger, fire) occurs, and incident reporting records and interview statements indicate that teammates report incidents. 技能員はインシデント(災害、業務上疾病、ニアミス・潜在的危険源、火災)が発生した際の報告方法を知っており、インシデント報告記録および面談報告書では従業員からインシデントが報告されている。 | E8: Capability 能力 | F8: 5 | G8: Do teammates know how to report incidents (injury, occupational disease/illness, near-miss/hidden danger)? 技能員はインシデント発生時の報告方法を知っていますか？ | H8: Teammate 技能員 | N8: レ | U8: How do you report an incident (injury, occupational disease/illness, near-miss/hidden danger)? Have you reported any recently, or are aware of any recently reported incidents? あなたが最近報告したインシデント（労働災害、疾病、ヒヤリ、潜在的危険源）は何ですか？ もしくは、最近他の技能員によって報告された事例は何かありますか？ | W8: Review incident records and cross-reference these with interview statements インシデント記録を検証し、面談調査と比較検討する。 | X8: A review of the incident records from the last month show that teammates have been reporting incidents (injury, occupational disease/illness, near-miss/hidden danger). In a sample of 5 teammates, at least 4 could explain how to report when an incident happen. 前月のインシデント記録を検証すると、インシデント（労働災害、疾病、ヒヤリ、潜在的危険源）を従業員が報告していることがわかる。任意選択した5人の技能員のうち4人以上がインシデント発生時の報告方法を知っている。
C9: 2 | D9: Teammates are involved in the actions implemented to prevent the reoccurrence of an incident (injury, occupational disease/illness, near-miss, hidden danger, fire) relevant to their daily job to ensure the appropriateness of such actions 各技能員は日常業務の中で事故再発防止対策に参加し、インシデント(災害、業務上疾病、ニアミス・潜在的危険源、火災)への適切な対策をとっている。 | E9: Action 行動 | F9: 6 | G9: Are teammates involved in preventing recurring incidents (injury, occupational disease/illness, near-miss/hidden danger)? 技能員は、再発防止（活動）に参加しているか？ | H9: Teammate 技能員 | N9: レ | U9: If you are involved in preventing incidents (injury, occupational disease/illness, near-miss/hidden danger), what do you do for recurrence prevention? もし、インシデント（労働災害、疾病、ヒヤリ、潜在的危険源）の発生にあなたが関与していた場合、あなたは再発防止のために何をしますか | X9: A sample of 5 teammates, at least 2 said they take part in the actions required to prevent incidents (injury, occupational disease/illness, near-miss/hidden danger) and provide feedback if these actions are not appropriate or useful. 任意選択した5人の技能員のうち2人以上が、インシデント（労働災害、疾病、ヒヤリ、潜在的危険源）防止のために必要な対応措置に参加し、その対応措置が不適切または有用でない場合にはフィードバックを提供すると述べた。
C10: 2 | D10: Statements from teammates indicate that they are informed of recent safety incidents relevant to them and the follow-up/actions taken to address them. 各技能員は、直近の安全関連インシデントの連絡を受けており、管理者から示されたフォローアップを認識している。 | E10: Knowledge 知識 | F10: 7 | G10: Are teammates informed of recent safety incidents (injury, occupational disease/illness, near-miss/hidden danger) in their areas and know what actions have been taken to address these? 技能員は、自職場の最近発生した災害とどのような対策が講じられたか連絡を受けているか？ | H10: Teammate 技能員 | N10: レ | U10: What incidents (injury, occupational disease/illness, near-miss/hidden danger) and the countermeasures were you informed of from management? 最近、連絡を受けたインシデント（労働災害、疾病、ヒヤリ、潜在的危険源）とその対策は何ですか？ | W10: Review incident (injury, occupational disease/illness, near-miss/hidden danger) records and cross-reference these with interview statements インシデント（労働災害、疾病、ヒヤリ、潜在的危険源）記録を検証し、面談調査と比較検討する。 | X10: A sample of 5 teammates can all state that they are informed of recent safety incidents (injury, occupational disease/illness, near-miss/hidden danger) in their areas and actions have been taken to address these. 任意選択した5人の技能員の全員が、自職場で発生した安全関連のインシデント（労働災害、疾病、ヒヤリ、潜在的危険源）と対策情報の連絡を受けた実績がある。
C11: 2
B12: Standardized | C12: 3 | D12: Teammates demonstrate a clear understanding of the H&S rules involved in their work and the relevance of these rules 各技能員は各自の業務に関する安全衛生規則を明確に理解し、その規則の関連性を理解していることが示される。 | E12: Capability 能力 | F12: 8 | G12: Do teammates know the department/job safety rules applicable to them? 技能員は、自部署/自作業に適用される安全ルールを理解しているか？ | H12: Teammate 技能員 | N12: レ | U12: What are the most important safety rules to you and why? あなたにとって最も重要な安全規則は何ですか、それはなぜですか。 | X12: A sample of 5 teammates can all explain the Department/Job Safety Rules in their work area and why they are important and relevant. 任意選択した5人の技能員の全員が、自身の作業地区における当該の部門規則や業務安全ルールについて説明でき、規則の重要性と関連性について理由を説明できる。
C13: 3 | D13: Teammates are trained at planned intervals of the different H&S rules aimed at ensuring their safety. 従業員は、自身の安全を確保するための各種安全衛生ルールを計画的な間隔で教育を受けている。 | E13: Knowledge 知識 | F13: 9 | G13: Are teammates regularly trained about the departmental/job safety rules applicable to them? 技能員は、自部署/自作業に適用される安全ルールについて、定期的に教育を受けているか？ | H13: Teammate 技能員 | N13: レ | U13: How can you provide feedback to management on safety rules? 安全ルールに関してどのように管理者へフィードバックしていますか？ | X13: A sample of 5 teammates all agreed that employees are regularly reminded and trained of the Department/Job Safety rules in their area. 任意選択した5人の技能員の全員が、自身の作業地区における当該の部門規則や業務安全ルールについて定期的に周知され、教育を受けていると回答した。
C14: 3 | D14: Site tour(s) indicates a structural adherence to the Department/Job Safety Rules applied to the sampled working areas. 任意選択された作業地区において、当該の部門規則や業務安全ルールが構造的に順守されていることが現場視察で示される。 | E14: Action 行動 | F14: 10 | G14: Are the Department/Job Safety rules being followed strictly? 自部署/自作業における安全ルールは、厳密に順守されているか？ | H14: Teammate 技能員 | N14: レ | V14: Observe work in three work areas to see if people work in accordance to safety rules 3か所の作業地区で作業を観察し、安全規則に従って作業が行われているか確認する。 | X14: When 3 different work areas were toured and observed, there was a strict adherence to the Department/Job safety rules of that area by the people working in that area. 3か所以上の作業地区を視察すると、その地区の作業者は各作業地区における当該の部門規則や業務安全ルールを厳守していた。 | AA14: Same as item 18 of organization checklist & item 76 of system checklist | AB14: Not yet
C15: 3
B16: Proactive | C16: 4 | D16: Interview statements indicate that teammates take trainings and understand the greatest potential H&S risks involved in their work and the controls applied to reduce these risks. 面談調査では、各技能員が教育を受け、自らの業務における安全衛生上の最重要リスクと管理対象項目を理解していることが示される。 | E16: Knowledge 知識 | F16: 11 | G16: Have teammates taken training on residual risks based on the work standard？ 技能員は、残留リスクについて作業標準ベースに教育を受けているか？ | H16: Teammate 技能員 | N16: レ | U16: Have you taken the training on the residual risks in your tasks? あなたは自作業の残留リスクについて教育を受けましたか？ | X16: A sample of 5 teammates could all state that they took the training on residual risks based on the work standard. 意選択した5人の技能員の全員が、残留リスクについて作業標準ベースに教育を受けていると述べた。
C17: 4 | E17: Capability 能力 | F17: 12 | G17: Do you understand the greatest potential risks, and how they are controlled? 技能員は、最も危険なリスクの内容及び管理方法を把握しているか？ | H17: Teammate 技能員 | N17: レ | U17: Which safety risks involved in your work/job are the most serious in your opinion and why? あなたの業務や役割において最も深刻だと思う安全リスクとその理由を教えてください。 | X17: A sample of 5 teammates could all describe and explain the greatest potential H&S risks in their work, and what controls they use or are in place to mitigate these risks. 任意選択した5人の技能員の全員が、各自の作業における最も深刻な安全衛生関連のリスクおよびリスク低減措置について説明できる。
C18: 4 | D18: Teammates propose improvements of H&S risks and risk mitigation measures at the creations or revisions of work standard, training material, etc. 作業標準や教育訓練資料等を作成、改訂する際、技能員が、安全リスクや低減策の改善提案をしている。 | E18: Capability 能力 | F18: 13 | G18: Have teammates proposed improvements of H&S risks and risk mitigation measures at the creations or revisions of work standards, training materials, etc. 作業標準や教育資料等を作成、改訂する際、安全リスクや低減策の改善提案をしていますか？ | H18: Production Supervisor 製造主任 | L18: レ | W18: Review work standards and training materials to see if revision history and content show inclusion of teammate's recommendations/suggestions. 作業標準や教育訓練資料を検証し、改訂履歴とその内容に技能員の意見が含まれているかを確認する。 | X18: Materials indicate that teammates propose improvements of H&S risks and risk mitigation measures at the creations or revisions of work standards, training materials, etc. 作業標準や教育資料等を作成、改訂する際、技能員が、安全リスクや低減策の改善提案をしていることが示される。
C19: 4 | D19: A sample of teammates participate in the risk assessment (RA) process, and they can demonstrate capability in performing a risk assessment on their work activities 任意選択した技能員が、自身の作業に関するリスクアセスメントに参加しており、リスクアセスメントを実施する能力があることを示すことができる。 | E19: Capability 能力 | F19: 14 | G19: Are some teammates capable of performing full risk assessments? 複数の技能員は、リスクアセスメントの全プロセス（危険源の同定から低減対策まで）を実行する能力があるか？ | H19: Teammate 技能員 | N19: レ | U19: Have you participated in RA process? If so, could you explain the RA process on your work place? 自職場の作業に関して、RAに参加したことがありますか？もしあれば、リスクアセスメントプロセスを説明してください。 | X19: In a sample of 5 teammates, at least two have participated RA process, and he/she could explain a full and accurate Risk Assessment. 任意選択した5人の技能員のうち2人以上が、リスクアセスメントに参加したことがあり、リスクアセスメントを完全かつ正確に実施できる。
C20: 4 | D20: Teammates proposed improvements to prevent incidents (injure, occupational disease/illness, near-miss/hidden danger) and received feedback from managements. 技能員は、インシデント（労働災害、疾病、ヒヤリ、潜在的危険源）に関する改善提案を行い、管理者からフィードバックを受けている。 | E20: Action 行動 | F20: 15 | G20: Have teammates proposed improvements for @reventation of incidents (injure/near-miss/hidden danger) and management has given feedback to them? 技能員から、インシデント（労働災害・ヒヤリ・潜在的危険源）に関する改善提案があり、管理者が対策実施内容をフィードバックしているか | H20: Management 管理者 | J20: レ | K20: レ | R20: レ | S20: レ | U20: How have you respond to proposals for improvement to prevent incidents (injury, occupational disease/illness, near-miss/hidden danger) from teammates? 技能員からのインシデント（労働災害、疾病、ヒヤリ、潜在的危険源）の改善提案に対して、どのように対応していますか？ | X20: Teammates proposed improvements on incidents (injury, occupational disease/illness, near-miss/hidden danger) prevention, and received feedback from managements. 技能員は、インシデント（災害、疾病、ヒヤリ・不具合に関する改善提案を行い、管理者からFBを受けていることが確認できる。
C21: 4 | D21: Review of action plans show that teammates have been involved in the design, implementation and evaluation of safety action plans. 活動計画を検証すると、安全対策計画の設計、導入、評価について、各技能員の参加対応があることが示される。 | E21: Action 行動 | F21: 16 | G21: Are teammates involved and consulted in safety action plans? 技能員は、安全実施計画（策定）に参加し、協議を行っているか？ | H21: Management 管理者 | J21: レ | K21: レ | R21: レ | W21: Review action plans or project planning to determine if these involve consultation steps with workers 活動計画またはプロジェクト計画を検証し、技能員との協議が行われているかを判断する。 | X21: A review of the safety action plans from the most recent safety projects show teammates were involved and consulted. 直近の安全プロジェクト（安全に関する取り組み）における安全関連の活動計画を検証すると、技能員の参加対応と協議があったことが示された。
C22: 4
B23: Excellent | C23: 5 | D23: H&S risks/measures of other departments have been shared at the safety meeting in your department. 自部署内の安全衛生会議等で、他部署での安全リスク/対策について共有されている | E23: Knowledge 知識 | F23: 17 | G23: Are there opportunities to share H&S risks/measures of other departments at the safety meeting in your department? 他部署での安全リスク/対策を共有する場があるか (自部署内の安全衛生会議などで) | H23: Teammate 技能員 | N23: レ | W23: Review the safety meeting material and minutes 会議資料や議事録を確認する。 | X23: H&S risks/measures of other departments have been shared at the safety meeting in your department. 自部署内の安全衛生会議等で、他部署での安全リスク/対策について共有されている.
C24: 5 | D24: Teammates are encouraged to talk with other teams and speak about H&S risks regularly to share best-practices and lessons-learned. 各従業員は、他のチームメンバー（他部署・他工程）と話し合うように奨励され、安全衛生関連のリスクについて定期的な話し合いを持ち、ベストプラクティスや教訓を共有している。 | E24: Capability 能力 | F24: 18 | G24: Do teammates know safety related information (H&S risk, recurrence prevention measures issued by GBS/SBU, etc.) shared among teams (department/areas) and plants? 部署間/工場間で共有された安全関連の情報（安全リスク、類災対策、GBS/SBUからの展開施策 等）を把握しているか？ | H24: Management 管理者 | J24: レ | K24: レ | R24: レ | S24: レ | U24: How is safety knowledge shared between teams and plants? 部署間と工場間で安全関連の知識をどのように共有していますか。 | X24: In a sample of 3 managers, 2 could explain how teams (departments/areas) share safety knowledge about H&S risks and risk mitigation with other teams and different sites. 任意選択した3人の管理者のうち2人が、安全衛生関連のリスクとリスク低減に関する安全関連情報を他のチームや別の現場とどのように共有するかを説明できた。
C25: 5 | D25: The site safety department communicates their best-practices in risk control with other plants to ensure cross-company learning and awareness. 現場の安全担当課は、リスク管理のベストプラクティスを他の工場にも伝達し、全社的な学習と意識向上を図っている。 | E25: Knowledge 知識 | F25: 19 | G25: Do you have opportunities to get *best practices from internal/external sources, and do you implement them in the plant? 社内外の*ベストプラクティス情報を入手する機会があり、自拠点への導入を行っているか？ | H25: Safety Manager 安全担当課長 | R25: レ | W25: Review what best-practices have been communicated and how well these were implemented どのようなベスト・プラクティスが伝達され、どのように実施されたかを検証する。 | X25: A review of the safety processes shows that H&S team has implemented best practices from other sites and these have yielded positive results. 安全関連プロセス(標準)を検証すると、安全衛生管理チームが他の現場のベストプラクティスを導入し、肯定的な結果を得たことを示している。
C26: 5 | D26: Interview statements and site tour(s) indicate that unsafe behavior is perceived as unacceptable. It is that anyone acting unsafe will be corrected by their peers. 面談調査と現場見学で、不安全行動は容認不可と認識されていることが示される。不安全行動をすると、同僚から指摘される。 | E26: Action 行動 | F26: 20 | G26: Is unsafe behavior completely unacceptable on site? 事業所において、不安全行動は、例外なく、容認されていないか？ | H26: Teammate 技能員 | N26: レ | U26: What response would you expect from your colleague when you act unsafe? あなたが不安全行動をした場合、あなたの同僚はどのような反応をすると期待しますか。 | X26: A sample of 5 operators all stated that unsafe behavior is unacceptable and anyone acting unsafe will be corrected by their peers. 任意選択した5人の技能員の全員が、不安全行動は容認できないと述べ、不安全行動をとる者は同僚によって指摘されると述べた。
C27: 5
I28: =COUNTA(I3:I27) -> 1 | J28: =COUNTA(J3:J27) -> 4 | K28: =COUNTA(K3:K27) -> 4 | L28: =COUNTA(L3:L27) -> 2 | M28: =COUNTA(M3:M27) -> 0 | N28: =COUNTA(N3:N27) -> 13 | O28: =COUNTA(O3:O27) -> 0 | P28: =COUNTA(P3:P27) -> 0 | ... T28: =COUNTA(T3:T27) -> 0
D29: *Best practice includes information gathered from other plants or external companies. The items which were already standardized are excluded. (E.g. Engineering/recurrence prevention measures defined in the international standard or SBU standard)
D30: *ベストプラクティスには、他工場や他社から入手した好事例が含まれる。但し、既に標準化/規格化/要領化された内容を除く。（例：国際規格やSBU規格に規定されている設備対策・類災対策）
D31: *Incidents: lost-time-injury, fire accident, occupational disease, near-miss, recurrence prevention, etc.
D32: インシデントには、災害・出火事故・業務上疾病・ヒヤリ・類災 等を含む

Sheet Organization Checklist
D1: Criteria 基準 | E1: Element エレメント | G1: Question 質問 | H1: Interview/Check インタビュー/確認 | U1: Interview インタビュー | V1: On-Site Observation 現場確認 | W1: Documents(example) 文書確認（例） | X1: Judgement Criteria 判断基準 | Y1: Judgement 判断 | Z1: Reason 判断理由 | AA1: Remark | AB1: F-up result (Jun) by APICTC
H2: Who? | I2: Plant Manager 工場長 | J2: Production GM 製造部長 | K2: Production Manager 製造課長 | L2: Production Foreperson 主任 | M2: Production Supervisor 職長 | N2: Teammate 技能員 | O2: Maintenance Manager 保全課長 | P2: Maintenance Foreman/Supervisor 保全主任・職長 | Q2: Maintenance Staff 保全員 | R2: Safety mgr. 安全担当課長 | S2: D.P. Manager 防災担当課長 | T2: Others その他 | U2: Content
B3: Ad-hoc | C3: 1 | D3: Compliance evaluation and training records indicate that H&S training required by regulation (including safety/disaster emergency drills) has been provided to all teammates. 法令遵守状況評価と教育訓練記録から、法令に定められた安全衛生関連の教育訓練（安全・防災の緊急時対応訓練を含む）が全従業員に実施されていることが示される。 | E3: Information 情報 | F3: 1 | G3: Is the legally required H&S training (including safety/disaster emergency drills) given to all teammates? 法令で要求される安全衛生教育（安全・防災の緊急時対応訓練を含む）は、全ての従業員に実施されているか？ | H3: Safety Manager 安全担当課長 | R3: レ | W3: Review local requirements and training records (including safety/disaster emergency drills)to see if a sample of teammates are properly trained. 現地のコンプライアンス記録と教育訓練記録を検証して、任意選択した従業員に適切な教育訓練が提供されているかを確認する。 | X3: A review of the most recent training records show that a sample of 10 randomly selected teammates (regardless of rank) have all received the H&S training (including safety/disaster emergency drills) required by regulation. 直近の教育訓練記録を検証すると、無作為に選択した10人（職位無視）の全員が、法的に必要な安全衛生関連の訓練（安全・防災の緊急時対応訓練を含む）を受けていた。
C4: 1 | D4: Incidents (injury, occupational disease/illness, near-miss, hidden danger) defects are communicated to management and they are encouraged to follow-up. インシデント（労働災害、疾病、ヒヤリ、潜在的危険源）情報は、フォローアップのための推奨事項とともに管理者に伝達されている。 | E4: Communication コミュニケーション | F4: 2 | G4: Do teammates communicate injuries/near-misses/defects to managers, and does management follow-up on them? 管理者は、災害/ヒヤリ/不具合情報を技能員から入手し、フォローアップしているか？ | H4: Management 管理者 | J4: レ | K4: レ | R4: レ | S4: レ | U4: How are you informed of incidents (injuries, near-misses, hidden dangers, etc.,) and what sort of follow-up process do you follow? 自身のプロセスに重要な安全衛生管理リスク（労働災害、ヒヤリ、潜在的危険源）について、どのように情報を得ていますか。 | X4: A sample of 3 managers can all show items recently reported to them and the examples of follow-ups associated with the reports. 任意選択した3人の管理者の全員が、最近報告された内容とそのフォローアップ活動の例を示すことができる。
C5: 1 | D5: Teammates are made aware of the function of safety controls through passive communication channels such as notice boards and e-mails 掲示板やメールなどの受動的な連絡手段を通じて、安全管理の機能を従業員に周知している。 | E5: Communication コミュニケーション | F5: 3 | G5: Is passive communication, such as notification boards and e-mails, being used to convey safety information? 安全管理を周知するための受動的なコミュニケーション（例：掲示物・メールによる展開）は、使用されているか？ | H5: Safety Manager 安全担当課長 | R5: レ | U5: Is passive communication, such as notification boards and e-mails, being used to convey safety information to Teammates? 従業員に自身の安全管理項目を理解させるために、どのような手段を用いていますか。（例：掲示板、メールによる展開） | X5: The H&S manager informs teammates of up to date safety information by notice boards, via emails, or other relevant passive communication system on site. 安全担当課長は、安全関連の最新情報について、掲示板やメール送信等を用いて展開している。
C6: 1 | D6: Roles and responsibilities of safety activities set out, and they are understood by those required to fulfil them 安全活動の役割と責任が明確になっており、その責任を負う者が理解している。 | E6: Participation 参加 | F6: 4 | G6: Does management have defined roles and responsibilities for safety activities? 管理者は、自部署の安全活動の担当者の役割を明確にし、任命しているか？ | H6: Management 管理者 | I6: レ | J6: レ | K6: レ | R6: レ | S6: レ | U6: How do you ensure H&S roles and responsibilities are effectively allocated? 安全衛生管理の役割と責任が効果的に割り当てられていることをどのように確認していますか。 | X6: A sample of 3 managers could all explain their roles and responsibilities on safety activity in their department/section/area. 任意選択した3人の管理者の全員が、自部署の安全活動担当者について役割・活動内容を説明できる。
C7: 1
B8: Reactive | C8: 2 | D8: Incident(injury, fire occupational disease/illness, near-miss, hidden danger)investigations are conducted by qualified people and the identified causes are included in the risk tracking as to-be-controlled risks インシデント（労働災害、疾病、ヒヤリおよび潜在的危険源、類災報告）調査は知識・能力を有した者(安全担当、SE等）が実施し、特定された原因は管理すべきリスクとしてリスク登録簿に登録されている。 | E8: Information 情報 | F8: 5 | G8: Are incident investigations carried out by qualified people? 災害調査は、知識・能力をもった者が実施しているか？ | H8: Safety Manager 安全担当課長 | R8: レ | W8: Review the risk and incident records to identify their correspondence リスク記録とインシデント記録を検証して、相互に対応しているかを確認する。 | X8: A review of the incident records show the last 5 incidents were investigated by qualified people, and the causes were identified and added to the risk tracking. インシデント記録（労働災害、疾病、ヒヤリ、潜在的危険源）を検証すると、直近5件のインシデントが知識・能力を有した者によって調査され、原因を特定し、リスク登録簿に追加されていた。
C9: 2 | D9: H and S activities are observed/reviewed by management for results and activities have the opportunity for continuous improvement about the lagging performance indication (e.g. # of injury, frequency rate, etc.) . 安全衛生活動は管理者によるレビューによって結果系指標（例：災害件数、災害度数率等）の継続的改善を行う機会を与えられている。 | E9: Communication コミュニケーション | F9: 6 | G9: Does management know what safety initiatives are active on site and how they are performing, and impact on the site's lagging indicators? 管理者は、現場でどの安全の取り組みが有効で、どのように実行されているか、把握しているか？ | H9: Management 管理者 | I9: レ | J9: レ | K9: レ | R9: レ | S9: レ | U9: What current safety initiatives are active, and have they resulted in improving lagging indicator performance? 直近の安全衛生管理の取り組みは、どのような成果がありましたか。 また、進捗が遅れている取り組みに対してどのような対応を行いましたか。 | X9: A sample of 3 managers could all describe the most recent H&S initiatives to improve H&S management on site, and knew if the results were positive or negative. 任意選択した3人の管理者の全員が、現場の安全衛生管理改善を目的とした直近の安全衛生の取り組みを説明でき、結果の良し悪しを知っていた。
C10: 2 | D10: Management and the H&S team collaborate to prevent reoccurrence of accidents by addressing the causation of these accidents 管理者と安全担当課が協力して、事故の因果関係を調査し、再発防止に取り組んでいる。 | E10: Participation 参加 | F10: 7 | G10: Is there collaboration between H&S and management to address recurring incidents, with focus on causation? 再発防止において、安全機能と管理者は連携しているか？ | H10: Management 管理者 | I10: レ | J10: レ | K10: レ | R10: レ | S10: レ | W10: Review incident records to determine how management and H&S collaborate, and how well causes are identified and mitigated. リスク記録とインシデント記録を検証して、管理職と安全管理部門がどのように協力して原因へ対応しているかを確認する。 | X10: A review of the incident(injury, occupational disease/illness, near-miss, hidden danger)records from the last month show evidence that the H&S team and management collaborate, and identify the causes and address the countermeasures to prevent the recurrence of incidents. 前月のインシデント（労働災害、疾病、ヒヤリ、潜在的危険源）記録を検証すると、安全担当課と管理者が協力してインシデント（労働災害、疾病、ヒヤリ、潜在的危険源）の再発防止に向け、原因を特定し、対応が実施されていることが示される。
C11: 2 | D11: Safety training for newcomers includes reference to *frequent incidents(injury, occupational disease/illness, near-miss, hidden danger)and severe risks to ensure teammates understand these and corresponding controls. *Frequent incident means that same incident is re-occurring 入社時の安全教育には頻発インシデント（労働災害、疾病、ヒヤリ、潜在的危険源）や重大リスクが含まれており、その内容と当該管理項目を従業員が確実に理解できるようにしている。 | E11: Participation 参加 | F11: 8 | G11: Do safety training sessions for newcomers reference relevant frequent incidents and risks? 安全教育において、よく発生する関連災害やリスクが参照されているか？ | H11: Safety Manager 安全担当課長 | R11: レ | V11: Request to attend such training to determine if relevant incidents are addressed インシデントに対して対応されていることを確認するため、当該教育訓練への参加許可を要請する。 | X11: During the attended training session, the safety training referred to frequent incidents and severe risks, and the controls in place to prevent reoccurrence of them. 出席した安全教育訓練では、頻繁に発生するインシデント（労働災害、疾病、ヒヤリ、潜在的危険源）と重大リスク、その管理事項などを対象としていた。
C12: 2
B13: Standardized | C13: 3 | D13: The H&S team, teammates and their supervisors evaluate the design, implementation and effectiveness of current safety rules in order to optimize these 安全担当課、技能員、監督者は、現在の安全ルールの内容、導入状況、有効性を評価し、最適化を図っている。 | E13: Information 情報 | F13: 9 | G13: Are current Safety rule's effectiveness being evaluated by a team? 現在の安全管理ルールの有効性が、各部署で評価されているか？ | H13: Safety Manager 安全担当課長 | R13: レ | U13: How is the effectiveness of H&S rules evaluated? Are Teammates, Supervisors and H&S involved with the evaluations? 安全ルールの有効性をどのように評価していますか。 またそれらの評価に技能員は関与していますか？ | X13: The H&S manager could describe how the H&S rule's effectiveness is evaluated, who is involved in the evaluation process and how the processes are improved after evaluation. Further, the evaluation includes input by Teammates & Supervisors, along with H&S. 安全担当課長は、安全ルールの有効性の評価方法、評価担当者の氏名、評価後のプロセス改善方法を説明できる。またそれらの評価に安全担当課や技能員の意見が反映されている。
C14: 3 | D14: Interview statements indicate that teammates know who to report to in order to fulfil their H&S/DP relevant responsibilities 面談調査で、従業員は各自の安全衛生や防災に関連する義務事項を果たすための報告すべき相手を知っていることが示される。 | E14: Communication コミュニケーション | F14: 10 | G14: Do teammates know who to speak to about H&S/DP and how the reporting structure works? 技能員は、安全衛生や防災について誰に報告すべきか、また、報告の仕組みを理解しているか？ | H14: Teammate 技能員 | N14: レ | U14: When safety/disaster issue X would occur, who would you logically talk to? 安全・防災上の課題Xが発生した場合、必然的に対話する相手は誰ですか。 | X14: A sample of 5 teammates could all explain who they would report specific safety/disaster issues to. 任意選択した5名の従業員の全員が、安全・防災関連の特定の課題を誰に報告するかについて説明できた。
C15: 3 | D15: Specific safety trainings are repeated at a standard interval to ensure the competence of people working on site. There are mandatory training requirements for each activity. 現場で働く人々の能力を確保するため、特定の安全教育訓練が標準化された間隔で繰り返されている。各作業について必須の教育訓練要件がある。 | E15: Information 情報 | F15: 11 | G15: Is there a skill matrix table for teammates that identifies the training requirements/needs for each job, including training dates? 能力要件表を定めており、各技能員の教育実施日や要件等について記載しているか？ | H15: Production Foreman 製造主任 | L15: レ | W15: Review the skill matrix table for teammates and training dates. 能力要件表と教育の実施日を確認する。 | X15: There are mandatory training requirements for each activity. Specific safety trainings are repeated at a standard interval to ensure the competence of people working on site and ensure compliance with local and SBU requirements. 必須の教育訓練要件が定められており、安全教育訓練が標準化された間隔で繰り返し実施されていることを確認できた。 | AB15: Not yet
C16: 3 | D16: Safety procedures are periodically reviewed to identify opportunities for improvement. This is often done by the H&S team and the line-managers involved in the specific safety processes. すべての安全プログラム(実施事項)は定期的に見直しがあり、改善できるようになっている。多くの場合、安全担当課と特定の安全プログラム(実施事項)に対応する製造課長がこの作業を実施する。 | E16: Participation 参加 | F16: 12 | G16: Are all safety programs reviewed periodically? 全ての安全プログラムは、年に1回、レビューされているか？ | H16: Safety Manager 安全担当課長 | R16: レ | V16: Request to attend such a review to determine if the involved parties reach good results. If unable to attend (e.g., such meeting doesn't occur while conducting the SMA (validation), then review any meeting notes or other documents that resulted from such meeting. 関係者が良好な結果を得ているかどうかを確認するため、検討会議への出席許可を要請する。 調査中にそれらの会議が開催されないなどして参加が困難な場合は、会議の議事録や出席表などを参照することで評価することとする。 | X16: During the attended safety review meeting, or review of meeting minutes if SMA Assessor is unable to attend such meeting, (H&S team and line leaders in attendance), improvement areas were discussed and action plans put in place. 出席した安全検討会議（安全担当課と課長・主任・職長らが出席）では、改善点を討議し、活動計画を策定していた。出席できない場合は、議事録でそれらの活動が行われていることが確認できた。
C17: 3 | D17: Forepersons/supervisors understand the system and scope of management of changes(4M changes) 4M変更管理の仕組み・対象について理解している。 | E17: Communication コミュニケーション | F17: 13 | G17: Is there a system on management of changes? 変更に関する管理の仕組みはありますか？ | H17: Supervisors 監督者 | L17: レ | M17: レ | U17: What is a contents of system and scope for management of change? 4M変更時のシステムとスコープは何ですか？ | X17: A sample of 3 supervisors all explained system and scope of management of change(4M changes). 任意選択した3人の監督者の全員が、４M変更管理の仕組み・対象について説明できた。 | AB17: Not yet
C18: 3
B19: Proactive | C19: 4 | D19: Prior to a change in process or equipment, are the risks associated with the change reviewed, evaluated and communicated with H&S team. 作業や設備の変更の前に、変更に関連したリスクは安全担当課とレビュー・評価を行っている。 | E19: Communication コミュニケーション | F19: 14 | G19: Do management and process owners communicate with H&S team about upcoming changes on site, along with any risks associated with the change? 管理者と監督者は、職場の予定された変更とそれに伴うリスクに関して、安全衛生担当課と話し合っていますか？ | H19: Supervisors 監督者 | L19: レ | M19: レ | U19: How and when do you involve the H&S team in discussions regarding planned changes in your process, along with any risks associated with the planned change? あなたはリスクの変化を伴う作業方法や工程の変更（4M変更）時に、安全担当課をいつ、どのようにそれらに関する議論に参加させていますか。 | X19: A sample of 3 supervisors all confirmed that they discuss with the H&S team the risks associated with upcoming changes to work processes. 任意選択した3人の監督者の全員が、作業工程の変更時、新規の作業が発生する際には、安全担当課とリスクと対応方法について討議したことを示した。
C20: 4 | D20: Safety instructions and trainings have been integrated into regular job-related training which is provided to teammates before they start the associated work. 安全に関する指示と教育訓練は通常の業務関連の教育訓練に統合されて、技能員が関連作業を開始する前に実施されている。 | E20: Information 情報 | F20: 15 | G20: Do work/job specific trainings highlight safety risks and processes associated with that work/job? 作業訓練において、関連する安全上のリスクや作業手順について、強調されているか？ | H20: Production Supervisor 製造主任 | L20: レ | W20: Review work/job specific training materials 作業訓練資料を確認する | X20: Safety instructions and safety training were included in the work specific training materials. 特定作業の教育訓練において、教育資料には、安全関連の指示事項と安全教育訓練が含まれていた。
C21: 4 | D21: Safety procedures and processes are reviewed at regular intervals by those involved, and revisions are made based upon relevant findings. 安全プロセス（要領等）は関係者によって定期的に見直しが行われ、当該指摘事項を含めることによって改善されている。 | E21: Participation 参加 | F21: 16 | G21: Are safety procedures and processes frequency reviewed and updated using findings from the review? 安全手順は、頻繁に見直され、見直し結果をもとに、改善されているか？ | H21: Safety Manager 安全担当課長 | R21: レ | U21: What was the feedback/follow-up you received from management on any incidents (injury, occupational disease/illness, near-miss, hidden danger) you reported? あなたがインシデント（労働災害、疾病、ヒヤリ、潜在的危険源）を報告をした場合、管理者からどのようなフィードバックやフォローアップがありましたか。 | W21: Review the document history of H&S procedures and standards 安全衛生関連の手順書と標準書の改訂記録を検証する。 | X21: A review of the document history from the last year showed where H&S procedures and safety processes had been evaluated and changed/updated by those involved as needed to address newly identified risks and controls. 前年以降の文書改訂履歴を検証すると、新たなリスクや課題について、必要とされる関係者によって、安全衛生管理手順と安全プロセスが変更または発展したことが示された。
C22: 4 | D22: Risk records indicate that hazards/injury/near-miss/defects reported are used by management to take actions and the result of these actions are communicated with the reporter. リスク記録では、危険状況/災害/ヒヤリ/不具合情報が報告された場合には管理部門がその情報を使用し、対応結果が報告者に通知されていることが示される。 | E22: Communication コミュニケーション | F22: 17 | G22: Does management take action when a hazard/injury/near-miss/defects is reported, and communicate these action to the reporter? 管理者は、危険源/災害/ヒヤリ/不具合情報が報告された際、対処しているか？また、対処結果を報告書へフィードバックしているか？ | H22: Teammate 技能員 | N22: レ | U22: What measures did the management take in response to the information you or your colleague reported? And what means was this feedback provided to you? あなたもしくは同僚が報告した不具合情報に対して、管理者はどのような対応を実施しましたか。またそれをどのような手段であなたにフィードバックされましたか。 | X22: A sample of 5 teammates all stated that management had taken specific actions to address hazards they reported, and these actions have been communicated to them 任意選択した5人の技能員の全員が、自分たちが報告した危険状況に対して、管理者が特定の対応措置を実施し、その件について自分たちに報告があったと述べた。
C23: 4
B24: Excellence | C24: 5 | D24: Teammates and managers are mindful of the need for safety, not only for themselves but also for others. Teammates and managers have a genuine concern for one another; a CFT approach is used to review and address safety issues. 技能員と管理者は自分だけでなく他者の安全にも配慮することを意識している。安全ルールの順守やリスクの改善活動は小集団・CFTで実施されている。 | E24: Participation 参加 | F24: 18 | G24: Do teammates and managers have a genuine concern for themselves and one another? When there are safety relates issues, is a CFT approach taken to resolving them? 技能員や管理者は、自身や同僚をお互いに危険に曝さぬように意識しているか？ 安全に関する問題が発生した場合、CFTによる解決への方策が図られているか？ | H24: Teammate 技能員 | N24: レ | V24: Assess 3 work areas to see if workers show consideration towards their safety and others 3か所以上の作業区域を評価し、技能員が自身および他者の安全に配慮しているか確認する。 | W24: Near Miss Reports Behavior Observation System (BOS) execution by leaders. Incident Reports and Investigation ニアミス報告書。 指導者（課長・主任・職長）による安全行動観察(モニタリング）の実施状況。 インシデントレポート（報告書）と調査状況。 | X24: A tour of 3 work areas showed that teammates are actively conscious of their safety and the safety of others. Activities for improvement were conducted in CFT being conscious of safety for not only their selves, but also teammates. 3か所以上の作業区域を視察すると、社員が自身の安全と他者の安全を積極的に意識していることが示された。改善活動は、自分だけでなく他者の安全を意識し、小集団・CFTで実施されている | AA24: Same as item 76 of system check sheet & item 10 of teammage engagement sheet
C25: 5 | D25: Line managers are actively engaging with *external parties to obtain knowledge on how they have controlled their risks and exchange knowledge on safety processes regularly. *External includes other company, SBU, other plants in BS 製造課長は*外部の関係者と積極的に連携し、リスク管理方法に関する情報を入手し、安全プロセスについて情報交換を定期的に行っている。 *外部には他社、SBU、他工場を含む | E25: Participation 参加 | F25: 19 | G25: Do line managers engage with external parties about safety? 管理者（工場長・部長・課長）は、安全の外部団体に参加しているか？ | H25: Management 管理者 | I25: レ | J25: レ | K25: レ | R25: レ | S25: レ | U25: How do you keep yourself informed on safety relevant developments? Do you engage in exchange of safety information and best practices/benchmarking with others outside your site (e.g., other BS sites, other companies, etc.)? 安全関連の当該最新情報をどのように得ていますか。 安全に関するベストプラクティスやベンチマークを社外や他のBSの拠点と交換していますか。 | X25: With a sample of 3 managers, at least 1 said they voluntarily discussed safety with managers from other sites or *external parties to improve safety knowledge. *External includes other company, SBU, other plants in BS 任意選択した3人の管理者の1人以上が、安全関連の知識を向上するため、自発的に他の現場や*外部の管理者と安全について討議したと述べた。 *外部には他社、SBU、他工場を含む
