Workbook

Sheet Safety Report
X1: Issue:
W2: Date:
B3: Safety Solidification Report
B4: Site | G4: Date
B6: QM foundation (management system) 3 axes
C8: Items | J8: 2025 | L8: 2028 | O8: 3 Axes Chart
J9: Score | K9: Level | L9: Score | M9: Level
I10: Total Avg | J10: =Cal!D47 -> 4.8333333 | K10: =IF(J10<2,"C",IF(J10<3,"B-",IF(J10<4,"B",IF(J10<5,"B+",IF(J10=5,"A",""))))) -> B+
D11: 3 Axes Evaluation | E11: Risk Detection and Reduction/Continuous Improvement | H11: Avg | J11: =Cal!D46 -> 4.5 | K11: =IF(J11=5,"A",IF(J11>=4,"B+",IF(J11>=3,"B",IF(J11>=2,"B-",IF(J11>=1, "C","-"))))) -> B+
H12: Distribution | I12: B+ or more | J12: =Cal!E61 -> 7
I13: B | J13: =Cal!E62 -> 0
I14: B- | J14: =Cal!E63 -> 0
I15: C | J15: =Cal!E64 -> 1
E16: Safety Rule Compliance/Safety Awareness Cultivation | H16: Avg | J16: =Cal!D44 -> 5 | K16: =IF(J16=5,"A",IF(J16>=4,"B+",IF(J16>=3,"B",IF(J16>=2,"B-",IF(J16>=1, "C","-"))))) -> A
H17: Distribution | I17: B+ or more | J17: =Cal!E67 -> 5
I18: B | J18: =Cal!E68 -> 0 | O18: Distribution
I19: B- | J19: =Cal!E69 -> 0 | O19: Risk | Q19: 2028
I20: C | J20: =Cal!E70 -> 0 | Q20: 2025
E21: Strengthening of Governance and Systems to Make Quality Management More Effective | H21: Avg | J21: =Cal!D45 -> 5 | K21: =IF(J21=5,"A",IF(J21>=4,"B+",IF(J21>=3,"B",IF(J21>=2,"B-",IF(J21>=1, "C","-"))))) -> A | O21: Compliance | Q21: 2028
H22: Distribution | I22: B+ or more | J22: =Cal!E73 -> 15 | Q22: 2025
I23: B | J23: =Cal!E74 -> 0 | O23: Governance | Q23: 2028
I24: B- | J24: =Cal!E75 -> 0 | Q24: 2025
I25: C | J25: =Cal!E76 -> 0
B27: QM foundation (management system) 5 axes
C29: Solidification 5 items | F29: 2025 | J29: 2028 | O29: Ave Score | T29: Min Score
F30: Avg | H30: Min | J30: Avg | L30: Min
F31: Score | G31: Level | H31: Score | I31: Level | J31: Score | K31: Level | L31: Score | M31: Level
C32: Issue solving | F32: =Cal!$E52 -> 4 | G32: =IF(F32<2,"C",IF(F32<3,"B-",IF(F32<4,"B",IF(F32<5,"B+",IF(F32=5,"A",""))))) -> B+ | H32: =Cal!$D52 -> 1 | I32: =IF(H32<2,"C",IF(H32<3,"B-",IF(H32<4,"B",IF(H32<5,"B+",IF(H32=5,"A",""))))) -> C
C33: Risk Management | F33: =Cal!$E53 -> 5 | G33: =IF(F33<2,"C",IF(F33<3,"B-",IF(F33<4,"B",IF(F33<5,"B+",IF(F33=5,"A",""))))) -> A | H33: =Cal!$D53 -> 5 | I33: =IF(H33<2,"C",IF(H33<3,"B-",IF(H33<4,"B",IF(H33<5,"B+",IF(H33=5,"A",""))))) -> A
C34: Business Strategy Adjustment | F34: =Cal!$E54 -> 5 | G34: =IF(F34<2,"C",IF(F34<3,"B-",IF(F34<4,"B",IF(F34<5,"B+",IF(F34=5,"A",""))))) -> A | H34: =Cal!$D54 -> 5 | I34: =IF(H34<2,"C",IF(H34<3,"B-",IF(H34<4,"B",IF(H34<5,"B+",IF(H34=5,"A",""))))) -> A
C35: Independency and Continuity | F35: =Cal!$E55 -> 5 | G35: =IF(F35<2,"C",IF(F35<3,"B-",IF(F35<4,"B",IF(F35<5,"B+",IF(F35=5,"A",""))))) -> A | H35: =Cal!$D55 -> 5 | I35: =IF(H35<2,"C",IF(H35<3,"B-",IF(H35<4,"B",IF(H35<5,"B+",IF(H35=5,"A",""))))) -> A
C36: Integration/ Incorporation | F36: =Cal!$E56 -> 5 | G36: =IF(F36<2,"C",IF(F36<3,"B-",IF(F36<4,"B",IF(F36<5,"B+",IF(F36=5,"A",""))))) -> A | H36: =Cal!$D56 -> 5 | I36: =IF(H36<2,"C",IF(H36<3,"B-",IF(H36<4,"B",IF(H36<5,"B+",IF(H36=5,"A",""))))) -> A
C38: Total | F38: =AVERAGE(F32:F36) -> 4.8 | G38: =IF(F38<2,"C",IF(F38<3,"B-",IF(F38<4,"B",IF(F38<5,"B+",IF(F38=5,"A",""))))) -> B+ | H38: =AVERAGE(H32:H36) -> 4.2 | I38: =IF(H38<2,"C",IF(H38<3,"B-",IF(H38<4,"B",IF(H38<5,"B+",IF(H38=5,"A",""))))) -> B+
B40: Comment

Sheet (ref.) Safety Cover
B3: Safety Solidification Report
B4: Site | G4: Date
B6: QM foundation (management system) 3 axes
C8: Items | J8: 2025 | L8: 2024 | O8: 3 Axes Chart
J9: Score | L9: Score
I10: Total Ave | J10: ='(ref.) Cal'!E43 -> #REF! | K10: =IF(J10<2,"C",IF(J10<3,"B-",IF(J10<4,"B",IF(J10<5,"B+",IF(J10=5,"A",""))))) -> #REF! | L10: ='(ref.) Cal'!D43 -> #N/A | M10: =IF(L10=5,"A",IF(L10>=4,"B+",IF(L10>=3,"B",IF(L10>=2,"B-",IF(L10>=1, "C","-"))))) -> #N/A
D11: 3 Axes Evaluation | E11: Risk Detection and Reduction/Continuous Improvement | H11: Ave | J11: ='(ref.) Cal'!E42 -> #REF! | K11: =IF(J11=5,"A",IF(J11>=4,"B+",IF(J11>=3,"B",IF(J11>=2,"B-",IF(J11>=1, "C","-"))))) -> #REF! | L11: ='(ref.) Cal'!D42 -> #N/A | M11: =IF(L11=5,"A",IF(L11>=4,"B+",IF(L11>=3,"B",IF(L11>=2,"B-",IF(L11>=1, "C","-"))))) -> #N/A
H12: Distribution | I12: B+ or more | J12: ='(ref.) Cal'!F57 -> 7 | L12: ='(ref.) Cal'!E57 -> 0
I13: B | J13: ='(ref.) Cal'!F58 -> 0 | L13: ='(ref.) Cal'!E58 -> 0
I14: B- | J14: ='(ref.) Cal'!F59 -> 0 | L14: ='(ref.) Cal'!E59 -> 0
I15: C | J15: ='(ref.) Cal'!F60 -> 1 | L15: ='(ref.) Cal'!E60 -> 0
E16: Safety Rule Compliance/Safety Awareness Cultivation | H16: Ave | J16: ='(ref.) Cal'!E40 -> 5 | K16: =IF(J16=5,"A",IF(J16>=4,"B+",IF(J16>=3,"B",IF(J16>=2,"B-",IF(J16>=1, "C","-"))))) -> A | L16: ='(ref.) Cal'!D40 -> #N/A | M16: =IF(L16=5,"A",IF(L16>=4,"B+",IF(L16>=3,"B",IF(L16>=2,"B-",IF(L16>=1, "C","-"))))) -> #N/A
H17: Distribution | I17: B+ or more | J17: ='(ref.) Cal'!F63 -> 5 | L17: ='(ref.) Cal'!E63 -> 0
I18: B | J18: ='(ref.) Cal'!F64 -> 0 | L18: ='(ref.) Cal'!E64 -> 0 | O18: Distribution
I19: B- | J19: ='(ref.) Cal'!F65 -> 0 | L19: ='(ref.) Cal'!E65 -> 0 | O19: Risk | Q19: 2025
I20: C | J20: ='(ref.) Cal'!F66 -> 0 | L20: ='(ref.) Cal'!E66 -> 0 | Q20: 2024
E21: Strengthening of Governance and Systems to Make Quality Management More Effective | H21: Ave | J21: ='(ref.) Cal'!E41 -> 5 | K21: =IF(J21=5,"A",IF(J21>=4,"B+",IF(J21>=3,"B",IF(J21>=2,"B-",IF(J21>=1, "C","-"))))) -> A | L21: ='(ref.) Cal'!D41 -> #N/A | M21: =IF(L21=5,"A",IF(L21>=4,"B+",IF(L21>=3,"B",IF(L21>=2,"B-",IF(L21>=1, "C","-"))))) -> #N/A | O21: Compliance | Q21: 2025
H22: Distribution | I22: B+ or more | J22: ='(ref.) Cal'!F69 -> 12 | L22: ='(ref.) Cal'!E69 -> 0 | Q22: 2024
I23: B | J23: ='(ref.) Cal'!F70 -> 0 | L23: ='(ref.) Cal'!E70 -> 0 | O23: Governance | Q23: 2025
I24: B- | J24: ='(ref.) Cal'!F71 -> 0 | L24: ='(ref.) Cal'!E71 -> 0 | Q24: 2024
I25: C | J25: ='(ref.) Cal'!F72 -> 0 | L25: ='(ref.) Cal'!E72 -> 0
B27: QM foundation (management system) 5 axes
C29: Solidification 5 items | F29: 2025 | J29: 2024 | O29: Ave Score | T29: Min Score
F30: Ave | H30: Min | J30: Ave | L30: Min
F31: Score | H31: Score | J31: Score | L31: Score
C32: Issue solving | F32: ='(ref.) Cal'!G48 -> 4 | G32: =IF(F32<2,"C",IF(F32<3,"B-",IF(F32<4,"B",IF(F32<5,"B+",IF(F32=5,"A",""))))) -> B+ | H32: ='(ref.) Cal'!F48 -> 1 | I32: =IF(H32<2,"C",IF(H32<3,"B-",IF(H32<4,"B",IF(H32<5,"B+",IF(H32=5,"A",""))))) -> C | J32: ='(ref.) Cal'!E48 -> #N/A | K32: =IF(J32<2,"C",IF(J32<3,"B-",IF(J32<4,"B",IF(J32<5,"B+",IF(J32=5,"A",""))))) -> #N/A | L32: ='(ref.) Cal'!D48 -> #N/A | M32: =IF(L32<2,"C",IF(L32<3,"B-",IF(L32<4,"B",IF(L32<5,"B+",IF(L32=5,"A",""))))) -> #N/A
C33: Risk Management | F33: ='(ref.) Cal'!G49 -> 5 | G33: =IF(F33<2,"C",IF(F33<3,"B-",IF(F33<4,"B",IF(F33<5,"B+",IF(F33=5,"A",""))))) -> A | H33: ='(ref.) Cal'!F49 -> 5 | I33: =IF(H33<2,"C",IF(H33<3,"B-",IF(H33<4,"B",IF(H33<5,"B+",IF(H33=5,"A",""))))) -> A | J33: ='(ref.) Cal'!E49 -> #N/A | K33: =IF(J33<2,"C",IF(J33<3,"B-",IF(J33<4,"B",IF(J33<5,"B+",IF(J33=5,"A",""))))) -> #N/A | L33: ='(ref.) Cal'!D49 -> #N/A | M33: =IF(L33<2,"C",IF(L33<3,"B-",IF(L33<4,"B",IF(L33<5,"B+",IF(L33=5,"A",""))))) -> #N/A
C34: Business Strategy Adjustment | F34: ='(ref.) Cal'!G50 -> 5 | G34: =IF(F34<2,"C",IF(F34<3,"B-",IF(F34<4,"B",IF(F34<5,"B+",IF(F34=5,"A",""))))) -> A | H34: ='(ref.) Cal'!F50 -> 5 | I34: =IF(H34<2,"C",IF(H34<3,"B-",IF(H34<4,"B",IF(H34<5,"B+",IF(H34=5,"A",""))))) -> A | J34: ='(ref.) Cal'!E50 -> #N/A | K34: =IF(J34<2,"C",IF(J34<3,"B-",IF(J34<4,"B",IF(J34<5,"B+",IF(J34=5,"A",""))))) -> #N/A | L34: ='(ref.) Cal'!D50 -> #N/A | M34: =IF(L34<2,"C",IF(L34<3,"B-",IF(L34<4,"B",IF(L34<5,"B+",IF(L34=5,"A",""))))) -> #N/A
C35: Independency and Continuity | F35: ='(ref.) Cal'!G51 -> #REF! | G35: =IF(F35<2,"C",IF(F35<3,"B-",IF(F35<4,"B",IF(F35<5,"B+",IF(F35=5,"A",""))))) -> #REF! | H35: ='(ref.) Cal'!F51 -> #REF! | I35: =IF(H35<2,"C",IF(H35<3,"B-",IF(H35<4,"B",IF(H35<5,"B+",IF(H35=5,"A",""))))) -> #REF! | J35: ='(ref.) Cal'!E51 -> #N/A | K35: =IF(J35<2,"C",IF(J35<3,"B-",IF(J35<4,"B",IF(J35<5,"B+",IF(J35=5,"A",""))))) -> #N/A | L35: ='(ref.) Cal'!D51 -> #N/A | M35: =IF(L35<2,"C",IF(L35<3,"B-",IF(L35<4,"B",IF(L35<5,"B+",IF(L35=5,"A",""))))) -> #N/A
C36: Integration/ Incorporation | F36: ='(ref.) Cal'!G52 -> 5 | G36: =IF(F36<2,"C",IF(F36<3,"B-",IF(F36<4,"B",IF(F36<5,"B+",IF(F36=5,"A",""))))) -> A | H36: ='(ref.) Cal'!F52 -> 5 | I36: =IF(H36<2,"C",IF(H36<3,"B-",IF(H36<4,"B",IF(H36<5,"B+",IF(H36=5,"A",""))))) -> A | J36: ='(ref.) Cal'!E52 -> #N/A | K36: =IF(J36<2,"C",IF(J36<3,"B-",IF(J36<4,"B",IF(J36<5,"B+",IF(J36=5,"A",""))))) -> #N/A | L36: ='(ref.) Cal'!D52 -> #N/A | M36: =IF(L36<2,"C",IF(L36<3,"B-",IF(L36<4,"B",IF(L36<5,"B+",IF(L36=5,"A",""))))) -> #N/A
C38: Total Ave | F38: =AVERAGE(F32:F36) -> #REF! | G38: =IF(F38<2,"C",IF(F38<3,"B-",IF(F38<4,"B",IF(F38<5,"B+",IF(F38=5,"A",""))))) -> #REF! | H38: =AVERAGE(H32:H36) -> #REF! | I38: =IF(H38<2,"C",IF(H38<3,"B-",IF(H38<4,"B",IF(H38<5,"B+",IF(H38=5,"A",""))))) -> #REF! | J38: =AVERAGE(J32:J36) -> #N/A | K38: =IF(J38<2,"C",IF(J38<3,"B-",IF(J38<4,"B",IF(J38<5,"B+",IF(J38=5,"A",""))))) -> #N/A | L38: =AVERAGE(L32:L36) -> #N/A | M38: =IF(L38<2,"C",IF(L38<3,"B-",IF(L38<4,"B",IF(L38<5,"B+",IF(L38=5,"A",""))))) -> #N/A
B40: Comment
C42: <Improvement Status from the last year's instruction> From last year, some issues found in the 2024 assessment have been improved, and at this time, we could observe some items could be more improved. <Comments from 3 axes points of view> Safety activities have been conducted and followed-up as plan by EHS team's leadership. Please promote KAIZEN improvement with use of autonomously KY, RA, etc. with reviewing the activities progress and result. Not only making periodical action plan, but we can find other points could be improved. <Risk> RIsk management have been well maintained. By comparing the reslut of RA with same machine, process, not only inside plant but other SC plant to realize what/where the risks exist, and how to reduce it. *In GENBA tour at this time, we could find some machines that have risks by using one hand swith - should have both hands swith when it is upgraded/renewed. Please see the appendix for detail. <Compliance> This area's score is lower than the other two area because of basic training leakage. (BSFA/LOTO) These kind of basic training should be periodically given to all teammates, to make them understand/remind the contents. Please make sure all training framework again. <Governance> Almost safety activities are well managed by action plan and its reviewing. For more works as BMT(plant wide), please confrim all managers understanding of safety activity - why do we need the items in action plan. And make sure of sharing management review from safety/DP point of view with all managers to understand safety safety activities result and what issues do we have.

Sheet DP Cover
B3: D.P. Solidification Report
B4: Site | G4: Date
B6: QM foundation (management system) 3 axes
C8: Items | J8: 2025 | L8: 2024 | O8: 3 Axes Chart
J9: Score | L9: Score
I10: Total Ave | J10: ='(ref.) Cal'!E81 -> 4.1666667 | K10: =IF(J10<2,"C",IF(J10<3,"B-",IF(J10<4,"B",IF(J10<5,"B+",IF(J10=5,"A",""))))) -> B+ | L10: ='(ref.) Cal'!D81 -> #REF! | M10: =IF(L10<2,"C",IF(L10<3,"B-",IF(L10<4,"B",IF(L10<5,"B+",IF(L10=5,"A",""))))) -> #REF!
D11: 3 Axes Evaluation | E11: Risk Detection and Reduction/Continuous Improvement | H11: Ave | J11: ='(ref.) Cal'!E80 -> 4 | K11: =IF(J11=5,"A",IF(J11>=4,"B+",IF(J11>=3,"B",IF(J11>=2,"B-",IF(J11>=1, "C","-"))))) -> B+ | L11: ='(ref.) Cal'!D80 -> #REF! | M11: =IF(L11=5,"A",IF(L11>=4,"B+",IF(L11>=3,"B",IF(L11>=2,"B-",IF(L11>=1, "C","-"))))) -> #REF!
H12: Distribution | I12: B+ or more | J12: ='(ref.) Cal'!F93 -> 6 | L12: ='(ref.) Cal'!E93 -> 0
I13: B | J13: ='(ref.) Cal'!F94 -> 3 | L13: ='(ref.) Cal'!E94 -> 0
I14: B- | J14: ='(ref.) Cal'!F95 -> 0 | L14: ='(ref.) Cal'!E95 -> 0
I15: C | J15: ='(ref.) Cal'!F96 -> 0 | L15: ='(ref.) Cal'!E96 -> 0
E16: Safety Rule Compliance/Safety Awareness Cultivation | H16: Ave | J16: ='(ref.) Cal'!E78 -> 4.5 | K16: =IF(J16=5,"A",IF(J16>=4,"B+",IF(J16>=3,"B",IF(J16>=2,"B-",IF(J16>=1, "C","-"))))) -> B+ | L16: ='(ref.) Cal'!D78 -> #REF! | M16: =IF(L16=5,"A",IF(L16>=4,"B+",IF(L16>=3,"B",IF(L16>=2,"B-",IF(L16>=1, "C","-"))))) -> #REF!
H17: Distribution | I17: B+ or more | J17: ='(ref.) Cal'!F99 -> 7 | L17: ='(ref.) Cal'!E99 -> 0
I18: B | J18: ='(ref.) Cal'!F100 -> 0 | L18: ='(ref.) Cal'!E100 -> 0 | O18: Distribution
I19: B- | J19: ='(ref.) Cal'!F101 -> 0 | L19: ='(ref.) Cal'!E101 -> 0 | O19: Risk | Q19: 2025
I20: C | J20: ='(ref.) Cal'!F102 -> 1 | L20: ='(ref.) Cal'!E102 -> 0 | Q20: 2024
E21: Strengthening of Governance and Systems to Make Quality Management More Effective | H21: Ave | J21: ='(ref.) Cal'!E79 -> 4 | K21: =IF(J21=5,"A",IF(J21>=4,"B+",IF(J21>=3,"B",IF(J21>=2,"B-",IF(J21>=1, "C","-"))))) -> B+ | L21: ='(ref.) Cal'!D79 -> #REF! | M21: =IF(L21=5,"A",IF(L21>=4,"B+",IF(L21>=3,"B",IF(L21>=2,"B-",IF(L21>=1, "C","-"))))) -> #REF! | O21: Compliance | Q21: 2025
H22: Distribution | I22: B+ or more | J22: ='(ref.) Cal'!F105 -> 5 | L22: ='(ref.) Cal'!E105 -> 0 | Q22: 2024
I23: B | J23: ='(ref.) Cal'!F106 -> 1 | L23: ='(ref.) Cal'!E106 -> 0 | O23: Governance | Q23: 2025
I24: B- | J24: ='(ref.) Cal'!F107 -> 0 | L24: ='(ref.) Cal'!E107 -> 0 | Q24: 2024
I25: C | J25: ='(ref.) Cal'!F108 -> 1 | L25: ='(ref.) Cal'!E108 -> 0
B27: QM foundation (management system) 5 axes
C29: Solidification 5 items | F29: 2025 | J29: 2024 | O29: Ave Score | T29: Min Score
F30: Ave | H30: Min | J30: Ave | L30: Min
F31: Score | H31: Score | J31: Score | L31: Score
C32: Issue solving | F32: ='(ref.) Cal'!G85 -> 4.6666667 | G32: =IF(F32<2,"C",IF(F32<3,"B-",IF(F32<4,"B",IF(F32<5,"B+",IF(F32=5,"A",""))))) -> B+ | H32: ='(ref.) Cal'!F85 -> 4 | I32: =IF(H32<2,"C",IF(H32<3,"B-",IF(H32<4,"B",IF(H32<5,"B+",IF(H32=5,"A",""))))) -> B+ | J32: ='(ref.) Cal'!E85 -> #REF! | K32: =IF(J32<2,"C",IF(J32<3,"B-",IF(J32<4,"B",IF(J32<5,"B+",IF(J32=5,"A",""))))) -> #REF! | L32: ='(ref.) Cal'!D85 -> #REF! | M32: =IF(L32<2,"C",IF(L32<3,"B-",IF(L32<4,"B",IF(L32<5,"B+",IF(L32=5,"A",""))))) -> #REF!
C33: Risk Management | F33: ='(ref.) Cal'!G86 -> 4 | G33: =IF(F33<2,"C",IF(F33<3,"B-",IF(F33<4,"B",IF(F33<5,"B+",IF(F33=5,"A",""))))) -> B+ | H33: ='(ref.) Cal'!F86 -> 3 | I33: =IF(H33<2,"C",IF(H33<3,"B-",IF(H33<4,"B",IF(H33<5,"B+",IF(H33=5,"A",""))))) -> B | J33: ='(ref.) Cal'!E86 -> #REF! | K33: =IF(J33<2,"C",IF(J33<3,"B-",IF(J33<4,"B",IF(J33<5,"B+",IF(J33=5,"A",""))))) -> #REF! | L33: ='(ref.) Cal'!D86 -> #REF! | M33: =IF(L33<2,"C",IF(L33<3,"B-",IF(L33<4,"B",IF(L33<5,"B+",IF(L33=5,"A",""))))) -> #REF!
C34: Business Strategy Adjustment | F34: ='(ref.) Cal'!G87 -> 4 | G34: =IF(F34<2,"C",IF(F34<3,"B-",IF(F34<4,"B",IF(F34<5,"B+",IF(F34=5,"A",""))))) -> B+ | H34: ='(ref.) Cal'!F87 -> 3 | I34: =IF(H34<2,"C",IF(H34<3,"B-",IF(H34<4,"B",IF(H34<5,"B+",IF(H34=5,"A",""))))) -> B | J34: ='(ref.) Cal'!E87 -> #REF! | K34: =IF(J34<2,"C",IF(J34<3,"B-",IF(J34<4,"B",IF(J34<5,"B+",IF(J34=5,"A",""))))) -> #REF! | L34: ='(ref.) Cal'!D87 -> #REF! | M34: =IF(L34<2,"C",IF(L34<3,"B-",IF(L34<4,"B",IF(L34<5,"B+",IF(L34=5,"A",""))))) -> #REF!
C35: Independency and Continuity | F35: ='(ref.) Cal'!G88 -> 4.4 | G35: =IF(F35<2,"C",IF(F35<3,"B-",IF(F35<4,"B",IF(F35<5,"B+",IF(F35=5,"A",""))))) -> B+ | H35: ='(ref.) Cal'!F88 -> 1 | I35: =IF(H35<2,"C",IF(H35<3,"B-",IF(H35<4,"B",IF(H35<5,"B+",IF(H35=5,"A",""))))) -> C | J35: ='(ref.) Cal'!E88 -> #REF! | K35: =IF(J35<2,"C",IF(J35<3,"B-",IF(J35<4,"B",IF(J35<5,"B+",IF(J35=5,"A",""))))) -> #REF! | L35: ='(ref.) Cal'!D88 -> #REF! | M35: =IF(L35<2,"C",IF(L35<3,"B-",IF(L35<4,"B",IF(L35<5,"B+",IF(L35=5,"A",""))))) -> #REF!
C36: Integration/ Incorporation | F36: ='(ref.) Cal'!G89 -> 3 | G36: =IF(F36<2,"C",IF(F36<3,"B-",IF(F36<4,"B",IF(F36<5,"B+",IF(F36=5,"A",""))))) -> B | H36: ='(ref.) Cal'!F89 -> 1 | I36: =IF(H36<2,"C",IF(H36<3,"B-",IF(H36<4,"B",IF(H36<5,"B+",IF(H36=5,"A",""))))) -> C | J36: ='(ref.) Cal'!E89 -> #REF! | K36: =IF(J36<2,"C",IF(J36<3,"B-",IF(J36<4,"B",IF(J36<5,"B+",IF(J36=5,"A",""))))) -> #REF! | L36: ='(ref.) Cal'!D89 -> #REF! | M36: =IF(L36<2,"C",IF(L36<3,"B-",IF(L36<4,"B",IF(L36<5,"B+",IF(L36=5,"A",""))))) -> #REF!
C38: Total Ave | F38: =AVERAGE(F32:F36) -> 4.0133333 | G38: =IF(F38<2,"C",IF(F38<3,"B-",IF(F38<4,"B",IF(F38<5,"B+",IF(F38=5,"A",""))))) -> B+ | H38: =AVERAGE(H32:H36) -> 2.4 | I38: =IF(H38<2,"C",IF(H38<3,"B-",IF(H38<4,"B",IF(H38<5,"B+",IF(H38=5,"A",""))))) -> B- | J38: =AVERAGE(J32:J36) -> #REF! | K38: =IF(J38<2,"C",IF(J38<3,"B-",IF(J38<4,"B",IF(J38<5,"B+",IF(J38=5,"A",""))))) -> #REF! | L38: =AVERAGE(L32:L36) -> #REF! | M38: =IF(L38<2,"C",IF(L38<3,"B-",IF(L38<4,"B",IF(L38<5,"B+",IF(L38=5,"A",""))))) -> #REF!
B40: Comment
C42: <Improvement Status from the last year's instruction> Total score is stable and almost good condition from DP point of view. But a few issue could be found in this assessment, please see the instruction for detail and promote more KAIZEN activity. <Comments from 3 axes points of view> From three axes point if view, BMT is in good condtion. Please keep this conditon and improve as stated in DP instruction. <Risk> All items have been validated B or more. With conducting new (BSJP tire version) Fire RA, clarify risks in workplace and promote it to reduce them. <Compliance> Almost good condtion. But we could find common fire prevention rule's understanding and its training is not good enough in the interview. Please confirm the action plan including the training based on IMD fire standard. <Governance> Almost good condition, but some manager could not state the policy/IIP/budget management strategy of BMT. Please make sure that all manager have understood it including issues from review of activities in the action plant to make sure all managers are on same page.

Sheet Safety Instruction
L1: 発行日： | M1: 45128
C2: Solidification Assessment Safety Instruction
C4: Site | D4: {='Safety Report'!D4:F4} -> 0 | E4: 0 | F4: 0 | M4: 継続：現状維持、 レベルアップ：A、B＋、Bレベルへの改善 新規：過去に指摘・提案がない
C6: Solidification 5 items | D6: Point of Evaluation | E6: Primary Categoty | F6: Secondary Categoty | G6: 3 Axes Evaluation | H6: Result | I6: 2028 Target | J6: Issues and/or Changes | K6: Instruction - Items could be Incorporated into MBP | L6: Implementation Items | M6: Category
H7: 2025 | M7: Continue | N7: Level up | O7: New
C9: Issue solving | D9: Quickness of issue solving Deep root cause analysis, standardization and implementation | E9: Cuntermeasures and Recurrence prevention | F9: Information Sharing | G9: Governance | H9: ='Safety overall result'!Z10 -> A | N9: X | R9: 情報展開 | S9: Information Sharing
F10: Recurrence Prevention | G10: Risk | H10: ='Safety overall result'!Z11 -> A | N10: X | R10: 再発防止 対策 | S10: Recurrence Prevention
F11: Injury Reporting | G11: Governance | H11: ='Safety overall result'!Z12 -> A | M11: X | R11: 災害報告 | S11: Injury Reporting
F12: Recurrence Prevention Process KPI | G12: Risk | H12: ='Safety overall result'!Z13 -> C | M12: X | R12: 類災対策 プロセスKPI | S12: Recurrence Prevention Process KPI
C13: Risk Management | D13: Symptom Management for QM defect Management and analysis of information which is explored, issued | E13: Risk Management | F13: RA Progress | G13: Risk | H13: ='Safety overall result'!Z14 -> A | M13: X | R13: RA評価推進 | S13: RA Progress
F14: Equipment RA | G14: Risk | H14: ='Safety overall result'!Z15 -> A | N14: X | R14: 設備RA プロセスKPI | S14: Equipment RA
F15: Task RA | G15: Risk | H15: ='Safety overall result'!Z16 -> A | N15: X | R15: 作業RA プロセスKPI | S15: Task RA
F16: LOTO | G16: Compliance | H16: ='Safety overall result'!Z17 -> A | N16: X | R16: LOTO 運用徹底 | S16: LOTO
F17: LOTO management | G17: Compliance | H17: ='Safety overall result'!Z18 -> A
F18: Contractor management | G18: Compliance | H18: ='Safety overall result'!Z19 -> A
F19: Training | G19: Compliance | H19: ='Safety overall result'!Z20 -> A | M19: X | R19: TYM/TS
C20: Business Strategy Adjustment | D20: Fundamental enhancement by Cpk and COPQ analysis QM management assurance across value chain | E20: Management System | F20: Policy/ Purpose/ Target | G20: Governance | H20: ='Safety overall result'!Z21 -> A | N20: X | R20: 教育訓練 | S20: Training
F21: Implementation Plan | G21: Governance | H21: ='Safety overall result'!Z22 -> A | N21: X | R21: 方針・目的・目標 | S21: Policy/ Purpose/ Target
F22: Audit | G22: Governance | H22: ='Safety overall result'!Z23 -> A | M22: X | R22: 実施計画 | S22: Implementation Plan
F23: Working std. (Review/Revise) | G23: Governance | H23: ='Safety overall result'!Z24 -> A
F24: TS/TYM (Trouble management) | G24: Governance | H24: ='Safety overall result'!Z25 -> A
F25: Safety Patrol/Monitoring | G25: Governance | H25: ='Safety overall result'!Z26 -> A
C26: Independency and Continuity | D26: Awareness and knowledge for QM | E26: Independent implementation of BSFA | F26: BSFA Training | G26: Compliance | H26: ='Safety overall result'!Z27 -> A | N26: X | R26: 監査 | S26: Audit
F27: 3S | G27: Risk | H27: ='Safety overall result'!Z28 -> A | N27: X | R27: BS共通安全 規定項目 教育 | S27: BSFA Training
F28: KYT/ Practical KYT | G28: Compliance | H28: ='Safety overall result'!Z29 -> A | M28: X | R28: 3S | S28: 3S
F29: Autonomously KY | G29: Risk | H29: ='Safety overall result'!#REF! -> #REF! | M29: X | R29: KYT 実践型KYT | S29: KYT/ Practical KYT
F30: RA | G30: Risk | H30: ='Safety overall result'!Z30 -> A | N30: X | R30: 自律的KY ・改善 | S30: Autonomously KY
F31: Safety Rule | G31: Compliance | H31: ='Safety overall result'!Z31 -> A | N31: X | R31: RA | S31: RA
F32: 4M Change Management | G32: Risk | H32: ='Safety overall result'!Z32 -> A | M32: X | R32: 安全ルール | S32: Safety Rule
F33: Management System: P | G33: Governance | H33: ='Safety overall result'!Z33 -> A | M33: X | R33: 4M変更管理 | S33: 4M Change Management
F34: Management System: D | G34: Governance | H34: ='Safety overall result'!Z34 -> A | M34: X | R34: 【モデル工場】 P | S34: Management System: P
F35: Management System: C | G35: Governance | H35: ='Safety overall result'!Z35 -> A | N35: X | R35: 【モデル工場】 D | S35: Management System: D
F36: Management System: A | G36: Governance | H36: ='Safety overall result'!Z36 -> A | N36: X | R36: 【モデル工場】 C | S36: Management System: C
C37: Integration/ Incorporation | D37: Resource and Organization for QM | E37: Plant Management | F37: Safety Organization | G37: Governance | H37: ='Safety overall result'!Z37 -> A | M37: X | R37: 【モデル工場】 A | S37: Management System: A
F38: SE | G38: Governance | H38: ='Safety overall result'!Z38 -> A | R38: 安全組織 | S38: Safety Organization
F39: Budget | G39: Governance | H39: ='Safety overall result'!Z39 -> A | N39: X | R39: 安全担当
R40: SE | S40: SE
R41: 安全専任 職長
R42: 予算確保 | S42: Budget

Sheet DP instruction
M1: 発行日： | N1: 45128
C2: Solidification Assessment DP Instruction
C4: Site | D4: ='Safety Instruction.'!D4 -> 0 | N4: 継続：現状維持、 レベルアップ：A、B＋、Bレベルへの改善 新規：過去に指摘・提案がない
C6: Solidification 5 items | D6: Point of Evaluation | E6: Primary Categoty | F6: Secondary Categoty | G6: 3 Axes Evaluation | H6: Solidification Score | J6: 2026 Target | K6: Issues and/or Changes | L6: Instruction - Items could be Incorporated into MBP | M6: Implementation Items | N6: Category
H7: 2024 | I7: 2025 | N7: Continue | O7: Level up | P7: New
C9: Issue solving | D9: Quickness of issue solving Deep root cause analysis, standardization and implementation | E9: Cuntermeasures and Recurrence prevention | F9: Information Sharing | G9: Governance | H9: =INDEX(Data!#REF!,MATCH('DP instruction'!F9,Data!#REF!,0),MATCH('DP instruction'!$D$4,Data!#REF!,0)) -> #REF! | I9: ='DP cal.'!X15 -> A | J9: A | K9: Keep the current condition. | L9: - | M9: Continue to share the incident information. | N9: X
F10: Recurrence Prevention | G10: Risk | H10: =INDEX(Data!#REF!,MATCH('DP instruction'!F10,Data!#REF!,0),MATCH('DP instruction'!$D$4,Data!#REF!,0)) -> #REF! | I10: ='DP cal.'!X16 -> B+ | J10: A | K10: Recurrence prevention measures have been taken but some SV could not state actual aciton clearly. | L10: Make sure all SVs understanding of recurrence prevention measures, especially in case that the action is related to their process. | M10: Consider to make SVs explain not only measures itself but its back ground, what they need in their own process. | O10: X
F11: Fire Reporting | G11: Governance | H11: =INDEX(Data!#REF!,MATCH('DP instruction'!F11,Data!#REF!,0),MATCH('DP instruction'!$D$4,Data!#REF!,0)) -> #REF! | I11: ='DP cal.'!X17 -> A | J11: A | K11: Keep the current condition. | L11: - | M11: Continue to report in case any incidents happened. | N11: X
F12: Recurrence Prevention Process KPI | G12: Risk | H12: =INDEX(Data!#REF!,MATCH('DP instruction'!F12,Data!#REF!,0),MATCH('DP instruction'!$D$4,Data!#REF!,0)) -> #REF! | I12: ='DP cal.'!X18 -> B | J12: B+ | K12: Recurrence prevention measures are on-going to the plan, but not yet completed. | L12: Consider progressing ahead of the plan | M12: Discuss whether the plan can be moved forward. | O12: X
C13: Risk Management | D13: Symptom Management for QM defect Management and analysis of information which is explored, issued | E13: RA | F13: Fire RA Progress | G13: Risk | H13: =INDEX(Data!#REF!,MATCH('DP instruction'!F13,Data!#REF!,0),MATCH('DP instruction'!$D$4,Data!#REF!,0)) -> #REF! | I13: ='DP cal.'!X19 -> B | J13: B+ | K13: Fire RA have not been completed so that the result have not been shared in the plant. | L13: Please complete Fire RA and share its result in plant. | M13: Complete Fire RA and prepare an opportunity to educate teammates about the fire risks of each process. | O13: X
F14: Fire RA | G14: Risk | H14: =INDEX(Data!#REF!,MATCH('DP instruction'!F14,Data!#REF!,0),MATCH('DP instruction'!$D$4,Data!#REF!,0)) -> #REF! | I14: ='DP cal.'!X20 -> B | J14: B+ | K14: Countermeasures for the fire risk are on-going to the plan. | L14: Consider progressing ahead of the plan | M14: Discuss whether the plan can be moved forward. | O14: X
F15: DP Inspection | G15: Risk | H15: =INDEX(Data!#REF!,MATCH('DP instruction'!F15,Data!#REF!,0),MATCH('DP instruction'!$D$4,Data!#REF!,0)) -> #REF! | I15: ='DP cal.'!X21 -> A | J15: A | K15: Keep the current condition. | L15: - | M15: Continue to keep inspection from DP point of view. | N15: X
F16: Electrical Wiring Inspection | G16: Risk | H16: =INDEX(Data!#REF!,MATCH('DP instruction'!F16,Data!#REF!,0),MATCH('DP instruction'!$D$4,Data!#REF!,0)) -> #REF! | I16: ='DP cal.'!X22 -> A | J16: A | K16: Keep the current condition. | L16: - | M16: Continue to keep DP inspection including electrical wiring inspection. | N16: X
F17: Noise patrol | G17: Risk | H17: =INDEX(Data!#REF!,MATCH('DP instruction'!F17,Data!#REF!,0),MATCH('DP instruction'!$D$4,Data!#REF!,0)) -> #REF! | I17: ='DP cal.'!X23 -> A | J17: A | K17: Keep the current condition. | L17: - | M17: Continue to keep inspection including noise check. | N17: X
C18: Business Strategy Adjustment | D18: Fundamental enhancement by Cpk and COPQ analysis QM management assurance across value chain | E18: Management System | F18: Policy/ Purpose/ Target | G18: Governance | H18: =INDEX(Data!#REF!,MATCH('DP instruction'!F18,Data!#REF!,0),MATCH('DP instruction'!$D$4,Data!#REF!,0)) -> #REF! | I18: ='DP cal.'!X24 -> A | J18: A | K18: Keep the current condition. | L18: - | M18: Continue to keep policy management. | N18: X
F19: Implementation Plan | G19: Governance | H19: =INDEX(Data!#REF!,MATCH('DP instruction'!F19,Data!#REF!,0),MATCH('DP instruction'!$D$4,Data!#REF!,0)) -> #REF! | I19: ='DP cal.'!X25 -> B | J19: B+ | K19: Some manager could not clearly stated the resut of last year, and what is updated/improved point(s) in the action plan. | L19: From previous result, please review the IIP's progress (and good/bad point) and consider to update it to go more forward. | M19: Consider to have a step to review the result of IIP, and update BMT's safety activity based on the review. | O19: X
F20: Audit | G20: Governance | H20: =INDEX(Data!#REF!,MATCH('DP instruction'!F20,Data!#REF!,0),MATCH('DP instruction'!$D$4,Data!#REF!,0)) -> #REF! | I20: ='DP cal.'!X26 -> B+ | J20: A | K20: Internal audit have been completed and some NC and OFI found and taking countermeasure in on progress. | L20: Promote to plan and conduct countermeasures for non-conformities. | M20: Discuss plans for non-conformities and promote countermeasures | O20: X
C21: Independency and Continuity | D21: Awareness and knowledge for QM | E21: Management System | F21: 3S *DP perspective (for flammable/combastible material storage) | G21: Risk | H21: =INDEX(Data!#REF!,MATCH('DP instruction'!F21,Data!#REF!,0),MATCH('DP instruction'!$D$4,Data!#REF!,0)) -> #REF! | I21: ='DP cal.'!X27 -> B+ | J21: A | K21: Workplace 3S is good condition, and almost of area's 3S level 4. | L21: Keep 3S condition based on 3S guideline. | M21: For more improvement, communication with the other site could be helpful so please consider to have this kind of opportunity. | O21: X
F22: KYT/ Practical KYT *DP point of view | G22: Compliance | H22: =INDEX(Data!#REF!,MATCH('DP instruction'!F22,Data!#REF!,0),MATCH('DP instruction'!$D$4,Data!#REF!,0)) -> #REF! | I22: ='DP cal.'!X28 -> A | J22: A | K22: Keep the current condition. | L22: - | N22: X
F23: Autonomous KY *DP point of view | G23: Risk | H23: =INDEX(Data!#REF!,MATCH('DP instruction'!F23,Data!#REF!,0),MATCH('DP instruction'!$D$4,Data!#REF!,0)) -> #REF! | I23: ='DP cal.'!X29 -> B+ | J23: A | K23: Autonomous KY activity is well going and updated compare with last year. | L23: Please consider to visualize KY point in map to make it easy to see which place has high risk. | M23: Please consider to use the maps to visualize everyone's KY point, and KAIZEN cycle to improve it. | O23: X
F24: Common Fire Prevention Rule | G24: Compliance | H24: =INDEX(Data!#REF!,MATCH('DP instruction'!F24,Data!#REF!,0),MATCH('DP instruction'!$D$4,Data!#REF!,0)) -> #REF! | I24: ='DP cal.'!X30 -> C | J24: B | K24: Some operators state that the training has been given not periodically. (few times from hired) | L24: Please conduct commom fire prevention rules training at least once a year, to all teammates. | M24: Make sure that the action plan includes training of common fire prevention rule. | O24: X
F25: Fire Fighting | G25: Compliance | H25: =INDEX(Data!#REF!,MATCH('DP instruction'!F25,Data!#REF!,0),MATCH('DP instruction'!$D$4,Data!#REF!,0)) -> #REF! | I25: ='DP cal.'!X31 -> A | J25: A | K25: Keep the current condition. | L25: - | N25: X
F26: Hot Work | G26: Compliance | H26: =INDEX(Data!#REF!,MATCH('DP instruction'!F26,Data!#REF!,0),MATCH('DP instruction'!$D$4,Data!#REF!,0)) -> #REF! | I26: ='DP cal.'!X32 -> A | J26: A | K26: Keep the current condition. | L26: - | N26: X
F27: Inspection/ clean-up of mobile equipment | G27: Compliance | H27: =INDEX(Data!#REF!,MATCH('DP instruction'!F27,Data!#REF!,0),MATCH('DP instruction'!$D$4,Data!#REF!,0)) -> #REF! | I27: ='DP cal.'!X33 -> A | J27: A | K27: Keep the current condition. | L27: - | N27: X
F28: Compliance of standards and inspection for gasoline cement houses and Warehouse storing flammable materials | G28: Compliance | H28: =INDEX(Data!#REF!,MATCH('DP instruction'!F28,Data!#REF!,0),MATCH('DP instruction'!$D$4,Data!#REF!,0)) -> #REF! | I28: ='DP cal.'!X34 -> A | J28: A | K28: Keep the current condition. | L28: - | N28: X
F29: Control of specified combustibles handling areas | G29: Compliance | H29: =INDEX(Data!#REF!,MATCH('DP instruction'!F29,Data!#REF!,0),MATCH('DP instruction'!$D$4,Data!#REF!,0)) -> #REF! | I29: ='DP cal.'!X35 -> A | J29: A | K29: Keep the current condition. | L29: - | N29: X
F30: Inspection of unattended areas | G30: Compliance | H30: =INDEX(Data!#REF!,MATCH('DP instruction'!F30,Data!#REF!,0),MATCH('DP instruction'!$D$4,Data!#REF!,0)) -> #REF! | I30: ='DP cal.'!X36 -> A | J30: A | K30: Keep the current condition. | L30: - | N30: X
F31: Carbon MUST items Selfcheck | G31: Compliance | H31: =INDEX(Data!#REF!,MATCH('DP instruction'!F31,Data!#REF!,0),MATCH('DP instruction'!$D$4,Data!#REF!,0)) -> #REF! | I31: ='DP cal.'!X37 -> 0
F32: Carbon MUST items Training | G32: Compliance | H32: =INDEX(Data!#REF!,MATCH('DP instruction'!F32,Data!#REF!,0),MATCH('DP instruction'!$D$4,Data!#REF!,0)) -> #REF! | I32: ='DP cal.'!X38 -> 0
C33: Integration/ Incorporation | D33: Resource and Organization for QM | E33: Plant Management | F33: DP Organization | G33: Governance | H33: =INDEX(Data!#REF!,MATCH('DP instruction'!F33,Data!#REF!,0),MATCH('DP instruction'!$D$4,Data!#REF!,0)) -> #REF! | I33: ='DP cal.'!X39 -> A | J33: A | K33: Keep the current condition. | L33: - | M33: Continue to keep EHS organization. | N33: X
F34: Legal lisence | G34: Governance | H34: =INDEX(Data!#REF!,MATCH('DP instruction'!F34,Data!#REF!,0),MATCH('DP instruction'!$D$4,Data!#REF!,0)) -> #REF! | I34: ='DP cal.'!X40 -> 0
F35: Budget | G35: Governance | H35: =INDEX(Data!#REF!,MATCH('DP instruction'!F35,Data!#REF!,0),MATCH('DP instruction'!$D$4,Data!#REF!,0)) -> #REF! | I35: ='DP cal.'!X41 -> C | J35: B+ | K35: Budget for DP was prepared and well managed, but some manager stated safety budget was not enough. | L35: Make sure all manager's understanding for management of budget - prioriy, validity and so on. | M35: Make sure of all teammates understanding of budget management. | O35: X
C46: 自他事業所のトラブル内容の共有化、また、対策推進の際は技能員の意見を聞き、対応状況のフィードバックについても確実に実施していること、職長の危険物取扱者資格(乙4)についても対象者全員が取得しておりましたので活動の継続をお願いします。 精練防災専任の配置については、24MBP/OBへ組み入れ、計画通りの推進をお願い致します。
C47: 安全活動全般について、標準通りの管理ができており、更にPDCAサイクルを回して継続的な改善が実施され、トラブル対応等についても、技能員の意見を聞き、フィードバックも確実に実施されておりましたので活動の継続をお願いします。 個々の活動については、工程や対象者により、実施内容の差（自律的KY、３Sビジュアル標準等）がありました。 更に安全活動を向上させ盤石な体制に向け、マネジメントチーム（基幹職・主任）全員で工場全体の安全活動推進状況を 現物現場で有効性を確認し、抽出した課題について討議する等、仕組の構築や標準化について検討をお願い致します。

Sheet Safety overall result
H1: Judgement Criteria
B2: Legend | I2: ・Pick the lowest score from each items | Q2: Ver_1:2023/3/31作成
C3: : Items from Safety Maturity Assessment | I3: ・Time scope is one year from evaluating | Q3: Ver_2:2024/3/19作成
C4: : Items that is newly added for solidification assessment | I4: ・ Questions for operators, need to have interview at least one person from production department. | Q4: Ver_3:2025/4/1作成
B5: Blue text | C5: : Items added by BSAPIC | I5: ・In case of question that is asking its progress, that should be evaluated at the day of evaluation. | Q5: Ver_4:2025/8/9 BSAPIC updated
C7: Solidification 5 items | D7: Point of Evaluation | E7: Primary Categoty | F7: Safety/ DP | G7: Secondary Categoty | H7: Current Issues Disposition | I7: Judge | J7: Potential Risk Prevention | K7: Judge | L7: Potential Risk Prevention | M7: Judge | N7: Proactive Prevention | O7: Judge | P7: Independent Quality Management | Q7: Judge | S7: 安全/ 防災 | T7: Judement | Y7: Score | Z7: Grade | AA7: 3 Axis
H8: 1 | J8: 2 | L8: 3 | N8: 4 | P8: 5 | T8: 1 | U8: 2 | V8: 3 | W8: 4 | X8: 5
H9: C | J9: B- | L9: B | N9: B+ | P9: A | T9: C | U9: B- | V9: B | W9: B+ | X9: A
C10: Issue solving | D10: Quickness of issue solving Deep root cause analysis, standardization and implementation | F10: Safety | G10: Information Sharing | H10: All teammates stated that, at least, safety manager and site leadership representative (e.g. plant manager, department manager, line manager) was involved in the root cause analysis process when a serious incident(lost-time-injury, etc.) occurred. (Leadership: Operator: No.5) | J10: All teammates can state that they are informed of recent safety incidents (injury, near-miss, etc.) in their areas and actions have been taken to address these. (Teammate Engagement: Operator: No.7) | L10: All teammates say that they are well informed and can explain how the information* communicated contributes to their safety. (System: Operator: No.64) *information: injury, near-miss etc. | N10: Teammates can provide examples of accidents which occurred on other facilities and how that information was obtained. (System: Operator: No.110) | P10: H&S risks/measures of other departments have been shared at the safety meeting in your department. (Teammate Engagement: Operator: No.17) | S10: Safety | T10: =I10 -> 0 | U10: =K10 -> 0 | V10: =M10 -> 0 | W10: =O10 -> 0 | X10: =Q10 -> 0 | Y10: =IF(T10="No",1,IF(U10="No",1,IF(V10="No",2,IF(W10="No",3,IF(X10="No",4,5))))) -> 5 | Z10: =IF(Y10<2,"C",IF(Y10<3,"B-",IF(Y10<4,"B",IF(Y10<5,"B+",IF(Y10=5,"A",""))))) -> A | AA10: Governance
F11: Safety | G11: Recurrence Prevention | H11: There is evidence that actions have been taken to prevent recurring incidents. And SVs can explain it. And also, confirm at least one example at GENBA. (System: Safety Manager: No.30) *Ask SVs | J11: A sample of 3 teammates, at least 1 (more than 33%) said they take part in the actions required to prevent safety accidents and provide feedback if these actions are not appropriate or useful. (Teammate Engagement: Operator: No.6) | L11: The safety manager can explain what actions are required for recurrence prevention when occuring a safety accicdent. (System: Safety Manager: No.86) *Ask SVs | N11: All teammates stated that management had taken specific actions to address hazards they reported, and these actions have been communicated to them. (safety point of view) (Organization: Operator: No.16) | P11: The safety leader can explain how such reviews are completed and why that method(s) is effective, providing feedback to SBU and assisting in determining countermeasures. (Example: Share more valid safety measreus than measures proposed by GBS/SBU) (System: Safety Manager: No.140) *Ask SVs | S11: Safety | T11: =I11 -> 0 | U11: =K11 -> 0 | V11: =M11 -> 0 | W11: =O11 -> 0 | X11: =Q11 -> 0 | Y11: =IF(T11="No",1,IF(U11="No",1,IF(V11="No",2,IF(W11="No",3,IF(X11="No",4,5))))) -> 5 | Z11: =IF(Y11<2,"C",IF(Y11<3,"B-",IF(Y11<4,"B",IF(Y11<5,"B+",IF(Y11=5,"A",""))))) -> A | AA11: Risk
F12: Safety | G12: Injury Reporting | H12: Issuing injury report with SBU's support. (Safety Manager) | J12: Injury report is issued by plant, but there was a delay in the due date in the guideline. (Safety Manager) | L12: Injury report is issued by plant, within the due date that is standardized in the guideline. And root cause analysis and its countermeasure has been completed and these report is issued within the due date as the guideline. (Safety Manager) | N12: Injury report is issued by plant, within the due date that is standardized in the guideline. And root cause analysis and its countermeasure has been completed and these report is issued within the due date as the guideline. Also, the countermeasure has been spreaded to similar machines/tasks. After the countermeasure is compleated, the report to SBU has been issued. (Safety Manager) | P12: Past countermeasures have been re-checked its implementation status periodically. *At least, need to check its progress within 1 year. (Safety Manager) | S12: Safety | T12: =I12 -> 0 | U12: =K12 -> 0 | V12: =M12 -> 0 | W12: =O12 -> 0 | X12: =Q12 -> 0 | Y12: =IF(T12="No",1,IF(U12="No",1,IF(V12="No",2,IF(W12="No",3,IF(X12="No",4,5))))) -> 5 | Z12: =IF(Y12<2,"C",IF(Y12<3,"B-",IF(Y12<4,"B",IF(Y12<5,"B+",IF(Y12=5,"A",""))))) -> A | AA12: Governance
F13: Safety | G13: Recurrence Prevention Process KPI | H13: There is no plan for countermeasures from outside of plant. *"Countermeasure" in this part means that is issued from BSJ7310 (Safety Manager) | J13: There is a plan for contermeasure, but there is a delay in the plan. *No corrective plan for delay. (Safety Manager) | L13: There is a plan for contermeasure, and it is on-going to the plan, but not yet completed. Or, there is a delay but corrective plan has been made for it, and it is on-going. (Safety Manager) | N13: There is a plan for contermeasure, and progressing ahead of the plan, but not yet completed. (Safety Manager) | P13: All contermeasures have been completed. (Safety Manager) | S13: Safety | T13: =I13 -> Yes | U13: =K13 -> No | V13: =M13 -> 0 | W13: =O13 -> 0 | X13: =Q13 -> 0 | Y13: =IF(T13="No",1,IF(U13="No",1,IF(V13="No",2,IF(W13="No",3,IF(X13="No",4,5))))) -> 1 | Z13: =IF(Y13<2,"C",IF(Y13<3,"B-",IF(Y13<4,"B",IF(Y13<5,"B+",IF(Y13=5,"A",""))))) -> C | AA13: Risk
C14: Risk Management | D14: Symptom Management for QM defct Management and analysis of information which is exploared, issued | E14: RA | F14: Safety | G14: RA Progress | H14: There is evidence that the required risk assessments have been done or there is a plan to complete. (System: Safety Manager: No.28) *Ask SVs | J14: There is a risk tracking that lists specific risks on site. (System: Safety Manager: No.50) *Ask SVs | L14: There is at least one control prescribed for each risk identified. These controls are either administrative or technical by nature. The remaining risks are post & written in the work standard. (System: Safety Manager: No.90) *Ask SVs | N14: The respondent is able to provide at least one recent example of bottom-up communication on hazards and risks. (System: Safety Manager: No.xx) *Ask SVs | P14: The respondent can show evidence of at least one review performed in the past 12 months where the risk assessment result/process was improved based on external best practice. (System: Safety Manager: No.154) *Ask SVs | S14: Safety | T14: =I14 -> 0 | U14: =K14 -> 0 | V14: =M14 -> 0 | W14: =O14 -> 0 | X14: =Q14 -> 0 | Y14: =IF(T14="No",1,IF(U14="No",1,IF(V14="No",2,IF(W14="No",3,IF(X14="No",4,5))))) -> 5 | Z14: =IF(Y14<2,"C",IF(Y14<3,"B-",IF(Y14<4,"B",IF(Y14<5,"B+",IF(Y14=5,"A",""))))) -> A | AA14: Risk
F15: Safety | G15: Equipment RA | H15: There is a plan for Machine RA. (Safety Manager) | J15: There is a plan for hardware countermeasures, but there is a delay in the plan. *No corrective plan for the delay. (Safety Manager) | L15: There is a plan for hardware countermeasures , and it is on-going to the plan. Or, there is a delay but corrective plan has been made for it, and it is on-going. (Safety Manager) | N15: There is a plan for hardware contermeasures, and progressing ahead of the plan, but not yet completed. (Safety Manager) | P15: All contermeasures have been completed. *all risks that could be countered by hardware have been reduced by hardware. (Safety Manager) | S15: Safety | T15: =I15 -> 0 | U15: =K15 -> 0 | V15: =M15 -> 0 | W15: =O15 -> 0 | X15: =Q15 -> 0 | Y15: =IF(T15="No",1,IF(U15="No",1,IF(V15="No",2,IF(W15="No",3,IF(X15="No",4,5))))) -> 5 | Z15: =IF(Y15<2,"C",IF(Y15<3,"B-",IF(Y15<4,"B",IF(Y15<5,"B+",IF(Y15=5,"A",""))))) -> A | AA15: Risk
F16: Safety | G16: Task RA | H16: There is a plan for Task RA. (Safety Manager) | J16: There is a plan for Task RA, but there is a delay in the plan. *No corrective plan for the delay. (Safety Manager) | L16: There is a plan for Task RA, and it is on-going to the plan. Or, there is a delay but corrective plan has been made for it, and it is on-going. (Safety Manager) | N16: There is a plan for Task RA, and progressing ahead of the plan, but not yet completed. (Safety Manager) | P16: All task RA have been completed. (Safety Manager) | S16: Safety | T16: =I16 -> 0 | U16: =K16 -> 0 | V16: =M16 -> 0 | W16: =O16 -> 0 | X16: =Q16 -> 0 | Y16: =IF(T16="No",1,IF(U16="No",1,IF(V16="No",2,IF(W16="No",3,IF(X16="No",4,5))))) -> 5 | Z16: =IF(Y16<2,"C",IF(Y16<3,"B-",IF(Y16<4,"B",IF(Y16<5,"B+",IF(Y16=5,"A",""))))) -> A | AA16: Risk
F17: Safety | G17: LOTO (Training) | H17: The basic LOTO training has been implemented anually, all operators understand basic LOTO operation. And, operator take one's own key and locks to GENBA if it is necessary. (operator) | J17: With the basic LOTO training, ECP has been trained to all operators, and they understand LOTO procedure. *ECP should be included in SOP. *ECP should be prepared for all LOTO devise (Operator) | L17: With the basic LOTO training, ECP has been trained to all operators, and they understand LOTO procedure. *ECP included in SOP, included all related energy and prepared for all LOTO device (Operator) | N17: If the operator handle LOTO procedure regularly, he/she can explain and implement its detail procedure. If the operator do not handle LOTO, he/she can explain basic LOTO rule. (Operator) | P17: Operator provide feedback or suggestions of their difficulty/improvement point of LOTO/ECP e.g. identify potential risks where LOTO should be applied and remind or guide others before unsafe conditions happen (Operator) | S17: Safety | T17: =I17 -> 0 | U17: =K17 -> 0 | V17: =M17 -> 0 | W17: =O17 -> 0 | X17: =Q17 -> 0 | Y17: =IF(T17="No",1,IF(U17="No",1,IF(V17="No",2,IF(W17="No",3,IF(X17="No",4,5))))) -> 5 | Z17: =IF(Y17<2,"C",IF(Y17<3,"B-",IF(Y17<4,"B",IF(Y17<5,"B+",IF(Y17=5,"A",""))))) -> A | AA17: Compliance
F18: Safety | G18: LOTO management | H18: SVs lack clarity on which operations require LOTO, unclear list. (SVs) | J18: SVs can explain LOTO operation/can't do LOTO, but unclear for SOP/APM for task, which can't apply LOTO or no implementation onsite (SVs) | L18: SVs can explain which operation needs LOTO in their own process. There's list of task (production, maintenance), which can/can't do LOTO, SOP has been already prepared and proper application of APM (e.g., orange tag) where LOTO cannot be applied (SVs) | N18: SVs actively ensure operators understand and follow LOTO and APM rules, regularly refresh knowledge, and verify compliance before starting tasks (SVs) | P18: Department/Section has a culture where SVs not only apply LOTO/APM consistently but also lead cross-functional learning, share best practices, and continuously improve SOPs to prevent energy hazards across all operations (SVs) | S18: Safety | T18: =I18 -> 0 | U18: =K18 -> 0 | V18: =M18 -> 0 | W18: =O18 -> 0 | X18: =Q18 -> 0 | Y18: =IF(T18="No",1,IF(U18="No",1,IF(V18="No",2,IF(W18="No",3,IF(X18="No",4,5))))) -> 5 | Z18: =IF(Y18<2,"C",IF(Y18<3,"B-",IF(Y18<4,"B",IF(Y18<5,"B+",IF(Y18=5,"A",""))))) -> A | AA18: Compliance
F19: Safety | G19: Contractor management | H19: There's no pre-work planning and meeting or no review risk of contrator work e.g. no JSA/RA (Safety manager) | J19: There's pre-work planning and meeting to identify risk and there's JSA/RA but measure onsite is insufficient or there's risk onsite (Safety manager) | L19: - Identify all risks in JSA/RA with sufficient measure onsite. - Risk and measure has been communicated to all related members - All members conduct KY before start work (Safety manager) | N19: There's communication to BS-PIC & contractor if any change and risk has been reviewed, take measure and communicate additional/changed risk to related person (Safety manager) | P19: All risks onsite has been controlled and contractor fully complied with standard and feedback risk/insufficient measure that may happen during work. (Safety manager) | S19: Safety | T19: =I19 -> 0 | U19: =K19 -> 0 | V19: =M19 -> 0 | W19: =O19 -> 0 | X19: =Q19 -> 0 | Y19: =IF(T19="No",1,IF(U19="No",1,IF(V19="No",2,IF(W19="No",3,IF(X19="No",4,5))))) -> 5 | Z19: =IF(Y19<2,"C",IF(Y19<3,"B-",IF(Y19<4,"B",IF(Y19<5,"B+",IF(Y19=5,"A",""))))) -> A | AA19: Compliance
F20: Safety | G20: Training | H20: Safety trainings have been given to workers when new hired and/or trasfered. (SVs) | J20: Safety training meets regional legal requirement. (SVs) | L20: Operators can work alone after their skill/knowledge is validated by the site's criteria. (SVs) | N20: Skill/knowledge training is managed by IIP for all operaters, and its criteria is clear. Also, their skill/knowledge is followed up until they achieve 100% (SVs) | P20: All operators understanding is confirmed periodically, and the confirmation step is standardized. (SVs) | S20: Safety | T20: =I20 -> 0 | U20: =K20 -> 0 | V20: =M20 -> 0 | W20: =O20 -> 0 | X20: =Q20 -> 0 | Y20: =IF(T20="No",1,IF(U20="No",1,IF(V20="No",2,IF(W20="No",3,IF(X20="No",4,5))))) -> 5 | Z20: =IF(Y20<2,"C",IF(Y20<3,"B-",IF(Y20<4,"B",IF(Y20<5,"B+",IF(Y20=5,"A",""))))) -> A | AA20: Compliance
C21: Business Strategy Adjustment | D21: Fundamental enhancement by Cpk and COPQ analysis QM management assurerance across value chain | E21: Management System | F21: Safety | G21: Policy/ Purpose/ Target | H21: Safety policy/target has not been issued. (Safety Manager) | J21: OH&S policy has been established at site. And the manager can explain it. (System: Plant Manager: No.9) (Mgr + SV) | L21: Management can describe and explain the site's OH&S objectives and goals. (Mgr + SV) | N21: The plan contains goals to be achieved which are relevant to the incidents and risks identified by the SBU. (Mgr + SV) | P21: There is evidence of OH&S benchmarking with other sites. (System: Safety Manager: No.123) (Mgr + SV) | S21: Safety | T21: =I21 -> 0 | U21: =K21 -> 0 | V21: =M21 -> 0 | W21: =O21 -> 0 | X21: =Q21 -> 0 | Y21: =IF(T21="No",1,IF(U21="No",1,IF(V21="No",2,IF(W21="No",3,IF(X21="No",4,5))))) -> 5 | Z21: =IF(Y21<2,"C",IF(Y21<3,"B-",IF(Y21<4,"B",IF(Y21<5,"B+",IF(Y21=5,"A",""))))) -> A | AA21: Governance
F22: Safety | G22: Implementation Plan | H22: There is no implementation plan for safety. (Safety Manager) | J22: There are documented OH&S action plans and evidence of OH&S results tracking. (Mgr) | L22: Safety KPIs are tracked at plant, department and line level. To solve issues on H&S, site leadership follow safety KPIs, and give directions to review the safety program if necessary. (Leadership: Plant Manager: No.7) (Mgr) | N22: Safety KPIs are tracked positively at plant, department and line level - using "Leading indicators"(e.g. Progress of RA, KPI for 3S activity, etc.) Site leadership follow not only lagging indicator(e.g. # of injuries), but also leading indicators, and give directions to review and/or improve safety programs if necessary. (Leadership: Plant Manager: No.16) (Mgr) | P22: The Plant Manager can describe his/her OH&S strategy and its goals, and how it will be implemented and the goals achieved. And, the strategy has been reviewed quarterly - its progress, validity. Also, revision/instruction for the starategy result have been implemented by plant manager. (Leadership: Plant manager: No.24) (mgr.) | S22: Safety | T22: =I22 -> 0 | U22: =K22 -> 0 | V22: =M22 -> 0 | W22: =O22 -> 0 | X22: =Q22 -> 0 | Y22: =IF(T22="No",1,IF(U22="No",1,IF(V22="No",2,IF(W22="No",3,IF(X22="No",4,5))))) -> 5 | Z22: =IF(Y22<2,"C",IF(Y22<3,"B-",IF(Y22<4,"B",IF(Y22<5,"B+",IF(Y22=5,"A",""))))) -> A | AA22: Governance
F23: Safety | G23: Audit | H23: Internal/external audit has not been conducted. (Safety Manager) | J23: Internal audit has been conducted, and its report could be found. But, it is not enough to follow up the findings. (System: Safety Manager: No.47) | L23: Items/Non-Conformities pointed out at the internal audits were improved or planed to improve them. (System: Safety Manager: No.77) | N23: OFIs found at last internal audit have been improved or have been planed to improve. (System: Safety Manager: No.106) | P23: Regarding the safety management system in the plant, the H&S manager can explain evaluation results by third party, feedback, and the actions. (Organization: Safety Manager: No.20) | S23: Safety | T23: =I23 -> 0 | U23: =K23 -> 0 | V23: =M23 -> 0 | W23: =O23 -> 0 | X23: =Q23 -> 0 | Y23: =IF(T23="No",1,IF(U23="No",1,IF(V23="No",2,IF(W23="No",3,IF(X23="No",4,5))))) -> 5 | Z23: =IF(Y23<2,"C",IF(Y23<3,"B-",IF(Y23<4,"B",IF(Y23<5,"B+",IF(Y23=5,"A",""))))) -> A | AA23: Governance
F24: Safety | G24: Working std. (Review/Revise) | H24: There's working standard but no mention necessary safety key point or no review/revise working std. as determined period of plant's std. (mgr.) | J24: There's working standard and review/revise as period but missing some necessary safety key point (mgr.) | L24: There's working standard with cover all necessary safety key point and it's review/revise periodically as plant std. (mgr.) | N24: O/P feedback missing step/improvement point and inform for further enhancement and there's evidence (mgr.) | P24: The best practices on working std. creation activity has been gathered from other facility/plants/industry, and it has been incorporated into plant. | S24: Safety | T24: =I24 -> 0 | U24: =K24 -> 0 | V24: =M24 -> 0 | W24: =O24 -> 0 | X24: =Q24 -> 0 | Y24: =IF(T24="No",1,IF(U24="No",1,IF(V24="No",2,IF(W24="No",3,IF(X24="No",4,5))))) -> 5 | Z24: =IF(Y24<2,"C",IF(Y24<3,"B-",IF(Y24<4,"B",IF(Y24<5,"B+",IF(Y24=5,"A",""))))) -> A | AA24: Governance
F25: Safety | G25: TS/TYM (Trouble management) | H25: There's list of troubles but no review or classification of risks *Ask Manager (not safety) | J25: Actions taken only after frequent troubles occur, without systematic risk classification or preventive planning *Ask Manager (not safety) | L25: There's list of trouble, review risk of each trouble to classify for TS/TYM action, create all TS standard, communicate to related O/P and they understand risk and how to avoid those risk. *Ask Manager (not safety) | N25: Analyze trouble trend especially frequent trouble by considering potential risk and take measure for reduction. *Ask Manager (not safety) | P25: The best practices/similar trouble of has been gathered from other facility/plants/industry, and implement in the plant or clear KPI to reduce frequent trouble *Ask Manager (not safety) | S25: Safety | T25: =I25 -> 0 | U25: =K25 -> 0 | V25: =M25 -> 0 | W25: =O25 -> 0 | X25: =Q25 -> 0 | Y25: =IF(T25="No",1,IF(U25="No",1,IF(V25="No",2,IF(W25="No",3,IF(X25="No",4,5))))) -> 5 | Z25: =IF(Y25<2,"C",IF(Y25<3,"B-",IF(Y25<4,"B",IF(Y25<5,"B+",IF(Y25=5,"A",""))))) -> A | AA25: Governance
F26: Safety | G26: Safety Patrol/Monitoring | H26: There's only general/same issue of patrol/monitoring e.g. no cleaning, improper parking cart etc. without law compliance/risk point finding and/or no follow up. (Mgr, SV) | J26: Risks, non-compliance, or unsafe behaviors are identified but follow up only after being highlighted by audits, incidents. (Mgr, SV) | L26: The patroller identify risk/non-compliance/unsafe behavior during patrol/monitoring and measure has been followed up until completion (Mgr, SV) | N26: Patrollers/section actively engage responsible persons, track corrective actions, and verify effectiveness to ensure risks are fully mitigated. (Mgr, SV) | P26: The patrol/monitoring process not only eliminate identified risks but also drive cross-functional learning among section, and a culture where everyone proactively prevents unsafe behaviors (Mgr, SV) | S26: Safety | T26: =I26 -> 0 | U26: =K26 -> 0 | V26: =M26 -> 0 | W26: =O26 -> 0 | X26: =Q26 -> 0 | Y26: =IF(T26="No",1,IF(U26="No",1,IF(V26="No",2,IF(W26="No",3,IF(X26="No",4,5))))) -> 5 | Z26: =IF(Y26<2,"C",IF(Y26<3,"B-",IF(Y26<4,"B",IF(Y26<5,"B+",IF(Y26=5,"A",""))))) -> A | AA26: Governance
C27: Independency and Continuity | D27: Awareness and knowledge for QM | E27: Independent implementation of BSFA | F27: Safety | G27: BSFA Training | H27: All teammates are taking BSFA training more than annually. (Operator) | J27: All teammates are taking BSFA training more than annually, but the material is not the latest version. (Safety Manager) | L27: All teammates are taking BSFA training more than annually, and the material is the latest version. *Confirm the the material and training records *In case that the material is not updated, if the site have a plan for the training, this item could be judged "Yes". (Safety Manager) | N27: After the BSFA training, all teammates' understandings are validated in GENBA situation by manager or supervisor. (Safety Manager) | P27: After the BSFA training, all teammates' understandings are validated in GENBA situation by manager or supervisor, and all teammates could answer correctly. (Safety Manager) | S27: Safety | T27: =I27 -> 0 | U27: =K27 -> 0 | V27: =M27 -> 0 | W27: =O27 -> 0 | X27: =Q27 -> 0 | Y27: =IF(T27="No",1,IF(U27="No",1,IF(V27="No",2,IF(W27="No",3,IF(X27="No",4,5))))) -> 5 | Z27: =IF(Y27<2,"C",IF(Y27<3,"B-",IF(Y27<4,"B",IF(Y27<5,"B+",IF(Y27=5,"A",""))))) -> A | AA27: Compliance
F28: Safety | G28: 3S | H28: 3S Documents are displayed in work areas, and there is evidence of this being followed. And, self-check has been implemented. (System: Operator: No.19) | J28: There is an officially appointed 3S leader on site. There is evidence of 3S inspections and recommended actions to improve 3S. (System: Safety Manager: No.44+45) (SV) | L28: 3S standard setting: The 3S standard was set with considering of risk/rule compliance and work ability e.g. no necessary item place inside dangerous zone etc. 3S onsite implementation: All inspected work areas were cleaned (no debris on floor, no spillages) as defined in the 3S visual standard, and there were no unnecessary objects that were not currently in use in the work area. *work area: production area and office (System: Operator: No.75) | N28: 3S activity for the improvement of 3S level has been proceeded. (or Improvement of 3S level can be confirmed, or 3s level is over 4.) (System: Operator: No.105) | P28: The best practices on 3S have been gathered from other plants/industry, and it has been incorporated into the site procedure. or There is a evidence of the comparison with other plants. (System: Safety Manager: No.133) (Safety manager) | S28: Safety | T28: =I28 -> 0 | U28: =K28 -> 0 | V28: =M28 -> 0 | W28: =O28 -> 0 | X28: =Q28 -> 0 | Y28: =IF(T28="No",1,IF(U28="No",1,IF(V28="No",2,IF(W28="No",3,IF(X28="No",4,5))))) -> 5 | Z28: =IF(Y28<2,"C",IF(Y28<3,"B-",IF(Y28<4,"B",IF(Y28<5,"B+",IF(Y28=5,"A",""))))) -> A | AA28: Risk
F29: Safety | G29: KYT/ Practical KYT | H29: KYT has not been implemented. (Safety Manager) *Ask SVs | J29: There is evidence of a defined KY process that been communicated with all staff at least once in the past year. (System: Manager: No.26) | L29: There is an officially appointed KY leader and KY representatives on site. KYT records show that everyone (all teammates and temporary staff) completed KYT monthly | N29: KY is performed by everyone onsite (at workstation, equipment, machine, office) The results from KYT/KY onsite used to develop new safety rules or adjust old rules or improvement of safety measures for hazards((risk mitigation/administrative measures) | P29: The KYT activity is evaluated and opportunity for inprovement is discussed with the plant manager annually. (System: Safety Manager: No.113) | S29: Safety | T29: =I29 -> 0 | U29: =K29 -> 0 | V29: =M29 -> 0 | W29: =O29 -> 0 | X29: =Q29 -> 0 | Y29: =IF(T29="No",1,IF(U29="No",1,IF(V29="No",2,IF(W29="No",3,IF(X29="No",4,5))))) -> 5 | Z29: =IF(Y29<2,"C",IF(Y29<3,"B-",IF(Y29<4,"B",IF(Y29<5,"B+",IF(Y29=5,"A",""))))) -> A | AA29: Compliance
F30: Safety | G30: RA | H30: All teammates recognize the H&S risks applicable in their areas and confirmed these were addressed in trainings. (Teammate Engagement: Operator: No.1) | J30: A sample of 3 teammates could all state that they took the traning on residual risks based on the work standard. (Teammate Engagement: Operator: No.11) | L30: A sample of 3 teammates could all describe and explain the greatest potential H&S risks in their work, and what controls they use or are in place to mitigate these risks. (Teammate Engagement: Operator: No.13) | N30: In a sample of 3 teammates, at least one have participated RA process, and he/she could explain a full and accurate Risk Assessment. (Teammate Engagement: Operator: No.14) | P30: H&S risks/measures of other departments have been shared at the safety meeting in your department. (Teammate Engagement: Operator: No.17) | S30: Safety | T30: =I30 -> 0 | U30: =K30 -> 0 | V30: =M30 -> 0 | W30: =O30 -> 0 | X30: =Q30 -> 0 | Y30: =IF(T30="No",1,IF(U30="No",1,IF(V30="No",2,IF(W30="No",3,IF(X30="No",4,5))))) -> 5 | Z30: =IF(Y30<2,"C",IF(Y30<3,"B-",IF(Y30<4,"B",IF(Y30<5,"B+",IF(Y30=5,"A",""))))) -> A | AA30: Risk
